Workbook
Name _Hlk3298152: Instructions!$B$32
Name CFO: [1]Variables!$E$10
Name CFO: [1]Variables!$E$10
Name Client_Ticker: [1]Variables!$B$5
Name Client_Ticker: [1]Variables!$B$5
Name Component: 'Raw Data'!$B$31:$AY$31
Name Currency_CAD: [1]Variables!$B$3
Name Currency_CAD: [1]Variables!$B$3
Name FX_2011: [1]Variables!$H$4
Name FX_2011: [1]Variables!$H$4
Name FX_2012: [1]Variables!$H$5
Name FX_2012: [1]Variables!$H$5
Name FX_2013: [1]Variables!$H$6
Name FX_2013: [1]Variables!$H$6
Name IQ_CH: 110000
Name IQ_CQ: 5000
Name IQ_CY: 10000
Name IQ_DAILY: 500000
Name IQ_FH: 100000
Name IQ_FQ: 500
Name IQ_FY: 1000
Name IQ_LTM: 2000
Name IQ_MONTH: 15000
Name IQ_NTM: 6000
Name IQ_WEEK: 50000
Name IQ_YTD: 3000
Name Look_Up: 'Raw Data'!$B$31:$B$1048576
Name Look_Up2: 'Raw Data'!$A$31:$A$1048576
Name Peer_1_Ticker: [1]Variables!$B$7
Name Peer_1_Ticker: [1]Variables!$B$7
Name Peer_10_Ticker: [1]Variables!$B$16
Name Peer_10_Ticker: [1]Variables!$B$16
Name Peer_12_Ticker: [1]Variables!$B$18
Name Peer_12_Ticker: [1]Variables!$B$18
Name Peer_13_Ticker: [1]Variables!$B$19
Name Peer_13_Ticker: [1]Variables!$B$19
Name Peer_14_Ticker: [1]Variables!$B$20
Name Peer_14_Ticker: [1]Variables!$B$20
Name Peer_2_Ticker: [1]Variables!$B$8
Name Peer_2_Ticker: [1]Variables!$B$8
Name Peer_3_Ticker: [1]Variables!$B$9
Name Peer_3_Ticker: [1]Variables!$B$9
Name Peer_4_Ticker: [1]Variables!$B$10
Name Peer_4_Ticker: [1]Variables!$B$10
Name Peer_5_Ticker: [1]Variables!$B$11
Name Peer_5_Ticker: [1]Variables!$B$11
Name Peer_6_Ticker: [1]Variables!$B$12
Name Peer_6_Ticker: [1]Variables!$B$12
Name Peer_7_Ticker: [1]Variables!$B$13
Name Peer_7_Ticker: [1]Variables!$B$13
Name Peer_8_Ticker: [1]Variables!$B$14
Name Peer_8_Ticker: [1]Variables!$B$14
Name Peer_9_Ticker: [1]Variables!$B$15
Name Peer_9_Ticker: [1]Variables!$B$15
Name raw: '[4]Raw Data'!$A$1:$AJ$289
Name raw: '[4]Raw Data'!$A$1:$AJ$289
Name Raw_Data: '[1]Raw Data'!$1:$1048576
Name Raw_Data: '[1]Raw Data'!$1:$1048576
Name Raw_Data: 'Raw Data'!$B$31:$AY$1048576

Sheet Instructions
A1: Executive Compensation Benchmarking Methodology
A3: Effective Date | B3: 44992 | D3: Remember: | E3: • NEO order
A4: Last Revised | B4: 44992 | E4: • Currency
E5: • Incumbents serving for partial years
E6: • Date of fiscal year end
B9: Purpose
B10: Establish guidelines for executive compensation benchmarking in order to maintain consistency across client projects and teams, improve ease of training, and increase the efficiency of the benchmarking exercise
B12: Policy
B13: Roles
B14: · Record each person’s entire name and role as disclosed in the proxy
B15: o Ignore “director” roles (i.e. assume that the CEO is on the Board of directors)
B16: · Capture Executive Chairman role if it is one of the top 5 NEOs, but do not use as a comparison to any of the NEOs, unless indicated by client team
B17: o Footnote and confirm with client team
B19: Base Salary
B20: · Record the base salary in the Summary Compensation Table
B21: · If the incumbent has partial years of service, annualize the base salary
B22: · If the upcoming year’s salary is disclosed, record it in column O; it will be used in lieu of data aging
... B132: · Assume that the peer reviewer has made all of the necessary changes to the raw data sheet

Sheet Import 2023 Data
B3: x | C3: Lookup | D3: Role match | E3: Company | F3: Title | G3: Incumbent | H3: Actual TDC | I3: Target TDC
C4: tsx:hbm_2023_CEO | D4: CEO | E4: Hudbay Minerals Inc. | F4: President & CEO | G4: Peter Kukielski | H4: - | I4: 4779.9705
C5: tsx:hbm_2023_CFO | D5: CFO | E5: Hudbay Minerals Inc. | F5: CFO | G5: Eugene Lei | H5: - | I5: 1930.656
C6: tsx:hbm_2023_COO | D6: COO | E6: Hudbay Minerals Inc. | F6: COO | G6: Andre Lauzon | H6: - | I6: 2232
C7: tsx:hbm_2023_Legal | D7: Legal | E7: Hudbay Minerals Inc. | F7: SVP, Legal and Ogranizational Effectiveness | G7: Patrick Donnelly | H7: - | I7: 1582.906
C8: tsx:hbm_2023_NEO2 | D8: NEO2 | E8: Hudbay Minerals Inc. | F8: SVP, Legal and Ogranizational Effectiveness | G8: Patrick Donnelly | H8: - | I8: 1582.906
C9: tsx:hbm_2023_NEO4 | D9: Tech | E9: Hudbay Minerals Inc. | F9: SVP, Exploration & Technical Services | G9: Olivier Tavchandjilan | H9: - | I9: 1101.1
C10: tsx:hbm_2023_NEO3 | D10: NEO3 | E10: Hudbay Minerals Inc. | F10: SVP, South America and USA | G10: Javier Del Rio | H10: - | I10: 1509
C11: tsx:hbm_2023_NEO4 | D11: NEO4 | E11: Hudbay Minerals Inc. | F11: SVP, Exploration & Technical Services | G11: Olivier Tavchandjilan | H11: - | I11: 1101.1
C12: TSX:K_2023_CEO | D12: CEO | E12: Kinross Gold Corporation | F12: President and CEO | G12: J. Paul Rollinson | H12: 9041.3336 | I12: 8608.1222
C13: TSX:PAAS_2023_CEO | D13: CEO | E13: Pan American Silver Corp. | F13: President and CEO | G13: Michael Steinmann | H13: 7497.2 | I13: 7395
D14: CEO
C15: - | D15: CEO | E15: - | F15: - | G15: - | H15: - | I15: -
C16: TSX:AGI_2023_CEO | D16: CEO | E16: Alamos Gold Inc. | F16: President and CEO | G16: John McCluskey | H16: 5354.3256 | I16: 5099.3583
C17: TSX:BTO_2023_CEO | D17: CEO | E17: B2Gold Corp. | F17: Director, President and CEO | G17: Clive Johnson | H17: 5600 | I17: 7275
C18: TSX:CS_2023_CEO | D18: CEO | E18: Capstone Copper Corp. | F18: CEO and Director | G18: John MacKenzie | H18: 4059.874 | I18: 4186
C19: NYSE:HL_2023_CEO | D19: CEO | E19: Hecla Mining Company | F19: CEO | G19: Phillips S. Baker, Jr. | H19: 4635.6105 | I19: 5486.7939
C20: TSX:SSRM_2023_CEO | D20: CEO | E20: SSR Mining Inc. | F20: Executive Chairman | G20: Rod Antal | H20: 7097.5089 | I20: 7471.3908
C21: TSX:ELD_2023_CEO | D21: CEO | E21: Eldorado Gold Corporation | F21: President and CEO | G21: George Burns | H21: 4870.654 | I21: 4614.48
C22: TSX:IMG_2023_CEO | D22: CEO | E22: IAMGOLD Corporation | F22: President and CEO | G22: Renaud Adams | H22: 3647.4525 | I22: 4156.25
C23: TSX:OGC _2023_CEO | D23: CEO | E23: OceanaGold Corporation | F23: President and CEO | G23: Gerard Bond | H23: 4467.6643 | I23: 4310.2275
C24: TSX:NGD_2023_CEO | D24: CEO | E24: New Gold Inc. | F24: President and CEO | G24: Patrick Godin | H24: 3605.0004 | I24: 3325
C25: TSX:CG_2023_CEO | D25: CEO | E25: Centerra Gold Inc. | F25: President and CEO | G25: Paul Tomory | H25: 2868.8441 | I25: 3487.5
C26: TSX:ERO_2023_CEO | D26: CEO | E26: Ero Copper Corp. | F26: CEO and Director | G26: David Strang | H26: 4183.8007 | I26: 4017.2353
C27: TSX:K_2023_CFO | D27: CFO | E27: Kinross Gold Corporation | F27: EVP and CFO | G27: Andrea S. Freeborough | H27: 2504.0634 | I27: 2405.7995
... C46: TSX:CS_2023_COO | D46: COO | E46: Capstone Copper Corp. | F46: President and COO | G46: Cashel Meagher | H46: 2267.46 | I46: 2340
D47: COO
C48: - | D48: COO | E48: - | F48: - | G48: - | H48: - | I48: -
C49: TSX:SSRM_2023_COO | D49: COO | E49: SSR Mining Inc. | F49: EVP Operations and Sustainability | G49: Bill MacNevin | H49: 2223.328 | I49: 2302.6526
C50: TSX:ELD_2023_COO | D50: COO | E50: Eldorado Gold Corporation | F50: Former EVP and COO | G50: Joseph Dick | H50: 2072.381 | I50: 2005.41
C51: TSX:IMG_2023_COO | D51: COO | E51: IAMGOLD Corporation | F51: COO | G51: Bruno Lemelin | H51: 1828.591 | I51: 1820
C52: TSX:OGC _2023_COO | D52: COO | E52: OceanaGold Corporation | F52: EVP and COO, Asia-Pacific | G52: Peter Sharpe | H52: 2167.4193 | I52: 2014.7115
C53: TSX:NGD_2023_COO | D53: COO | E53: New Gold Inc. | F53: EVP and COO | G53: Yohann Bouchard | H53: 2061.8701 | I53: 2156.25
C54: TSX:CG_2023_COO | D54: COO | E54: Centerra Gold Inc. | F54: EVP and COO | G54: Paul Chawrun | H54: 1882.428 | I54: 1854
C55: TSX:ERO_2023_COO | D55: COO | E55: Ero Copper Corp. | F55: President & COO | G55: Makko DeFilippo | H55: 2133.2462 | I55: 2133.2462
C56: TSX:PAAS_2023_Legal | D56: Legal | E56: Pan American Silver Corp. | F56: General Counsel | G56: Christopher Lemon | H56: 2497.875 | I56: 2383.1
C57: TSX:LUN_2023_Legal | D57: Legal | E57: Lundin Mining Corporation | F57: General Counsel | G57: Peter Brady | H57: 1940.0917 | I57: 1851.4828
C58: TSX:AGI_2023_Legal | D58: Legal | E58: Alamos Gold Inc. | F58: SVP, General Counsel | G58: Nils F. Engelstad | H58: 1262.2693 | I58: 1216.8289
C59: TSX:BTO_2023_Legal | D59: Legal | E59: B2Gold Corp. | F59: SVP Legal and Coporate Communications | G59: Randall Chatwin | H59: 2295 | I59: 2677.583
C60: TSX:CS_2023_Legal | D60: Legal | E60: Capstone Copper Corp. | F60: SVP, Risk, ESG, General Counsel and Corporate Secretary | G60: Wendy King | H60: 1365.885 | I60: 1411.15
...

Sheet Pension Analysis
C1: COO | D1: F38 | E1: X38 | F1: X29 | H1: Y38 | I1: Y29
C2: Legal | D2: F27 | E2: X27 | F2: X18 | H2: Y27 | I2: Y18
D3: F39 | E3: X39 | F3: X30 | H3: Y39 | I3: Y30
C4: Role | D4: Incumbent | E4: Pension | F4: Peer Median | G4: Variance to Median | H4: Other Compensation | I4: Peer Median | J4: Variance to Median
C5: CEO | D5: {=INDIRECT("'"&$C5&"'!"&D$3)} -> Peter Kukielski | E5: {=INDIRECT("'"&$C5&"'!"&E$3)} -> 122.042 | F5: {=INDIRECT("'"&$C5&"'!"&F$3)} -> 263.96897 | G5: =E5/F5-1 -> -0.53766536 | H5: {=INDIRECT("'"&$C5&"'!"&H$3)} -> 255.034 | I5: {=INDIRECT("'"&$C5&"'!"&I$3)} -> 54.95 | J5: =H5/I5-1 -> 3.6412011
C6: CFO | D6: {=INDIRECT("'"&$C6&"'!"&D$3)} -> Eugene Lei | E6: {=INDIRECT("'"&$C6&"'!"&E$3)} -> 132.222 | F6: {=INDIRECT("'"&$C6&"'!"&F$3)} -> 93.574 | G6: =E6/F6-1 -> 0.41302071 | H6: {=INDIRECT("'"&$C6&"'!"&H$3)} -> 103.501 | I6: {=INDIRECT("'"&$C6&"'!"&I$3)} -> 32.15652 | J6: =H6/I6-1 -> 2.218663
C7: COO | D7: {=INDIRECT("'"&$C7&"'!"&D$1)} -> Andre Lauzon | E7: {=INDIRECT("'"&$C7&"'!"&E$1)} -> 74.4 | F7: {=INDIRECT("'"&$C7&"'!"&F$1)} -> 114.576 | G7: =E7/F7-1 -> -0.35064935 | H7: {=INDIRECT("'"&$C7&"'!"&H$1)} -> 85.127 | I7: {=INDIRECT("'"&$C7&"'!"&I$1)} -> 39.064917 | J7: =H7/I7-1 -> 1.1791164
C8: Legal | D8: {=INDIRECT("'"&$C8&"'!"&D$2)} -> Patrick Donnelly | E8: {=INDIRECT("'"&$C8&"'!"&E$2)} -> 122.673 | F8: {=INDIRECT("'"&$C8&"'!"&F$2)} -> 86.895 | G8: =E8/F8-1 -> 0.4117383 | H8: {=INDIRECT("'"&$C8&"'!"&H$2)} -> 84.863 | I8: {=INDIRECT("'"&$C8&"'!"&I$2)} -> 54.7155 | J8: =H8/I8-1 -> 0.55098647
C9: NEO4 | D9: {=INDIRECT("'"&$C9&"'!"&D$3)} -> Patrick Donnelly | E9: {=INDIRECT("'"&$C9&"'!"&E$3)} -> 122.673 | F9: {=INDIRECT("'"&$C9&"'!"&F$3)} -> 87.84 | G9: =E9/F9-1 -> 0.39655055 | H9: {=INDIRECT("'"&$C9&"'!"&H$3)} -> 84.863 | I9: {=INDIRECT("'"&$C9&"'!"&I$3)} -> 29.806678 | J9: =H9/I9-1 -> 1.8471136
C10: NEO5 | D10: {=INDIRECT("'"&$C10&"'!"&D$3)} -> Javier Del Rio | E10: {=INDIRECT("'"&$C10&"'!"&E$3)} -> 18.435637 | F10: {=INDIRECT("'"&$C10&"'!"&F$3)} -> 85.1645 | G10: =E10/F10-1 -> -0.78352908 | H10: {=INDIRECT("'"&$C10&"'!"&H$3)} -> 101.602 | I10: {=INDIRECT("'"&$C10&"'!"&I$3)} -> 38.710768 | J10: =H10/I10-1 -> 1.6246444

Sheet Target Comp
B6: Executive | C6: Role | D6: Base Salary | E6: Target STIP (%) | F6: Target STIP ($) | G6: Target Total ($) | H6: Target LTIP (%) | I6: Target LTIP ($) | J6: Target TDC ($) | K6: 2024 Target TDC | M6: 2024 Target | N6: Increase YoY
B7: Peter Kukielski | C7: President & CEO | D7: ='Raw Data'!P32/1000 -> 1047.525 | E7: ='Raw Data'!W32 -> 1.2 | F7: =E7*D7 -> 1257.03 | G7: =SUM(F7,D7) -> 2304.555 | H7: ='Raw Data'!AI32 -> 2.65 | I7: =H7*D7 -> 2775.9413 | J7: =I7+G7 -> 5080.4963 | K7: =TEXT(M7,"$0,000")&TEXT(N7," (+0%)") -> $4,780 (+6%) | M7: 4780 | N7: =J7/M7-1 -> 0.062865324
B8: Eugene Lei | C8: CFO | D8: ='Raw Data'!P38/1000 -> 573.681 | E8: ='Raw Data'!W38 -> 0.9 | F8: =E8*D8 -> 516.3129 | G8: =SUM(F8,D8) -> 1089.9939 | H8: ='Raw Data'!AI38 -> 1.7 | I8: =H8*D8 -> 975.2577 | J8: =I8+G8 -> 2065.2516 | K8: =TEXT(M8,"$0,000")&TEXT(N8," (+0%)") -> $1,931 (+7%) | M8: 1931 | N8: =J8/M8-1 -> 0.069524392
B9: Andre Lauzon | C9: COO | D9: ='Raw Data'!P35/1000 -> 651 | E9: ='Raw Data'!W35 -> 0.9 | F9: =E9*D9 -> 585.9 | G9: =SUM(F9,D9) -> 1236.9 | H9: ='Raw Data'!AI35 -> 1.7 | I9: =H9*D9 -> 1106.7 | J9: =I9+G9 -> 2343.6 | K9: =TEXT(M9,"$0,000")&TEXT(N9," (+0%)") -> $2,232 (+5%) | M9: 2232 | N9: =J9/M9-1 -> 0.05
B10: Patrick Donnelly | C10: SVP, Legal & Organizational Effectiveness | D10: ='Raw Data'!P41/1000 -> 501.659 | E10: ='Raw Data'!W41 -> 0.75 | F10: =E10*D10 -> 376.24425 | G10: =SUM(F10,D10) -> 877.90325 | H10: ='Raw Data'!AI41 -> 1.5 | I10: =H10*D10 -> 752.4885 | J10: =I10+G10 -> 1630.3917 | K10: =TEXT(M10,"$0,000")&TEXT(N10," (+0%)") -> $1,583 (+3%) | M10: 1583 | N10: =J10/M10-1 -> 0.029937934
B11: Javier Del Rio1 | C11: SVP, US | D11: ='Raw Data'!P44/1000 -> 606.75786 | E11: ='Raw Data'!W44 -> 0.6 | F11: =E11*D11 -> 364.05472 | G11: =SUM(F11,D11) -> 970.81258 | H11: ='Raw Data'!AI44 -> 1.2 | I11: =H11*D11 -> 728.10943 | J11: =I11+G11 -> 1698.922 | K11: =TEXT(M11,"$0,000")&TEXT(N11," (+0%)") -> $1,532 (+11%) | M11: 1532 | N11: =J11/M11-1 -> 0.10895693
B12: Olivier Tavchandjian | C12: SVP, Exploration and Technical Services | D12: ='Raw Data'!P47/1000 -> 465.85 | E12: ='Raw Data'!W47 -> 0.6 | F12: =E12*D12 -> 279.51 | G12: =SUM(F12,D12) -> 745.36 | H12: ='Raw Data'!AI47 -> 1.2 | I12: =H12*D12 -> 559.02 | J12: =I12+G12 -> 1304.38 | K12: =TEXT(M12,"$0,000")&TEXT(N12," (+0%)") -> $1,101 (+18%) | M12: 1101 | N12: =J12/M12-1 -> 0.18472298
B13: Rob Carter | C13: SVP, Canada | D13: ='Raw Data'!P50/1000 -> 453.5 | E13: ='Raw Data'!W50 -> 0.6 | F13: =E13*D13 -> 272.1 | G13: =SUM(F13,D13) -> 725.6 | H13: ='Raw Data'!AI50 -> 1.2 | I13: =H13*D13 -> 544.2 | J13: =I13+G13 -> 1269.8 | K13: =TEXT(M13,"$000")&TEXT(N13," (+0%)") -> $954 (+33%) | M13: 954 | N13: =J13/M13-1 -> 0.33102725

Sheet Raw Data
C2: INPUTS
AN3: Check with client team 1) whether this benchmarking is necessary and 2) how to treat pension & other in the output tables (i.e., actual, 3-year average)
C4: Peer Ticker(s) | F4: Date | G4: 45852
C5: 1 | D5: TSX:K | F5: Currency | G5: CAD
C6: 2 | D6: TSX:LUN | F6: Client Ticker | G6: TSX:HBM
C7: 3 | D7: TSX:AGI
C8: 4 | D8: TSX:PAAS | F8: CAD/USD
C9: 5 | D9: TSX:CS | F9: 2024 | G9: =_xll.ciqfunctions.udf.CIQAVG("$CADUSD", "IQ_LASTSALEPRICE", "1/1/"&$F9, "31/12/"&$F9) -> 1.37017
C10: 6 | D10: TSX:IMG | F10: =F9-1 -> 2023 | G10: =_xll.ciqfunctions.udf.CIQAVG("$CADUSD", "IQ_LASTSALEPRICE", "1/1/"&$F10, "31/12/"&$F10) -> 1.34954
C11: 7 | D11: TSX:BTO | F11: =F10-1 -> 2022 | G11: =_xll.ciqfunctions.udf.CIQAVG("$CADUSD", "IQ_LASTSALEPRICE", "1/1/"&$F11, "31/12/"&$F11) -> 1.30175
C12: 8 | D12: NYSE:HL
C13: 9 | D13: TSX:NGD | F13: Data Aging: | G13: 0.03
C14: 10 | D14: TSX:ELD
C15: 11 | D15: TSX:SSRM
C16: 12 | D16: TSX:OGC
C17: 13 | D17: TSX:ERO
C18: 14 | D18: TSX:CG
C19: 15 | E19: =COUNTA(D5:D18) -> 14
C20: 16
C21: 17
C22: 18
C23: 19
C24: 20
C25: 21
C26: 22
C27: 23
C28: 24
O30: Base Salary | S30: STIP | Y30: Total Cash Compensation | AA30: Long-Term Incentives | AL30: Total Direct Compensation | AN30: Pension & Other | AU30: Total Compensation
A31: Look-Up2 | B31: Look-Up | C31: Ticker | D31: Company | E31: Year | F31: Incumbent Start Month | G31: End Month (Typically FYE) | H31: Months | I31: Currency of Disclosure | J31: FX Rate | K31: Role Match | L31: Position Match | M31: Position Title | N31: Incumbent | O31: Actual Paid | P31: Annualized / Converted | Q31: Latest (if disclosed) | R31: Latest (if disclosed) - Annualized / Converted | S31: Actual $ | T31: Annualized/ Converted | U31: Actual STI % | V31: 3 Year Average STIP % | W31: Target STI % | X31: Target STI $ | Y31: Actual TCC | Z31: Target TCC | AA31: RSUs | AB31: PSUs | AC31: Stock Options | AD31: DSUs | AE31: LT Cash | AF31: Total LTI $ | AG31: Total LTI % | AH31: 3 Year Average LTIP % | AI31: Target LTI % | AJ31: Target LTI $ | AK31: Total LTI (Converted) | AL31: Actual (base + actual bonus + actual LTIP) | AM31: Target (base + target bonus + Target LTIP) | AN31: Pension | AO31: DB or DC Pension? | AP31: Pension Converted | AQ31: Pension 3 Year Average | AR31: Other | AS31: Other Converted | AT31: Other 3 Year Average | AU31: Actual (Actual TDC + Pension + Other) | AV31: Target (Target TDC + Pension + Other) | AW31: Incumbent Specific Notes: | AX31: Data Recorder | AY31: Peer Reviewer
A32: =$C32&"_"&$E32&"_"&$K32 -> TSX:HBM_2024_ | B32: =$C32&"_"&$E32&"_"&$L32 -> TSX:HBM_2024_CEO | C32: =G6 -> TSX:HBM | D32: =_xll.ciqfunctions.udf.CIQ(C32,"IQ_Company_Name") -> Hudbay Minerals Inc. | E32: 2024 | F32: =E32&"-01-01" -> 2024-01-01 | G32: =E32&"-12-31" -> 2024-12-31 | H32: =_xlfn.DAYS(G32,F32)/_xlfn.DAYS(E32&"-12-31",E32&"-01-01")*12 -> 12 | I32: =$G$5 -> CAD | J32: =IF($I32="CAD",1,IF($I32="USD",VLOOKUP($E32,$F$9:$G$11,2,FALSE),"N/A")) -> 1 | L32: CEO | M32: President & CEO | N32: Peter Kukielski | O32: 1047525 | P32: =IFERROR(O32*(12/$H32)*$J32,"-") -> 1047525 | R32: =IFERROR(IF((Q32*$L32)=0,"-",(Q32*$L32)),"-") -> - | S32: 1632919 | T32: =IFERROR(S32*(12/$H32)*$J32,"-") -> 1632919 | U32: =IFERROR($T32/$P32,"-") -> 1.5588353 | V32: =IFERROR(AVERAGE(U32:U34),"N/A") -> 1.5588353 | W32: 1.2 | X32: =IFERROR(IF(ISNUMBER($W32)=TRUE, $W32*$P32,$V32*$P32),"-") -> 1257030 | Y32: =IFERROR(IF(SUM(P32,T32)=0,"-",SUM(P32,T32)),"-") -> 2680444 | Z32: =IFERROR(IF(SUM(P32,X32)=0,"-",SUM(P32,X32)),"-") -> 2304555 | AB32: 1906903 | AC32: 635634 | AD32: - | AE32: - | AF32: =IFERROR(IF(SUM(AA32:AE32)=0,IF(COUNTIF($AA32:$AE32,"=0")>0,"$0","-"),SUM(AA32:AE32)),"-") -> 2542537 | AG32: =IFERROR($AK32/$P32,"-") -> 2.427185 | AH32: =IFERROR(AVERAGE(AG32:AG34),"N/A") -> 2.427185 | AI32: 2.65 | AJ32: =IFERROR(IF(ISNUMBER($AI32)=TRUE, $AI32*$P32, $AH32*$P32), "-") -> 2775941.2 | AK32: =IFERROR($AF32*$J32,"-") -> 2542537 | AL32: =IFERROR(IF(SUM(Y32,AK32)=0,"-",SUM(Y32,AK32)),"-") -> 5222981 | AM32: =IFERROR(IF(SUM($Z32,$AJ32)=0,"-",SUM($Z32,$AJ32)),"-") -> 5080496.2 | AN32: 122042 | AO32: DC | AP32: =IFERROR(AN32*(12/$H32)*$J32,"-") -> 122042 | AQ32: =IFERROR(AVERAGE(AP32:AP34),"N/A") -> 118074.67 | AR32: 255034 | AS32: =IFERROR(AR32*(12/$H32)*$J32,"-") -> 255034 | AT32: =IFERROR(AVERAGE(AS32:AS34),"N/A") -> 245312.67 | AU32: =IFERROR(IF(SUM(AL32,AP32,AS32)=0,"-",SUM(AL32,AP32,AS32)),"-") -> 5600057 | AV32: =IFERROR(IF(SUM(AM32,AP32,AS32)=0,"-",SUM(AM32,AP32,AS32)),"-") -> 5457572.2 | AW32: - | AX32: AH
A33: =$C33&"_"&$E33&"_"&$K33 -> TSX:HBM_2023_ | B33: =$C33&"_"&$E33&"_"&$L33 -> TSX:HBM_2023_CEO | C33: =C32 -> TSX:HBM | D33: =_xll.ciqfunctions.udf.CIQ(C33,"IQ_Company_Name") -> Hudbay Minerals Inc. | E33: 2023 | F33: =E33&"-01-01" -> 2023-01-01 | G33: =E33&"-12-31" -> 2023-12-31 | H33: =_xlfn.DAYS(G33,F33)/_xlfn.DAYS(E33&"-12-31",E33&"-01-01")*12 -> 12 | I33: =I32 -> CAD | J33: =IF($I33="CAD",1,IF($I33="USD",VLOOKUP($E33,$F$9:$G$11,2,FALSE),"N/A")) -> 1 | L33: =L32 -> CEO | M33: =M32 -> President & CEO | N33: =N32 -> Peter Kukielski | P33: =IFERROR(O33*(12/$H33)*$J33,"-") -> 0 | R33: =IFERROR(IF((Q33*$L33)=0,"-",(Q33*$L33)),"-") -> - | T33: =IFERROR(S33*(12/$H33)*$J33,"-") -> 0 | U33: =IFERROR($T33/$P33,"-") -> - | X33: =IFERROR(IF(ISNUMBER($W33)=TRUE, $W33*$P33,$V33*$P33),"-") -> 0 | Y33: =IFERROR(IF(SUM(P33,T33)=0,"-",SUM(P33,T33)),"-") -> - | Z33: =IFERROR(IF(SUM(P33,X33)=0,"-",SUM(P33,X33)),"-") -> - | AD33: - | AE33: - | AF33: =IFERROR(IF(SUM(AA33:AE33)=0,IF(COUNTIF($AA33:$AE33,"=0")>0,"$0","-"),SUM(AA33:AE33)),"-") -> - | AG33: =IFERROR($AK33/$P33,"-") -> - | AJ33: =IFERROR(IF(ISNUMBER($AI33)=TRUE, $AI33*$P33, $AH33*$P33), "-") -> 0 | AK33: =IFERROR($AF33*$J33,"-") -> - | AL33: =IFERROR(IF(SUM(Y33,AK33)=0,"-",SUM(Y33,AK33)),"-") -> - | AM33: =IFERROR(IF(SUM($Z33,$AJ33)=0,"-",SUM($Z33,$AJ33)),"-") -> - | AN33: 119348 | AO33: DC | AP33: =IFERROR(AN33*(12/$H33)*$J33,"-") -> 119348 | AR33: 275237 | AS33: =IFERROR(AR33*(12/$H33)*$J33,"-") -> 275237 | AU33: =IFERROR(IF(SUM(AL33,AP33,AS33)=0,"-",SUM(AL33,AP33,AS33)),"-") -> 394585 | AV33: =IFERROR(IF(SUM(AM33,AP33,AS33)=0,"-",SUM(AM33,AP33,AS33)),"-") -> 394585 | AW33: -
A34: =$C34&"_"&$E34&"_"&$K34 -> TSX:HBM_2022_ | B34: =$C34&"_"&$E34&"_"&$L34 -> TSX:HBM_2022_CEO | C34: =C33 -> TSX:HBM | D34: =_xll.ciqfunctions.udf.CIQ(C34,"IQ_Company_Name") -> Hudbay Minerals Inc. | E34: 2022 | F34: =E34&"-01-01" -> 2022-01-01 | G34: =E34&"-12-31" -> 2022-12-31 | H34: =_xlfn.DAYS(G34,F34)/_xlfn.DAYS(E34&"-12-31",E34&"-01-01")*12 -> 12 | I34: =I33 -> CAD | J34: =IF($I34="CAD",1,IF($I34="USD",VLOOKUP($E34,$F$9:$G$11,2,FALSE),"N/A")) -> 1 | L34: =L33 -> CEO | M34: =M33 -> President & CEO | N34: =N33 -> Peter Kukielski | P34: =IFERROR(O34*(12/$H34)*$J34,"-") -> 0 | R34: =IFERROR(IF((Q34*$L34)=0,"-",(Q34*$L34)),"-") -> - | T34: =IFERROR(S34*(12/$H34)*$J34,"-") -> 0 | U34: =IFERROR($T34/$P34,"-") -> - | X34: =IFERROR(IF(ISNUMBER($W34)=TRUE, $W34*$P34,$V34*$P34),"-") -> 0 | Y34: =IFERROR(IF(SUM(P34,T34)=0,"-",SUM(P34,T34)),"-") -> - | Z34: =IFERROR(IF(SUM(P34,X34)=0,"-",SUM(P34,X34)),"-") -> - | AD34: - | AE34: - | AF34: =IFERROR(IF(SUM(AA34:AE34)=0,IF(COUNTIF($AA34:$AE34,"=0")>0,"$0","-"),SUM(AA34:AE34)),"-") -> - | AG34: =IFERROR($AK34/$P34,"-") -> - | AJ34: =IFERROR(IF(ISNUMBER($AI34)=TRUE, $AI34*$P34, $AH34*$P34), "-") -> 0 | AK34: =IFERROR($AF34*$J34,"-") -> - | AL34: =IFERROR(IF(SUM(Y34,AK34)=0,"-",SUM(Y34,AK34)),"-") -> - | AM34: =IFERROR(IF(SUM($Z34,$AJ34)=0,"-",SUM($Z34,$AJ34)),"-") -> - | AN34: 112834 | AO34: DC | AP34: =IFERROR(AN34*(12/$H34)*$J34,"-") -> 112834 | AR34: 205667 | AS34: =IFERROR(AR34*(12/$H34)*$J34,"-") -> 205667 | AU34: =IFERROR(IF(SUM(AL34,AP34,AS34)=0,"-",SUM(AL34,AP34,AS34)),"-") -> 318501 | AV34: =IFERROR(IF(SUM(AM34,AP34,AS34)=0,"-",SUM(AM34,AP34,AS34)),"-") -> 318501 | AW34: -
A35: =$C35&"_"&$E35&"_"&$K35 -> TSX:HBM_2024_COO | B35: =$C35&"_"&$E35&"_"&$L35 -> TSX:HBM_2024_NEO1 | C35: =C34 -> TSX:HBM | D35: =_xll.ciqfunctions.udf.CIQ(C35,"IQ_Company_Name") -> Hudbay Minerals Inc. | E35: =E32 -> 2024 | F35: =E35&"-01-01" -> 2024-01-01 | G35: =E35&"-12-31" -> 2024-12-31 | H35: =_xlfn.DAYS(G35,F35)/_xlfn.DAYS(E35&"-12-31",E35&"-01-01")*12 -> 12 | I35: =I34 -> CAD | J35: =IF($I35="CAD",1,IF($I35="USD",VLOOKUP($E35,$F$9:$G$11,2,FALSE),"N/A")) -> 1 | K35: COO | L35: NEO1 | M35: COO | N35: Andre Lauzon | O35: 651000 | P35: =IFERROR(O35*(12/$H35)*$J35,"-") -> 651000 | R35: =IFERROR(IF((Q35*$L35)=0,"-",(Q35*$L35)),"-") -> - | S35: 740466 | T35: =IFERROR(S35*(12/$H35)*$J35,"-") -> 740466 | U35: =IFERROR($T35/$P35,"-") -> 1.1374286 | V35: =IFERROR(AVERAGE(U35:U37),"N/A") -> 1.1374286 | W35: 0.9 | X35: =IFERROR(IF(ISNUMBER($W35)=TRUE, $W35*$P35,$V35*$P35),"-") -> 585900 | Y35: =IFERROR(IF(SUM(P35,T35)=0,"-",SUM(P35,T35)),"-") -> 1391466 | Z35: =IFERROR(IF(SUM(P35,X35)=0,"-",SUM(P35,X35)),"-") -> 1236900 | AB35: 790500 | AC35: 263500 | AD35: - | AE35: - | AF35: =IFERROR(IF(SUM(AA35:AE35)=0,IF(COUNTIF($AA35:$AE35,"=0")>0,"$0","-"),SUM(AA35:AE35)),"-") -> 1054000 | AG35: =IFERROR($AK35/$P35,"-") -> 1.6190476 | AH35: =IFERROR(AVERAGE(AG35:AG37),"N/A") -> 1.6190476 | AI35: 1.7 | AJ35: =IFERROR(IF(ISNUMBER($AI35)=TRUE, $AI35*$P35, $AH35*$P35), "-") -> 1106700 | AK35: =IFERROR($AF35*$J35,"-") -> 1054000 | AL35: =IFERROR(IF(SUM(Y35,AK35)=0,"-",SUM(Y35,AK35)),"-") -> 2445466 | AM35: =IFERROR(IF(SUM($Z35,$AJ35)=0,"-",SUM($Z35,$AJ35)),"-") -> 2343600 | AN35: 74400 | AO35: DC | AP35: =IFERROR(AN35*(12/$H35)*$J35,"-") -> 74400 | AQ35: =IFERROR(AVERAGE(AP35:AP37),"N/A") -> 67856 | AR35: 85127 | AS35: =IFERROR(AR35*(12/$H35)*$J35,"-") -> 85127 | AT35: =IFERROR(AVERAGE(AS35:AS37),"N/A") -> 196002.67 | AU35: =IFERROR(IF(SUM(AL35,AP35,AS35)=0,"-",SUM(AL35,AP35,AS35)),"-") -> 2604993 | AV35: =IFERROR(IF(SUM(AM35,AP35,AS35)=0,"-",SUM(AM35,AP35,AS35)),"-") -> 2503127 | AW35: - | AX35: AH
A36: =$C36&"_"&$E36&"_"&$K36 -> TSX:HBM_2023_COO | B36: =$C36&"_"&$E36&"_"&$L36 -> TSX:HBM_2023_NEO1 | C36: =C35 -> TSX:HBM | D36: =_xll.ciqfunctions.udf.CIQ(C36,"IQ_Company_Name") -> Hudbay Minerals Inc. | E36: =E33 -> 2023 | F36: =E36&"-01-01" -> 2023-01-01 | G36: =E36&"-12-31" -> 2023-12-31 | H36: =_xlfn.DAYS(G36,F36)/_xlfn.DAYS(E36&"-12-31",E36&"-01-01")*12 -> 12 | I36: =I35 -> CAD | J36: =IF($I36="CAD",1,IF($I36="USD",VLOOKUP($E36,$F$9:$G$11,2,FALSE),"N/A")) -> 1 | K36: COO | L36: =L35 -> NEO1 | M36: =M35 -> COO | N36: =N35 -> Andre Lauzon | P36: =IFERROR(O36*(12/$H36)*$J36,"-") -> 0 | R36: =IFERROR(IF((Q36*$L36)=0,"-",(Q36*$L36)),"-") -> - | T36: =IFERROR(S36*(12/$H36)*$J36,"-") -> 0 | U36: =IFERROR($T36/$P36,"-") -> - | X36: =IFERROR(IF(ISNUMBER($W36)=TRUE, $W36*$P36,$V36*$P36),"-") -> 0 | Y36: =IFERROR(IF(SUM(P36,T36)=0,"-",SUM(P36,T36)),"-") -> - | Z36: =IFERROR(IF(SUM(P36,X36)=0,"-",SUM(P36,X36)),"-") -> - | AD36: - | AE36: - | AF36: =IFERROR(IF(SUM(AA36:AE36)=0,IF(COUNTIF($AA36:$AE36,"=0")>0,"$0","-"),SUM(AA36:AE36)),"-") -> - | AG36: =IFERROR($AK36/$P36,"-") -> - | AJ36: =IFERROR(IF(ISNUMBER($AI36)=TRUE, $AI36*$P36, $AH36*$P36), "-") -> 0 | AK36: =IFERROR($AF36*$J36,"-") -> - | AL36: =IFERROR(IF(SUM(Y36,AK36)=0,"-",SUM(Y36,AK36)),"-") -> - | AM36: =IFERROR(IF(SUM($Z36,$AJ36)=0,"-",SUM($Z36,$AJ36)),"-") -> - | AN36: 66768 | AO36: DC | AP36: =IFERROR(AN36*(12/$H36)*$J36,"-") -> 66768 | AR36: 179092 | AS36: =IFERROR(AR36*(12/$H36)*$J36,"-") -> 179092 | AU36: =IFERROR(IF(SUM(AL36,AP36,AS36)=0,"-",SUM(AL36,AP36,AS36)),"-") -> 245860 | AV36: =IFERROR(IF(SUM(AM36,AP36,AS36)=0,"-",SUM(AM36,AP36,AS36)),"-") -> 245860 | AW36: -
A37: =$C37&"_"&$E37&"_"&$K37 -> TSX:HBM_2022_COO | B37: =$C37&"_"&$E37&"_"&$L37 -> TSX:HBM_2022_NEO1 | C37: =C36 -> TSX:HBM | D37: =_xll.ciqfunctions.udf.CIQ(C37,"IQ_Company_Name") -> Hudbay Minerals Inc. | E37: =E34 -> 2022 | F37: =E37&"-01-01" -> 2022-01-01 | G37: =E37&"-12-31" -> 2022-12-31 | H37: =_xlfn.DAYS(G37,F37)/_xlfn.DAYS(E37&"-12-31",E37&"-01-01")*12 -> 12 | I37: =I36 -> CAD | J37: =IF($I37="CAD",1,IF($I37="USD",VLOOKUP($E37,$F$9:$G$11,2,FALSE),"N/A")) -> 1 | K37: COO | L37: =L36 -> NEO1 | M37: =M36 -> COO | N37: =N36 -> Andre Lauzon | P37: =IFERROR(O37*(12/$H37)*$J37,"-") -> 0 | R37: =IFERROR(IF((Q37*$L37)=0,"-",(Q37*$L37)),"-") -> - | T37: =IFERROR(S37*(12/$H37)*$J37,"-") -> 0 | U37: =IFERROR($T37/$P37,"-") -> - | X37: =IFERROR(IF(ISNUMBER($W37)=TRUE, $W37*$P37,$V37*$P37),"-") -> 0 | Y37: =IFERROR(IF(SUM(P37,T37)=0,"-",SUM(P37,T37)),"-") -> - | Z37: =IFERROR(IF(SUM(P37,X37)=0,"-",SUM(P37,X37)),"-") -> - | AD37: - | AE37: - | AF37: =IFERROR(IF(SUM(AA37:AE37)=0,IF(COUNTIF($AA37:$AE37,"=0")>0,"$0","-"),SUM(AA37:AE37)),"-") -> - | AG37: =IFERROR($AK37/$P37,"-") -> - | AJ37: =IFERROR(IF(ISNUMBER($AI37)=TRUE, $AI37*$P37, $AH37*$P37), "-") -> 0 | AK37: =IFERROR($AF37*$J37,"-") -> - | AL37: =IFERROR(IF(SUM(Y37,AK37)=0,"-",SUM(Y37,AK37)),"-") -> - | AM37: =IFERROR(IF(SUM($Z37,$AJ37)=0,"-",SUM($Z37,$AJ37)),"-") -> - | AN37: 62400 | AO37: DC | AP37: =IFERROR(AN37*(12/$H37)*$J37,"-") -> 62400 | AR37: 323789 | AS37: =IFERROR(AR37*(12/$H37)*$J37,"-") -> 323789 | AU37: =IFERROR(IF(SUM(AL37,AP37,AS37)=0,"-",SUM(AL37,AP37,AS37)),"-") -> 386189 | AV37: =IFERROR(IF(SUM(AM37,AP37,AS37)=0,"-",SUM(AM37,AP37,AS37)),"-") -> 386189 | AW37: -
A38: =$C38&"_"&$E38&"_"&$K38 -> TSX:HBM_2024_ | B38: =$C38&"_"&$E38&"_"&$L38 -> TSX:HBM_2024_CFO | C38: =C37 -> TSX:HBM | D38: =_xll.ciqfunctions.udf.CIQ(C38,"IQ_Company_Name") -> Hudbay Minerals Inc. | E38: =E35 -> 2024 | F38: =E38&"-01-01" -> 2024-01-01 | G38: =E38&"-12-31" -> 2024-12-31 | H38: =_xlfn.DAYS(G38,F38)/_xlfn.DAYS(E38&"-12-31",E38&"-01-01")*12 -> 12 | I38: =I37 -> CAD | J38: =IF($I38="CAD",1,IF($I38="USD",VLOOKUP($E38,$F$9:$G$11,2,FALSE),"N/A")) -> 1 | L38: CFO | M38: CFO | N38: Eugene Lei | O38: 573681 | P38: =IFERROR(O38*(12/$H38)*$J38,"-") -> 573681 | R38: =IFERROR(IF((Q38*$L38)=0,"-",(Q38*$L38)),"-") -> - | S38: 658795 | T38: =IFERROR(S38*(12/$H38)*$J38,"-") -> 658795 | U38: =IFERROR($T38/$P38,"-") -> 1.1483647 | V38: =IFERROR(AVERAGE(U38:U40),"N/A") -> 1.1483647 | W38: 0.9 | X38: =IFERROR(IF(ISNUMBER($W38)=TRUE, $W38*$P38,$V38*$P38),"-") -> 516312.9 | Y38: =IFERROR(IF(SUM(P38,T38)=0,"-",SUM(P38,T38)),"-") -> 1232476 | Z38: =IFERROR(IF(SUM(P38,X38)=0,"-",SUM(P38,X38)),"-") -> 1089993.9 | AB38: 661939 | AC38: 220646 | AD38: - | AE38: - | AF38: =IFERROR(IF(SUM(AA38:AE38)=0,IF(COUNTIF($AA38:$AE38,"=0")>0,"$0","-"),SUM(AA38:AE38)),"-") -> 882585 | AG38: =IFERROR($AK38/$P38,"-") -> 1.5384595 | AH38: =IFERROR(AVERAGE(AG38:AG40),"N/A") -> 1.5384595 | AI38: 1.7 | AJ38: =IFERROR(IF(ISNUMBER($AI38)=TRUE, $AI38*$P38, $AH38*$P38), "-") -> 975257.7 | AK38: =IFERROR($AF38*$J38,"-") -> 882585 | AL38: =IFERROR(IF(SUM(Y38,AK38)=0,"-",SUM(Y38,AK38)),"-") -> 2115061 | AM38: =IFERROR(IF(SUM($Z38,$AJ38)=0,"-",SUM($Z38,$AJ38)),"-") -> 2065251.6 | AN38: 132222 | AO38: DB & DC | AP38: =IFERROR(AN38*(12/$H38)*$J38,"-") -> 132222 | AQ38: =IFERROR(AVERAGE(AP38:AP40),"N/A") -> 157909.67 | AR38: 103501 | AS38: =IFERROR(AR38*(12/$H38)*$J38,"-") -> 103501 | AT38: =IFERROR(AVERAGE(AS38:AS40),"N/A") -> 119085.67 | AU38: =IFERROR(IF(SUM(AL38,AP38,AS38)=0,"-",SUM(AL38,AP38,AS38)),"-") -> 2350784 | AV38: =IFERROR(IF(SUM(AM38,AP38,AS38)=0,"-",SUM(AM38,AP38,AS38)),"-") -> 2300974.6 | AW38: - | AX38: AH
A39: =$C39&"_"&$E39&"_"&$K39 -> TSX:HBM_2023_ | B39: =$C39&"_"&$E39&"_"&$L39 -> TSX:HBM_2023_CFO | C39: =C38 -> TSX:HBM | D39: =_xll.ciqfunctions.udf.CIQ(C39,"IQ_Company_Name") -> Hudbay Minerals Inc. | E39: =E36 -> 2023 | F39: =E39&"-01-01" -> 2023-01-01 | G39: =E39&"-12-31" -> 2023-12-31 | H39: =_xlfn.DAYS(G39,F39)/_xlfn.DAYS(E39&"-12-31",E39&"-01-01")*12 -> 12 | I39: =I38 -> CAD | J39: =IF($I39="CAD",1,IF($I39="USD",VLOOKUP($E39,$F$9:$G$11,2,FALSE),"N/A")) -> 1 | L39: =L38 -> CFO | M39: =M38 -> CFO | N39: =N38 -> Eugene Lei | P39: =IFERROR(O39*(12/$H39)*$J39,"-") -> 0 | R39: =IFERROR(IF((Q39*$L39)=0,"-",(Q39*$L39)),"-") -> - | T39: =IFERROR(S39*(12/$H39)*$J39,"-") -> 0 | U39: =IFERROR($T39/$P39,"-") -> - | X39: =IFERROR(IF(ISNUMBER($W39)=TRUE, $W39*$P39,$V39*$P39),"-") -> 0 | Y39: =IFERROR(IF(SUM(P39,T39)=0,"-",SUM(P39,T39)),"-") -> - | Z39: =IFERROR(IF(SUM(P39,X39)=0,"-",SUM(P39,X39)),"-") -> - | AD39: - | AE39: - | AF39: =IFERROR(IF(SUM(AA39:AE39)=0,IF(COUNTIF($AA39:$AE39,"=0")>0,"$0","-"),SUM(AA39:AE39)),"-") -> - | AG39: =IFERROR($AK39/$P39,"-") -> - | AJ39: =IFERROR(IF(ISNUMBER($AI39)=TRUE, $AI39*$P39, $AH39*$P39), "-") -> 0 | AK39: =IFERROR($AF39*$J39,"-") -> - | AL39: =IFERROR(IF(SUM(Y39,AK39)=0,"-",SUM(Y39,AK39)),"-") -> - | AM39: =IFERROR(IF(SUM($Z39,$AJ39)=0,"-",SUM($Z39,$AJ39)),"-") -> - | AN39: 108961 | AO39: DB & DC | AP39: =IFERROR(AN39*(12/$H39)*$J39,"-") -> 108961 | AR39: 141406 | AS39: =IFERROR(AR39*(12/$H39)*$J39,"-") -> 141406 | AU39: =IFERROR(IF(SUM(AL39,AP39,AS39)=0,"-",SUM(AL39,AP39,AS39)),"-") -> 250367 | AV39: =IFERROR(IF(SUM(AM39,AP39,AS39)=0,"-",SUM(AM39,AP39,AS39)),"-") -> 250367 | AW39: -
A40: =$C40&"_"&$E40&"_"&$K40 -> TSX:HBM_2022_ | B40: =$C40&"_"&$E40&"_"&$L40 -> TSX:HBM_2022_CFO | C40: =C39 -> TSX:HBM | D40: =_xll.ciqfunctions.udf.CIQ(C40,"IQ_Company_Name") -> Hudbay Minerals Inc. | E40: =E37 -> 2022 | F40: =E40&"-01-01" -> 2022-01-01 | G40: =E40&"-12-31" -> 2022-12-31 | H40: =_xlfn.DAYS(G40,F40)/_xlfn.DAYS(E40&"-12-31",E40&"-01-01")*12 -> 12 | I40: =I39 -> CAD | J40: =IF($I40="CAD",1,IF($I40="USD",VLOOKUP($E40,$F$9:$G$11,2,FALSE),"N/A")) -> 1 | L40: =L39 -> CFO | M40: =M39 -> CFO | N40: =N39 -> Eugene Lei | P40: =IFERROR(O40*(12/$H40)*$J40,"-") -> 0 | R40: =IFERROR(IF((Q40*$L40)=0,"-",(Q40*$L40)),"-") -> - | T40: =IFERROR(S40*(12/$H40)*$J40,"-") -> 0 | U40: =IFERROR($T40/$P40,"-") -> - | X40: =IFERROR(IF(ISNUMBER($W40)=TRUE, $W40*$P40,$V40*$P40),"-") -> 0 | Y40: =IFERROR(IF(SUM(P40,T40)=0,"-",SUM(P40,T40)),"-") -> - | Z40: =IFERROR(IF(SUM(P40,X40)=0,"-",SUM(P40,X40)),"-") -> - | AD40: - | AE40: - | AF40: =IFERROR(IF(SUM(AA40:AE40)=0,IF(COUNTIF($AA40:$AE40,"=0")>0,"$0","-"),SUM(AA40:AE40)),"-") -> - | AG40: =IFERROR($AK40/$P40,"-") -> - | AJ40: =IFERROR(IF(ISNUMBER($AI40)=TRUE, $AI40*$P40, $AH40*$P40), "-") -> 0 | AK40: =IFERROR($AF40*$J40,"-") -> - | AL40: =IFERROR(IF(SUM(Y40,AK40)=0,"-",SUM(Y40,AK40)),"-") -> - | AM40: =IFERROR(IF(SUM($Z40,$AJ40)=0,"-",SUM($Z40,$AJ40)),"-") -> - | AN40: 232546 | AO40: DB & DC | AP40: =IFERROR(AN40*(12/$H40)*$J40,"-") -> 232546 | AR40: 112350 | AS40: =IFERROR(AR40*(12/$H40)*$J40,"-") -> 112350 | AU40: =IFERROR(IF(SUM(AL40,AP40,AS40)=0,"-",SUM(AL40,AP40,AS40)),"-") -> 344896 | AV40: =IFERROR(IF(SUM(AM40,AP40,AS40)=0,"-",SUM(AM40,AP40,AS40)),"-") -> 344896 | AW40: -
A41: =$C41&"_"&$E41&"_"&$K41 -> TSX:HBM_2024_Legal | B41: =$C41&"_"&$E41&"_"&$L41 -> TSX:HBM_2024_NEO2 | C41: =C40 -> TSX:HBM | D41: =_xll.ciqfunctions.udf.CIQ(C41,"IQ_Company_Name") -> Hudbay Minerals Inc. | E41: =E38 -> 2024 | F41: =E41&"-01-01" -> 2024-01-01 | G41: =E41&"-12-31" -> 2024-12-31 | H41: =_xlfn.DAYS(G41,F41)/_xlfn.DAYS(E41&"-12-31",E41&"-01-01")*12 -> 12 | I41: =I40 -> CAD | J41: =IF($I41="CAD",1,IF($I41="USD",VLOOKUP($E41,$F$9:$G$11,2,FALSE),"N/A")) -> 1 | K41: Legal | L41: NEO2 | M41: SVP, Legal and Organizational Effectiveness | N41: Patrick Donnelly | O41: 501659 | P41: =IFERROR(O41*(12/$H41)*$J41,"-") -> 501659 | R41: =IFERROR(IF((Q41*$L41)=0,"-",(Q41*$L41)),"-") -> - | S41: 479256 | T41: =IFERROR(S41*(12/$H41)*$J41,"-") -> 479256 | U41: =IFERROR($T41/$P41,"-") -> 0.95534217 | V41: =IFERROR(AVERAGE(U41:U43),"N/A") -> 0.95534217 | W41: 0.75 | X41: =IFERROR(IF(ISNUMBER($W41)=TRUE, $W41*$P41,$V41*$P41),"-") -> 376244.25 | Y41: =IFERROR(IF(SUM(P41,T41)=0,"-",SUM(P41,T41)),"-") -> 980915 | Z41: =IFERROR(IF(SUM(P41,X41)=0,"-",SUM(P41,X41)),"-") -> 877903.25 | AB41: 547929 | AC41: 182643 | AD41: - | AE41: - | AF41: =IFERROR(IF(SUM(AA41:AE41)=0,IF(COUNTIF($AA41:$AE41,"=0")>0,"$0","-"),SUM(AA41:AE41)),"-") -> 730572 | AG41: =IFERROR($AK41/$P41,"-") -> 1.456312 | AH41: =IFERROR(AVERAGE(AG41:AG43),"N/A") -> 1.456312 | AI41: 1.5 | AJ41: =IFERROR(IF(ISNUMBER($AI41)=TRUE, $AI41*$P41, $AH41*$P41), "-") -> 752488.5 | AK41: =IFERROR($AF41*$J41,"-") -> 730572 | AL41: =IFERROR(IF(SUM(Y41,AK41)=0,"-",SUM(Y41,AK41)),"-") -> 1711487 | AM41: =IFERROR(IF(SUM($Z41,$AJ41)=0,"-",SUM($Z41,$AJ41)),"-") -> 1630391.8 | AN41: 122673 | AO41: DB | AP41: =IFERROR(AN41*(12/$H41)*$J41,"-") -> 122673 | AQ41: =IFERROR(AVERAGE(AP41:AP43),"N/A") -> 97104 | AR41: 84863 | AS41: =IFERROR(AR41*(12/$H41)*$J41,"-") -> 84863 | AT41: =IFERROR(AVERAGE(AS41:AS43),"N/A") -> 89528.333 | AU41: =IFERROR(IF(SUM(AL41,AP41,AS41)=0,"-",SUM(AL41,AP41,AS41)),"-") -> 1919023 | AV41: =IFERROR(IF(SUM(AM41,AP41,AS41)=0,"-",SUM(AM41,AP41,AS41)),"-") -> 1837927.8 | AW41: - | AX41: AH
A42: =$C42&"_"&$E42&"_"&$K42 -> TSX:HBM_2023_Legal | B42: =$C42&"_"&$E42&"_"&$L42 -> TSX:HBM_2023_NEO2 | C42: =C41 -> TSX:HBM | D42: =_xll.ciqfunctions.udf.CIQ(C42,"IQ_Company_Name") -> Hudbay Minerals Inc. | E42: =E39 -> 2023 | F42: =E42&"-01-01" -> 2023-01-01 | G42: =E42&"-12-31" -> 2023-12-31 | H42: =_xlfn.DAYS(G42,F42)/_xlfn.DAYS(E42&"-12-31",E42&"-01-01")*12 -> 12 | I42: =I41 -> CAD | J42: =IF($I42="CAD",1,IF($I42="USD",VLOOKUP($E42,$F$9:$G$11,2,FALSE),"N/A")) -> 1 | K42: Legal | L42: =L41 -> NEO2 | M42: =M41 -> SVP, Legal and Organizational Effectiveness | N42: =N41 -> Patrick Donnelly | P42: =IFERROR(O42*(12/$H42)*$J42,"-") -> 0 | R42: =IFERROR(IF((Q42*$L42)=0,"-",(Q42*$L42)),"-") -> - | T42: =IFERROR(S42*(12/$H42)*$J42,"-") -> 0 | U42: =IFERROR($T42/$P42,"-") -> - | X42: =IFERROR(IF(ISNUMBER($W42)=TRUE, $W42*$P42,$V42*$P42),"-") -> 0 | Y42: =IFERROR(IF(SUM(P42,T42)=0,"-",SUM(P42,T42)),"-") -> - | Z42: =IFERROR(IF(SUM(P42,X42)=0,"-",SUM(P42,X42)),"-") -> - | AD42: - | AE42: - | AF42: =IFERROR(IF(SUM(AA42:AE42)=0,IF(COUNTIF($AA42:$AE42,"=0")>0,"$0","-"),SUM(AA42:AE42)),"-") -> - | AG42: =IFERROR($AK42/$P42,"-") -> - | AJ42: =IFERROR(IF(ISNUMBER($AI42)=TRUE, $AI42*$P42, $AH42*$P42), "-") -> 0 | AK42: =IFERROR($AF42*$J42,"-") -> - | AL42: =IFERROR(IF(SUM(Y42,AK42)=0,"-",SUM(Y42,AK42)),"-") -> - | AM42: =IFERROR(IF(SUM($Z42,$AJ42)=0,"-",SUM($Z42,$AJ42)),"-") -> - | AN42: 54180 | AO42: DB | AP42: =IFERROR(AN42*(12/$H42)*$J42,"-") -> 54180 | AR42: 104737 | AS42: =IFERROR(AR42*(12/$H42)*$J42,"-") -> 104737 | AU42: =IFERROR(IF(SUM(AL42,AP42,AS42)=0,"-",SUM(AL42,AP42,AS42)),"-") -> 158917 | AV42: =IFERROR(IF(SUM(AM42,AP42,AS42)=0,"-",SUM(AM42,AP42,AS42)),"-") -> 158917 | AW42: -
...

Sheet Master - Summary
A1: =TODAY() -> 45975
A2: CAD | B2: Position
B3: Year | C3: 2018
C4: Company | D4: Market Cap | E4: TEV | F4: Incumbent | G4: Position Title | H4: Annualized / Converted | I4: Annualized/ Converted | J4: Actual STI % | K4: 3 Year Average STIP % | L4: Target STI $ | M4: Target STI % | N4: Actual TCC | O4: Target TCC | P4: Total LTI (Converted) | Q4: Total LTI % | R4: 3 Year Average LTIP % | S4: Target LTI $ | T4: Target LTI % | U4: Actual (base + actual bonus + actual LTIP) | V4: Target (base + target bonus + Target LTIP) | X4: Cash | Y4: Equity
C5: =+C2& " Benchmarking - "&'Raw Data'!G5&" $000s" -> Benchmarking - CAD $000s
C6: Company | D6: Market Cap | E6: TEV | F6: Incumbent | G6: Title | H6: Base Salary | I6: STIP | L6: STIP | N6: Total Cash Compensation | P6: LTIP | S6: LTIP | U6: Total Direct Compensation | X6: Pay Mix
A7: Look-up | B7: Ticker | D7: Market Cap | E7: TEV | F7: Incumbent | G7: Title | H7: Base Salary | I7: Actual $ | J7: Actual % | K7: 3 Year Average STIP % | L7: Target $ | M7: Target % | N7: Actual $ | O7: Target $ | P7: Actual $ | Q7: Actual% | R7: 3 Year Average LTIP % | S7: Target $ | T7: Target % | U7: Actual $ | V7: Target $ | X7: Cash | Y7: Equity
A8: =$B8&"_"&$C$3&"_"&$C$2 -> TSX:T_2018_ | B8: TSX:T | C8: =IFERROR(INDEX(Raw_Data,MATCH($A8,Look_Up,0),MATCH(C$4,Component,0)),"-") -> - | D8: =_xll.ciqfunctions.udf.CIQ(B8, "IQ_MARKETCAP", $A$1,$A$2) -> 31919.76 | E8: =_xll.ciqfunctions.udf.CIQ($B8, "IQ_TEV", $A$1,$A$2) -> 61771.76 | F8: =IFERROR(INDEX(Raw_Data,MATCH($A8,Look_Up,0),MATCH(F$4,Component,0)),"-") -> - | G8: =IFERROR(INDEX(Raw_Data,MATCH($A8,Look_Up,0),MATCH(G$4,Component,0)),"-") -> - | H8: =IFERROR(INDEX(Raw_Data,MATCH($A8,Look_Up,0),MATCH(H$4,Component,0))/1000,"-") -> - | I8: =IFERROR(INDEX(Raw_Data,MATCH($A8,Look_Up,0),MATCH(I$4,Component,0))/1000,"-") -> - | J8: =IFERROR(INDEX(Raw_Data,MATCH($A8,Look_Up,0),MATCH(J$4,Component,0)),"-") -> - | K8: =IFERROR(INDEX(Raw_Data,MATCH($A8,Look_Up,0),MATCH(K$4,Component,0)),"-") -> - | L8: =IFERROR(INDEX(Raw_Data,MATCH($A8,Look_Up,0),MATCH(L$4,Component,0))/1000,"-") -> - | M8: =IFERROR(INDEX(Raw_Data,MATCH($A8,Look_Up,0),MATCH(M$4,Component,0)),"-") -> - | N8: =IFERROR(INDEX(Raw_Data,MATCH($A8,Look_Up,0),MATCH(N$4,Component,0))/1000,"-") -> - | O8: =IFERROR(INDEX(Raw_Data,MATCH($A8,Look_Up,0),MATCH(O$4,Component,0))/1000,"-") -> - | P8: =IFERROR(INDEX(Raw_Data,MATCH($A8,Look_Up,0),MATCH(P$4,Component,0))/1000,"-") -> - | Q8: =IFERROR(INDEX(Raw_Data,MATCH($A8,Look_Up,0),MATCH(Q$4,Component,0)),"-") -> - | R8: =IFERROR(INDEX(Raw_Data,MATCH($A8,Look_Up,0),MATCH(R$4,Component,0)),"-") -> - | S8: =IFERROR(INDEX(Raw_Data,MATCH($A8,Look_Up,0),MATCH(S$4,Component,0))/1000,"-") -> - | T8: =IFERROR(INDEX(Raw_Data,MATCH($A8,Look_Up,0),MATCH(T$4,Component,0)),"-") -> - | U8: =IFERROR(INDEX(Raw_Data,MATCH($A8,Look_Up,0),MATCH(U$4,Component,0))/1000,"-") -> - | V8: =IFERROR(INDEX(Raw_Data,MATCH($A8,Look_Up,0),MATCH(V$4,Component,0))/1000,"-") -> - | X8: =IFERROR(N8/U8,"-") -> - | Y8: =IFERROR(P8/U8,"-") -> -
A9: =$B9&"_"&$C$3&"_"&$C$2 -> TSX:S_2018_ | B9: TSX:S | C9: =IFERROR(INDEX(Raw_Data,MATCH($A9,Look_Up,0),MATCH(C$4,Component,0)),"-") -> - | D9: =_xll.ciqfunctions.udf.CIQ(B9, "IQ_MARKETCAP", $A$1,$A$2) -> 62.03609 | E9: =_xll.ciqfunctions.udf.CIQ($B9, "IQ_TEV", $A$1,$A$2) -> 267.43609 | F9: =IFERROR(INDEX(Raw_Data,MATCH($A9,Look_Up,0),MATCH(F$4,Component,0)),"-") -> - | G9: =IFERROR(INDEX(Raw_Data,MATCH($A9,Look_Up,0),MATCH(G$4,Component,0)),"-") -> - | H9: =IFERROR(INDEX(Raw_Data,MATCH($A9,Look_Up,0),MATCH(H$4,Component,0))/1000,"-") -> - | I9: =IFERROR(INDEX(Raw_Data,MATCH($A9,Look_Up,0),MATCH(I$4,Component,0))/1000,"-") -> - | J9: =IFERROR(INDEX(Raw_Data,MATCH($A9,Look_Up,0),MATCH(J$4,Component,0)),"-") -> - | K9: =IFERROR(INDEX(Raw_Data,MATCH($A9,Look_Up,0),MATCH(K$4,Component,0)),"-") -> - | L9: =IFERROR(INDEX(Raw_Data,MATCH($A9,Look_Up,0),MATCH(L$4,Component,0))/1000,"-") -> - | M9: =IFERROR(INDEX(Raw_Data,MATCH($A9,Look_Up,0),MATCH(M$4,Component,0)),"-") -> - | N9: =IFERROR(INDEX(Raw_Data,MATCH($A9,Look_Up,0),MATCH(N$4,Component,0))/1000,"-") -> - | O9: =IFERROR(INDEX(Raw_Data,MATCH($A9,Look_Up,0),MATCH(O$4,Component,0))/1000,"-") -> - | P9: =IFERROR(INDEX(Raw_Data,MATCH($A9,Look_Up,0),MATCH(P$4,Component,0))/1000,"-") -> - | Q9: =IFERROR(INDEX(Raw_Data,MATCH($A9,Look_Up,0),MATCH(Q$4,Component,0)),"-") -> - | R9: =IFERROR(INDEX(Raw_Data,MATCH($A9,Look_Up,0),MATCH(R$4,Component,0)),"-") -> - | S9: =IFERROR(INDEX(Raw_Data,MATCH($A9,Look_Up,0),MATCH(S$4,Component,0))/1000,"-") -> - | T9: =IFERROR(INDEX(Raw_Data,MATCH($A9,Look_Up,0),MATCH(T$4,Component,0)),"-") -> - | U9: =IFERROR(INDEX(Raw_Data,MATCH($A9,Look_Up,0),MATCH(U$4,Component,0))/1000,"-") -> - | V9: =IFERROR(INDEX(Raw_Data,MATCH($A9,Look_Up,0),MATCH(V$4,Component,0))/1000,"-") -> - | X9: =IFERROR(N9/U9,"-") -> - | Y9: =IFERROR(P9/U9,"-") -> -
A10: =$B10&"_"&$C$3&"_"&$C$2 -> TSX:R_2018_ | B10: TSX:R | C10: =IFERROR(INDEX(Raw_Data,MATCH($A10,Look_Up,0),MATCH(C$4,Component,0)),"-") -> - | D10: =_xll.ciqfunctions.udf.CIQ(B10, "IQ_MARKETCAP", $A$1,$A$2) -> (Invalid Identifier) | E10: =_xll.ciqfunctions.udf.CIQ($B10, "IQ_TEV", $A$1,$A$2) -> (Invalid Identifier) | F10: =IFERROR(INDEX(Raw_Data,MATCH($A10,Look_Up,0),MATCH(F$4,Component,0)),"-") -> - | G10: =IFERROR(INDEX(Raw_Data,MATCH($A10,Look_Up,0),MATCH(G$4,Component,0)),"-") -> - | H10: =IFERROR(INDEX(Raw_Data,MATCH($A10,Look_Up,0),MATCH(H$4,Component,0))/1000,"-") -> - | I10: =IFERROR(INDEX(Raw_Data,MATCH($A10,Look_Up,0),MATCH(I$4,Component,0))/1000,"-") -> - | J10: =IFERROR(INDEX(Raw_Data,MATCH($A10,Look_Up,0),MATCH(J$4,Component,0)),"-") -> - | K10: =IFERROR(INDEX(Raw_Data,MATCH($A10,Look_Up,0),MATCH(K$4,Component,0)),"-") -> - | L10: =IFERROR(INDEX(Raw_Data,MATCH($A10,Look_Up,0),MATCH(L$4,Component,0))/1000,"-") -> - | M10: =IFERROR(INDEX(Raw_Data,MATCH($A10,Look_Up,0),MATCH(M$4,Component,0)),"-") -> - | N10: =IFERROR(INDEX(Raw_Data,MATCH($A10,Look_Up,0),MATCH(N$4,Component,0))/1000,"-") -> - | O10: =IFERROR(INDEX(Raw_Data,MATCH($A10,Look_Up,0),MATCH(O$4,Component,0))/1000,"-") -> - | P10: =IFERROR(INDEX(Raw_Data,MATCH($A10,Look_Up,0),MATCH(P$4,Component,0))/1000,"-") -> - | Q10: =IFERROR(INDEX(Raw_Data,MATCH($A10,Look_Up,0),MATCH(Q$4,Component,0)),"-") -> - | R10: =IFERROR(INDEX(Raw_Data,MATCH($A10,Look_Up,0),MATCH(R$4,Component,0)),"-") -> - | S10: =IFERROR(INDEX(Raw_Data,MATCH($A10,Look_Up,0),MATCH(S$4,Component,0))/1000,"-") -> - | T10: =IFERROR(INDEX(Raw_Data,MATCH($A10,Look_Up,0),MATCH(T$4,Component,0)),"-") -> - | U10: =IFERROR(INDEX(Raw_Data,MATCH($A10,Look_Up,0),MATCH(U$4,Component,0))/1000,"-") -> - | V10: =IFERROR(INDEX(Raw_Data,MATCH($A10,Look_Up,0),MATCH(V$4,Component,0))/1000,"-") -> - | X10: =IFERROR(N10/U10,"-") -> - | Y10: =IFERROR(P10/U10,"-") -> -
A11: =$B11&"_"&$C$3&"_"&$C$2 -> TSX:Q_2018_ | B11: TSX:Q | C11: =IFERROR(INDEX(Raw_Data,MATCH($A11,Look_Up,0),MATCH(C$4,Component,0)),"-") -> - | D11: =_xll.ciqfunctions.udf.CIQ(B11, "IQ_MARKETCAP", $A$1,$A$2) -> (Invalid Identifier) | E11: =_xll.ciqfunctions.udf.CIQ($B11, "IQ_TEV", $A$1,$A$2) -> (Invalid Identifier) | F11: =IFERROR(INDEX(Raw_Data,MATCH($A11,Look_Up,0),MATCH(F$4,Component,0)),"-") -> - | G11: =IFERROR(INDEX(Raw_Data,MATCH($A11,Look_Up,0),MATCH(G$4,Component,0)),"-") -> - | H11: =IFERROR(INDEX(Raw_Data,MATCH($A11,Look_Up,0),MATCH(H$4,Component,0))/1000,"-") -> - | I11: =IFERROR(INDEX(Raw_Data,MATCH($A11,Look_Up,0),MATCH(I$4,Component,0))/1000,"-") -> - | J11: =IFERROR(INDEX(Raw_Data,MATCH($A11,Look_Up,0),MATCH(J$4,Component,0)),"-") -> - | K11: =IFERROR(INDEX(Raw_Data,MATCH($A11,Look_Up,0),MATCH(K$4,Component,0)),"-") -> - | L11: =IFERROR(INDEX(Raw_Data,MATCH($A11,Look_Up,0),MATCH(L$4,Component,0))/1000,"-") -> - | M11: =IFERROR(INDEX(Raw_Data,MATCH($A11,Look_Up,0),MATCH(M$4,Component,0)),"-") -> - | N11: =IFERROR(INDEX(Raw_Data,MATCH($A11,Look_Up,0),MATCH(N$4,Component,0))/1000,"-") -> - | O11: =IFERROR(INDEX(Raw_Data,MATCH($A11,Look_Up,0),MATCH(O$4,Component,0))/1000,"-") -> - | P11: =IFERROR(INDEX(Raw_Data,MATCH($A11,Look_Up,0),MATCH(P$4,Component,0))/1000,"-") -> - | Q11: =IFERROR(INDEX(Raw_Data,MATCH($A11,Look_Up,0),MATCH(Q$4,Component,0)),"-") -> - | R11: =IFERROR(INDEX(Raw_Data,MATCH($A11,Look_Up,0),MATCH(R$4,Component,0)),"-") -> - | S11: =IFERROR(INDEX(Raw_Data,MATCH($A11,Look_Up,0),MATCH(S$4,Component,0))/1000,"-") -> - | T11: =IFERROR(INDEX(Raw_Data,MATCH($A11,Look_Up,0),MATCH(T$4,Component,0)),"-") -> - | U11: =IFERROR(INDEX(Raw_Data,MATCH($A11,Look_Up,0),MATCH(U$4,Component,0))/1000,"-") -> - | V11: =IFERROR(INDEX(Raw_Data,MATCH($A11,Look_Up,0),MATCH(V$4,Component,0))/1000,"-") -> - | X11: =IFERROR(N11/U11,"-") -> - | Y11: =IFERROR(P11/U11,"-") -> -
A12: =$B12&"_"&$C$3&"_"&$C$2 -> TSX:P_2018_ | B12: TSX:P | C12: =IFERROR(INDEX(Raw_Data,MATCH($A12,Look_Up,0),MATCH(C$4,Component,0)),"-") -> - | D12: =_xll.ciqfunctions.udf.CIQ(B12, "IQ_MARKETCAP", $A$1,$A$2) -> (Invalid Identifier) | E12: =_xll.ciqfunctions.udf.CIQ($B12, "IQ_TEV", $A$1,$A$2) -> (Invalid Identifier) | F12: =IFERROR(INDEX(Raw_Data,MATCH($A12,Look_Up,0),MATCH(F$4,Component,0)),"-") -> - | G12: =IFERROR(INDEX(Raw_Data,MATCH($A12,Look_Up,0),MATCH(G$4,Component,0)),"-") -> - | H12: =IFERROR(INDEX(Raw_Data,MATCH($A12,Look_Up,0),MATCH(H$4,Component,0))/1000,"-") -> - | I12: =IFERROR(INDEX(Raw_Data,MATCH($A12,Look_Up,0),MATCH(I$4,Component,0))/1000,"-") -> - | J12: =IFERROR(INDEX(Raw_Data,MATCH($A12,Look_Up,0),MATCH(J$4,Component,0)),"-") -> - | K12: =IFERROR(INDEX(Raw_Data,MATCH($A12,Look_Up,0),MATCH(K$4,Component,0)),"-") -> - | L12: =IFERROR(INDEX(Raw_Data,MATCH($A12,Look_Up,0),MATCH(L$4,Component,0))/1000,"-") -> - | M12: =IFERROR(INDEX(Raw_Data,MATCH($A12,Look_Up,0),MATCH(M$4,Component,0)),"-") -> - | N12: =IFERROR(INDEX(Raw_Data,MATCH($A12,Look_Up,0),MATCH(N$4,Component,0))/1000,"-") -> - | O12: =IFERROR(INDEX(Raw_Data,MATCH($A12,Look_Up,0),MATCH(O$4,Component,0))/1000,"-") -> - | P12: =IFERROR(INDEX(Raw_Data,MATCH($A12,Look_Up,0),MATCH(P$4,Component,0))/1000,"-") -> - | Q12: =IFERROR(INDEX(Raw_Data,MATCH($A12,Look_Up,0),MATCH(Q$4,Component,0)),"-") -> - | R12: =IFERROR(INDEX(Raw_Data,MATCH($A12,Look_Up,0),MATCH(R$4,Component,0)),"-") -> - | S12: =IFERROR(INDEX(Raw_Data,MATCH($A12,Look_Up,0),MATCH(S$4,Component,0))/1000,"-") -> - | T12: =IFERROR(INDEX(Raw_Data,MATCH($A12,Look_Up,0),MATCH(T$4,Component,0)),"-") -> - | U12: =IFERROR(INDEX(Raw_Data,MATCH($A12,Look_Up,0),MATCH(U$4,Component,0))/1000,"-") -> - | V12: =IFERROR(INDEX(Raw_Data,MATCH($A12,Look_Up,0),MATCH(V$4,Component,0))/1000,"-") -> - | X12: =IFERROR(N12/U12,"-") -> - | Y12: =IFERROR(P12/U12,"-") -> -
A13: =$B13&"_"&$C$3&"_"&$C$2 -> TSX:O_2018_ | B13: TSX:O | C13: =IFERROR(INDEX(Raw_Data,MATCH($A13,Look_Up,0),MATCH(C$4,Component,0)),"-") -> - | D13: =_xll.ciqfunctions.udf.CIQ(B13, "IQ_MARKETCAP", $A$1,$A$2) -> (Invalid Identifier) | E13: =_xll.ciqfunctions.udf.CIQ($B13, "IQ_TEV", $A$1,$A$2) -> (Invalid Identifier) | F13: =IFERROR(INDEX(Raw_Data,MATCH($A13,Look_Up,0),MATCH(F$4,Component,0)),"-") -> - | G13: =IFERROR(INDEX(Raw_Data,MATCH($A13,Look_Up,0),MATCH(G$4,Component,0)),"-") -> - | H13: =IFERROR(INDEX(Raw_Data,MATCH($A13,Look_Up,0),MATCH(H$4,Component,0))/1000,"-") -> - | I13: =IFERROR(INDEX(Raw_Data,MATCH($A13,Look_Up,0),MATCH(I$4,Component,0))/1000,"-") -> - | J13: =IFERROR(INDEX(Raw_Data,MATCH($A13,Look_Up,0),MATCH(J$4,Component,0)),"-") -> - | K13: =IFERROR(INDEX(Raw_Data,MATCH($A13,Look_Up,0),MATCH(K$4,Component,0)),"-") -> - | L13: =IFERROR(INDEX(Raw_Data,MATCH($A13,Look_Up,0),MATCH(L$4,Component,0))/1000,"-") -> - | M13: =IFERROR(INDEX(Raw_Data,MATCH($A13,Look_Up,0),MATCH(M$4,Component,0)),"-") -> - | N13: =IFERROR(INDEX(Raw_Data,MATCH($A13,Look_Up,0),MATCH(N$4,Component,0))/1000,"-") -> - | O13: =IFERROR(INDEX(Raw_Data,MATCH($A13,Look_Up,0),MATCH(O$4,Component,0))/1000,"-") -> - | P13: =IFERROR(INDEX(Raw_Data,MATCH($A13,Look_Up,0),MATCH(P$4,Component,0))/1000,"-") -> - | Q13: =IFERROR(INDEX(Raw_Data,MATCH($A13,Look_Up,0),MATCH(Q$4,Component,0)),"-") -> - | R13: =IFERROR(INDEX(Raw_Data,MATCH($A13,Look_Up,0),MATCH(R$4,Component,0)),"-") -> - | S13: =IFERROR(INDEX(Raw_Data,MATCH($A13,Look_Up,0),MATCH(S$4,Component,0))/1000,"-") -> - | T13: =IFERROR(INDEX(Raw_Data,MATCH($A13,Look_Up,0),MATCH(T$4,Component,0)),"-") -> - | U13: =IFERROR(INDEX(Raw_Data,MATCH($A13,Look_Up,0),MATCH(U$4,Component,0))/1000,"-") -> - | V13: =IFERROR(INDEX(Raw_Data,MATCH($A13,Look_Up,0),MATCH(V$4,Component,0))/1000,"-") -> - | X13: =IFERROR(N13/U13,"-") -> - | Y13: =IFERROR(P13/U13,"-") -> -
A14: =$B14&"_"&$C$3&"_"&$C$2 -> TSX:N_2018_ | B14: TSX:N | C14: =IFERROR(INDEX(Raw_Data,MATCH($A14,Look_Up,0),MATCH(C$4,Component,0)),"-") -> - | D14: =_xll.ciqfunctions.udf.CIQ(B14, "IQ_MARKETCAP", $A$1,$A$2) -> (Invalid Identifier) | E14: =_xll.ciqfunctions.udf.CIQ($B14, "IQ_TEV", $A$1,$A$2) -> (Invalid Identifier) | F14: =IFERROR(INDEX(Raw_Data,MATCH($A14,Look_Up,0),MATCH(F$4,Component,0)),"-") -> - | G14: =IFERROR(INDEX(Raw_Data,MATCH($A14,Look_Up,0),MATCH(G$4,Component,0)),"-") -> - | H14: =IFERROR(INDEX(Raw_Data,MATCH($A14,Look_Up,0),MATCH(H$4,Component,0))/1000,"-") -> - | I14: =IFERROR(INDEX(Raw_Data,MATCH($A14,Look_Up,0),MATCH(I$4,Component,0))/1000,"-") -> - | J14: =IFERROR(INDEX(Raw_Data,MATCH($A14,Look_Up,0),MATCH(J$4,Component,0)),"-") -> - | K14: =IFERROR(INDEX(Raw_Data,MATCH($A14,Look_Up,0),MATCH(K$4,Component,0)),"-") -> - | L14: =IFERROR(INDEX(Raw_Data,MATCH($A14,Look_Up,0),MATCH(L$4,Component,0))/1000,"-") -> - | M14: =IFERROR(INDEX(Raw_Data,MATCH($A14,Look_Up,0),MATCH(M$4,Component,0)),"-") -> - | N14: =IFERROR(INDEX(Raw_Data,MATCH($A14,Look_Up,0),MATCH(N$4,Component,0))/1000,"-") -> - | O14: =IFERROR(INDEX(Raw_Data,MATCH($A14,Look_Up,0),MATCH(O$4,Component,0))/1000,"-") -> - | P14: =IFERROR(INDEX(Raw_Data,MATCH($A14,Look_Up,0),MATCH(P$4,Component,0))/1000,"-") -> - | Q14: =IFERROR(INDEX(Raw_Data,MATCH($A14,Look_Up,0),MATCH(Q$4,Component,0)),"-") -> - | R14: =IFERROR(INDEX(Raw_Data,MATCH($A14,Look_Up,0),MATCH(R$4,Component,0)),"-") -> - | S14: =IFERROR(INDEX(Raw_Data,MATCH($A14,Look_Up,0),MATCH(S$4,Component,0))/1000,"-") -> - | T14: =IFERROR(INDEX(Raw_Data,MATCH($A14,Look_Up,0),MATCH(T$4,Component,0)),"-") -> - | U14: =IFERROR(INDEX(Raw_Data,MATCH($A14,Look_Up,0),MATCH(U$4,Component,0))/1000,"-") -> - | V14: =IFERROR(INDEX(Raw_Data,MATCH($A14,Look_Up,0),MATCH(V$4,Component,0))/1000,"-") -> - | X14: =IFERROR(N14/U14,"-") -> - | Y14: =IFERROR(P14/U14,"-") -> -
A15: =$B15&"_"&$C$3&"_"&$C$2 -> TSX:M_2018_ | B15: TSX:M | C15: =IFERROR(INDEX(Raw_Data,MATCH($A15,Look_Up,0),MATCH(C$4,Component,0)),"-") -> - | D15: =_xll.ciqfunctions.udf.CIQ(B15, "IQ_MARKETCAP", $A$1,$A$2) -> (Invalid Identifier) | E15: =_xll.ciqfunctions.udf.CIQ($B15, "IQ_TEV", $A$1,$A$2) -> (Invalid Identifier) | F15: =IFERROR(INDEX(Raw_Data,MATCH($A15,Look_Up,0),MATCH(F$4,Component,0)),"-") -> - | G15: =IFERROR(INDEX(Raw_Data,MATCH($A15,Look_Up,0),MATCH(G$4,Component,0)),"-") -> - | H15: =IFERROR(INDEX(Raw_Data,MATCH($A15,Look_Up,0),MATCH(H$4,Component,0))/1000,"-") -> - | I15: =IFERROR(INDEX(Raw_Data,MATCH($A15,Look_Up,0),MATCH(I$4,Component,0))/1000,"-") -> - | J15: =IFERROR(INDEX(Raw_Data,MATCH($A15,Look_Up,0),MATCH(J$4,Component,0)),"-") -> - | K15: =IFERROR(INDEX(Raw_Data,MATCH($A15,Look_Up,0),MATCH(K$4,Component,0)),"-") -> - | L15: =IFERROR(INDEX(Raw_Data,MATCH($A15,Look_Up,0),MATCH(L$4,Component,0))/1000,"-") -> - | M15: =IFERROR(INDEX(Raw_Data,MATCH($A15,Look_Up,0),MATCH(M$4,Component,0)),"-") -> - | N15: =IFERROR(INDEX(Raw_Data,MATCH($A15,Look_Up,0),MATCH(N$4,Component,0))/1000,"-") -> - | O15: =IFERROR(INDEX(Raw_Data,MATCH($A15,Look_Up,0),MATCH(O$4,Component,0))/1000,"-") -> - | P15: =IFERROR(INDEX(Raw_Data,MATCH($A15,Look_Up,0),MATCH(P$4,Component,0))/1000,"-") -> - | Q15: =IFERROR(INDEX(Raw_Data,MATCH($A15,Look_Up,0),MATCH(Q$4,Component,0)),"-") -> - | R15: =IFERROR(INDEX(Raw_Data,MATCH($A15,Look_Up,0),MATCH(R$4,Component,0)),"-") -> - | S15: =IFERROR(INDEX(Raw_Data,MATCH($A15,Look_Up,0),MATCH(S$4,Component,0))/1000,"-") -> - | T15: =IFERROR(INDEX(Raw_Data,MATCH($A15,Look_Up,0),MATCH(T$4,Component,0)),"-") -> - | U15: =IFERROR(INDEX(Raw_Data,MATCH($A15,Look_Up,0),MATCH(U$4,Component,0))/1000,"-") -> - | V15: =IFERROR(INDEX(Raw_Data,MATCH($A15,Look_Up,0),MATCH(V$4,Component,0))/1000,"-") -> - | X15: =IFERROR(N15/U15,"-") -> - | Y15: =IFERROR(P15/U15,"-") -> -
A16: =$B16&"_"&$C$3&"_"&$C$2 -> TSX:L_2018_ | B16: TSX:L | C16: =IFERROR(INDEX(Raw_Data,MATCH($A16,Look_Up,0),MATCH(C$4,Component,0)),"-") -> - | D16: =_xll.ciqfunctions.udf.CIQ(B16, "IQ_MARKETCAP", $A$1,$A$2) -> 69884.25 | E16: =_xll.ciqfunctions.udf.CIQ($B16, "IQ_TEV", $A$1,$A$2) -> 87934.25 | F16: =IFERROR(INDEX(Raw_Data,MATCH($A16,Look_Up,0),MATCH(F$4,Component,0)),"-") -> - | G16: =IFERROR(INDEX(Raw_Data,MATCH($A16,Look_Up,0),MATCH(G$4,Component,0)),"-") -> - | H16: =IFERROR(INDEX(Raw_Data,MATCH($A16,Look_Up,0),MATCH(H$4,Component,0))/1000,"-") -> - | I16: =IFERROR(INDEX(Raw_Data,MATCH($A16,Look_Up,0),MATCH(I$4,Component,0))/1000,"-") -> - | J16: =IFERROR(INDEX(Raw_Data,MATCH($A16,Look_Up,0),MATCH(J$4,Component,0)),"-") -> - | K16: =IFERROR(INDEX(Raw_Data,MATCH($A16,Look_Up,0),MATCH(K$4,Component,0)),"-") -> - | L16: =IFERROR(INDEX(Raw_Data,MATCH($A16,Look_Up,0),MATCH(L$4,Component,0))/1000,"-") -> - | M16: =IFERROR(INDEX(Raw_Data,MATCH($A16,Look_Up,0),MATCH(M$4,Component,0)),"-") -> - | N16: =IFERROR(INDEX(Raw_Data,MATCH($A16,Look_Up,0),MATCH(N$4,Component,0))/1000,"-") -> - | O16: =IFERROR(INDEX(Raw_Data,MATCH($A16,Look_Up,0),MATCH(O$4,Component,0))/1000,"-") -> - | P16: =IFERROR(INDEX(Raw_Data,MATCH($A16,Look_Up,0),MATCH(P$4,Component,0))/1000,"-") -> - | Q16: =IFERROR(INDEX(Raw_Data,MATCH($A16,Look_Up,0),MATCH(Q$4,Component,0)),"-") -> - | R16: =IFERROR(INDEX(Raw_Data,MATCH($A16,Look_Up,0),MATCH(R$4,Component,0)),"-") -> - | S16: =IFERROR(INDEX(Raw_Data,MATCH($A16,Look_Up,0),MATCH(S$4,Component,0))/1000,"-") -> - | T16: =IFERROR(INDEX(Raw_Data,MATCH($A16,Look_Up,0),MATCH(T$4,Component,0)),"-") -> - | U16: =IFERROR(INDEX(Raw_Data,MATCH($A16,Look_Up,0),MATCH(U$4,Component,0))/1000,"-") -> - | V16: =IFERROR(INDEX(Raw_Data,MATCH($A16,Look_Up,0),MATCH(V$4,Component,0))/1000,"-") -> - | X16: =IFERROR(N16/U16,"-") -> - | Y16: =IFERROR(P16/U16,"-") -> -
A17: =$B17&"_"&$C$3&"_"&$C$2 -> TSX:K_2018_ | B17: TSX:K | C17: =IFERROR(INDEX(Raw_Data,MATCH($A17,Look_Up,0),MATCH(C$4,Component,0)),"-") -> - | D17: =_xll.ciqfunctions.udf.CIQ(B17, "IQ_MARKETCAP", $A$1,$A$2) -> 43214.18 | E17: =_xll.ciqfunctions.udf.CIQ($B17, "IQ_TEV", $A$1,$A$2) -> 42579.719 | F17: =IFERROR(INDEX(Raw_Data,MATCH($A17,Look_Up,0),MATCH(F$4,Component,0)),"-") -> - | G17: =IFERROR(INDEX(Raw_Data,MATCH($A17,Look_Up,0),MATCH(G$4,Component,0)),"-") -> - | H17: =IFERROR(INDEX(Raw_Data,MATCH($A17,Look_Up,0),MATCH(H$4,Component,0))/1000,"-") -> - | I17: =IFERROR(INDEX(Raw_Data,MATCH($A17,Look_Up,0),MATCH(I$4,Component,0))/1000,"-") -> - | J17: =IFERROR(INDEX(Raw_Data,MATCH($A17,Look_Up,0),MATCH(J$4,Component,0)),"-") -> - | K17: =IFERROR(INDEX(Raw_Data,MATCH($A17,Look_Up,0),MATCH(K$4,Component,0)),"-") -> - | L17: =IFERROR(INDEX(Raw_Data,MATCH($A17,Look_Up,0),MATCH(L$4,Component,0))/1000,"-") -> - | M17: =IFERROR(INDEX(Raw_Data,MATCH($A17,Look_Up,0),MATCH(M$4,Component,0)),"-") -> - | N17: =IFERROR(INDEX(Raw_Data,MATCH($A17,Look_Up,0),MATCH(N$4,Component,0))/1000,"-") -> - | O17: =IFERROR(INDEX(Raw_Data,MATCH($A17,Look_Up,0),MATCH(O$4,Component,0))/1000,"-") -> - | P17: =IFERROR(INDEX(Raw_Data,MATCH($A17,Look_Up,0),MATCH(P$4,Component,0))/1000,"-") -> - | Q17: =IFERROR(INDEX(Raw_Data,MATCH($A17,Look_Up,0),MATCH(Q$4,Component,0)),"-") -> - | R17: =IFERROR(INDEX(Raw_Data,MATCH($A17,Look_Up,0),MATCH(R$4,Component,0)),"-") -> - | S17: =IFERROR(INDEX(Raw_Data,MATCH($A17,Look_Up,0),MATCH(S$4,Component,0))/1000,"-") -> - | T17: =IFERROR(INDEX(Raw_Data,MATCH($A17,Look_Up,0),MATCH(T$4,Component,0)),"-") -> - | U17: =IFERROR(INDEX(Raw_Data,MATCH($A17,Look_Up,0),MATCH(U$4,Component,0))/1000,"-") -> - | V17: =IFERROR(INDEX(Raw_Data,MATCH($A17,Look_Up,0),MATCH(V$4,Component,0))/1000,"-") -> - | X17: =IFERROR(N17/U17,"-") -> - | Y17: =IFERROR(P17/U17,"-") -> -
A18: =$B18&"_"&$C$3&"_"&$C$2 -> TSX:J_2018_ | B18: TSX:J | C18: =IFERROR(INDEX(Raw_Data,MATCH($A18,Look_Up,0),MATCH(C$4,Component,0)),"-") -> - | D18: =_xll.ciqfunctions.udf.CIQ(B18, "IQ_MARKETCAP", $A$1,$A$2) -> 0 | E18: =_xll.ciqfunctions.udf.CIQ($B18, "IQ_TEV", $A$1,$A$2) -> 0 | F18: =IFERROR(INDEX(Raw_Data,MATCH($A18,Look_Up,0),MATCH(F$4,Component,0)),"-") -> - | G18: =IFERROR(INDEX(Raw_Data,MATCH($A18,Look_Up,0),MATCH(G$4,Component,0)),"-") -> - | H18: =IFERROR(INDEX(Raw_Data,MATCH($A18,Look_Up,0),MATCH(H$4,Component,0))/1000,"-") -> - | I18: =IFERROR(INDEX(Raw_Data,MATCH($A18,Look_Up,0),MATCH(I$4,Component,0))/1000,"-") -> - | J18: =IFERROR(INDEX(Raw_Data,MATCH($A18,Look_Up,0),MATCH(J$4,Component,0)),"-") -> - | K18: =IFERROR(INDEX(Raw_Data,MATCH($A18,Look_Up,0),MATCH(K$4,Component,0)),"-") -> - | L18: =IFERROR(INDEX(Raw_Data,MATCH($A18,Look_Up,0),MATCH(L$4,Component,0))/1000,"-") -> - | M18: =IFERROR(INDEX(Raw_Data,MATCH($A18,Look_Up,0),MATCH(M$4,Component,0)),"-") -> - | N18: =IFERROR(INDEX(Raw_Data,MATCH($A18,Look_Up,0),MATCH(N$4,Component,0))/1000,"-") -> - | O18: =IFERROR(INDEX(Raw_Data,MATCH($A18,Look_Up,0),MATCH(O$4,Component,0))/1000,"-") -> - | P18: =IFERROR(INDEX(Raw_Data,MATCH($A18,Look_Up,0),MATCH(P$4,Component,0))/1000,"-") -> - | Q18: =IFERROR(INDEX(Raw_Data,MATCH($A18,Look_Up,0),MATCH(Q$4,Component,0)),"-") -> - | R18: =IFERROR(INDEX(Raw_Data,MATCH($A18,Look_Up,0),MATCH(R$4,Component,0)),"-") -> - | S18: =IFERROR(INDEX(Raw_Data,MATCH($A18,Look_Up,0),MATCH(S$4,Component,0))/1000,"-") -> - | T18: =IFERROR(INDEX(Raw_Data,MATCH($A18,Look_Up,0),MATCH(T$4,Component,0)),"-") -> - | U18: =IFERROR(INDEX(Raw_Data,MATCH($A18,Look_Up,0),MATCH(U$4,Component,0))/1000,"-") -> - | V18: =IFERROR(INDEX(Raw_Data,MATCH($A18,Look_Up,0),MATCH(V$4,Component,0))/1000,"-") -> - | X18: =IFERROR(N18/U18,"-") -> - | Y18: =IFERROR(P18/U18,"-") -> -
A19: =$B19&"_"&$C$3&"_"&$C$2 -> TSX:I_2018_ | B19: TSX:I | C19: =IFERROR(INDEX(Raw_Data,MATCH($A19,Look_Up,0),MATCH(C$4,Component,0)),"-") -> - | D19: =_xll.ciqfunctions.udf.CIQ(B19, "IQ_MARKETCAP", $A$1,$A$2) -> (Invalid Identifier) | E19: =_xll.ciqfunctions.udf.CIQ($B19, "IQ_TEV", $A$1,$A$2) -> (Invalid Identifier) | F19: =IFERROR(INDEX(Raw_Data,MATCH($A19,Look_Up,0),MATCH(F$4,Component,0)),"-") -> - | G19: =IFERROR(INDEX(Raw_Data,MATCH($A19,Look_Up,0),MATCH(G$4,Component,0)),"-") -> - | H19: =IFERROR(INDEX(Raw_Data,MATCH($A19,Look_Up,0),MATCH(H$4,Component,0))/1000,"-") -> - | I19: =IFERROR(INDEX(Raw_Data,MATCH($A19,Look_Up,0),MATCH(I$4,Component,0))/1000,"-") -> - | J19: =IFERROR(INDEX(Raw_Data,MATCH($A19,Look_Up,0),MATCH(J$4,Component,0)),"-") -> - | K19: =IFERROR(INDEX(Raw_Data,MATCH($A19,Look_Up,0),MATCH(K$4,Component,0)),"-") -> - | L19: =IFERROR(INDEX(Raw_Data,MATCH($A19,Look_Up,0),MATCH(L$4,Component,0))/1000,"-") -> - | M19: =IFERROR(INDEX(Raw_Data,MATCH($A19,Look_Up,0),MATCH(M$4,Component,0)),"-") -> - | N19: =IFERROR(INDEX(Raw_Data,MATCH($A19,Look_Up,0),MATCH(N$4,Component,0))/1000,"-") -> - | O19: =IFERROR(INDEX(Raw_Data,MATCH($A19,Look_Up,0),MATCH(O$4,Component,0))/1000,"-") -> - | P19: =IFERROR(INDEX(Raw_Data,MATCH($A19,Look_Up,0),MATCH(P$4,Component,0))/1000,"-") -> - | Q19: =IFERROR(INDEX(Raw_Data,MATCH($A19,Look_Up,0),MATCH(Q$4,Component,0)),"-") -> - | R19: =IFERROR(INDEX(Raw_Data,MATCH($A19,Look_Up,0),MATCH(R$4,Component,0)),"-") -> - | S19: =IFERROR(INDEX(Raw_Data,MATCH($A19,Look_Up,0),MATCH(S$4,Component,0))/1000,"-") -> - | T19: =IFERROR(INDEX(Raw_Data,MATCH($A19,Look_Up,0),MATCH(T$4,Component,0)),"-") -> - | U19: =IFERROR(INDEX(Raw_Data,MATCH($A19,Look_Up,0),MATCH(U$4,Component,0))/1000,"-") -> - | V19: =IFERROR(INDEX(Raw_Data,MATCH($A19,Look_Up,0),MATCH(V$4,Component,0))/1000,"-") -> - | X19: =IFERROR(N19/U19,"-") -> - | Y19: =IFERROR(P19/U19,"-") -> -
