Workbook
Name _Hlk3298152: Instructions!$B$32
Name CFO: #REF!
Name CFO: #REF!
Name Client_Ticker: #REF!
Name Client_Ticker: #REF!
Name Component: 'Raw Data'!$B$31:$BA$31
Name Currency_CAD: #REF!
Name Currency_CAD: #REF!
Name FX_2011: #REF!
Name FX_2011: #REF!
Name FX_2012: #REF!
Name FX_2012: #REF!
Name FX_2013: #REF!
Name FX_2013: #REF!
Name IQ_CH: 110000
Name IQ_CQ: 5000
Name IQ_CY: 10000
Name IQ_DAILY: 500000
Name IQ_FH: 100000
Name IQ_FQ: 500
Name IQ_FY: 1000
Name IQ_LTM: 2000
Name IQ_MONTH: 15000
Name IQ_NTM: 6000
Name IQ_WEEK: 50000
Name IQ_YTD: 3000
Name Look_Up: 'Raw Data'!$B$31:$B$1048576
Name Look_Up2: 'Raw Data'!$A$31:$A$1048576
Name Look_Up3: 'Raw Data'!$C$31:$C$1048576
Name Peer_1_Ticker: #REF!
Name Peer_1_Ticker: #REF!
Name Peer_10_Ticker: #REF!
Name Peer_10_Ticker: #REF!
Name Peer_12_Ticker: #REF!
Name Peer_12_Ticker: #REF!
Name Peer_13_Ticker: #REF!
Name Peer_13_Ticker: #REF!
Name Peer_14_Ticker: #REF!
Name Peer_14_Ticker: #REF!
Name Peer_2_Ticker: #REF!
Name Peer_2_Ticker: #REF!
Name Peer_3_Ticker: #REF!
Name Peer_3_Ticker: #REF!
Name Peer_4_Ticker: #REF!
Name Peer_4_Ticker: #REF!
Name Peer_5_Ticker: #REF!
Name Peer_5_Ticker: #REF!
Name Peer_6_Ticker: #REF!
Name Peer_6_Ticker: #REF!
Name Peer_7_Ticker: #REF!
Name Peer_7_Ticker: #REF!
Name Peer_8_Ticker: #REF!
Name Peer_8_Ticker: #REF!
Name Peer_9_Ticker: #REF!
Name Peer_9_Ticker: #REF!
Name raw: #REF!
Name raw: #REF!
Name Raw_Data: #REF!
Name Raw_Data: #REF!
Name Raw_Data: 'Raw Data'!$B$31:$BA$1048576

Sheet __snloffice
A1: 允䅁䍁䅯䅁䵁䅁䅁䅖呂䙁䅧杏䉂䅁䅁䅁䅁䵁䉙䅁㡁䙁䅁兙祂䝁䅅兢杁䝁䅫䅚㥁䍁䅉兎楁䑁䄴免㡁䍁䄸䅕桂䡁䅉兙瑂䑁䄴䅐兂䝁䅅杣桂䝁䄰䅉灂䝁䅑児楁䑁䅅杉⭁䍁䄰免㑁䑁䅫免穁䑁䅫李㑁䑁䅕䅎㡁䍁䄸䅕桂䡁䅉兙瑂䑁䄴䅐兂䝁䅅杣桂䝁䄰䅉灂䝁䅑児楁䑁䅍杉⭁䑁䅉睎㡁䍁䄸䅕桂䡁䅉兙瑂䑁䄴䅐兂䝁䅅杣桂䝁䄰䅉灂䝁䅑児楁䑁䅉杉⭁䑁䅅䅍睁䑁䅁兎ぁ䑁䅷睌兂䝁䅅杣桂䝁䄰材㡁䙁䅁兙祂䝁䅅兢杁䝁䅫䅚㥁䍁䅉䅎楁䑁䄴䅍㡁䍁䄸䅕桂䡁䅉兙瑂䑁䄴䅐兂䝁䅅杣桂䝁䄰䅉灂䝁䅑児楁䑁䅣杉⭁䑁䅙睌祁䑁䅉睌祁䑁䅁杍㉁䑁䅷睌兂䝁䅅杣桂䝁䄰材㡁䙁䅁兙祂䝁䅅兢杁䝁䅫䅚㥁䍁䅉免㍁䍁䅉材㑁䑁䅣睍㑁䑁䅁免㡁䍁䄸䅕桂䡁䅉兙瑂䑁䄴䅐兂䝁䅅杣桂䝁䄰䅉灂䝁䅑児楁䑁䅅䅏楁䑁䄴睎穁䑁䅕免㑁䍁䄴李祁䑁䅕䅍ㅁ䑁䅉䅐癁䙁䅁兙祂䝁䅅兢⭁䅁䅁睈䅁䉁䅯䅁䩂䙁䅅睘乂䕁䅅杕䱂䕁䅕䅖䑂䕁䅅䅕䅁䅁䅅䅁䵁䅁䅁䅖呂䙁䅧杏䭂䅁䅁杄䅁䅁䅷䅁ぁ䑁䅙免㕁䑁䅕䅁䍁䅁䅁䅄䅁䙁䅑睕奂䑁䅯睓䅁䅁䅕䅁䵁䅁䅁䅖呂䙁䅧杏䑂䅁䅁睇䅁䅁䅧䅁䑂䕁䅅䅒䅁䅁䅍䅁煁䅁䅁䅋䩂䝁䄴杤桂䝁䅷兡歂䍁䅁兓歂䝁䅕杢あ䝁䅫杚灂䝁䅕杣灁䅁䅁䅂䅁䅁䄴䅁䩂䙁䅅睘啂䕁䅕杖䅁䅁䅙䅁䝄允䅁䅐兂䝁䅅杣桂䝁䄰䅉灂䝁䅑児楁䑁䅕杉⭁䑁䅅䅐癁䙁䅁兙祂䝁䅅兢⭁䑁䅷䅕桂䡁䅉兙瑂䍁䅁兡歂䑁䄰杉硁䍁䅉材瑁䑁䅅䅏㕁䑁䅍䅍ㅁ䑁䅙䅍㑁䑁䅅䅐癁䙁䅁兙祂䝁䅅兢⭁䑁䅷䅕桂䡁䅉兙瑂䍁䅁兡歂䑁䄰杉穁䍁䅉材祁䑁䅣䅐癁䙁䅁兙祂䝁䅅兢⭁䑁䅷䅕桂䡁䅉兙瑂䍁䅁兡歂䑁䄰杉祁䍁䅉材硁䑁䅁䅍睁䑁䅙䅍㡁䍁䄸䅕桂䡁䅉兙瑂䑁䄴䅐兂䝁䅅杣桂䝁䄰䅉灂䝁䅑児楁䑁䅑杉⭁䑁䅁䅐癁䙁䅁兙祂䝁䅅兢⭁䑁䅷䅕桂䡁䅉兙瑂䍁䅁兡歂䑁䄰杉㍁䍁䅉材㉁䍁䄸杍祁䍁䄸杍睁䑁䅉李㡁䍁䄸䅕桂䡁䅉兙瑂䑁䄴䅐兂䝁䅅杣桂䝁䄰䅉灂䝁䅑児楁䑁䅅睎楁䑁䄴杍㕁䑁䅣免㍁䑁䅫䅐癁䙁䅁兙祂䝁䅅兢⭁䑁䅷䅕桂䡁䅉兙瑂䍁䅁兡歂䑁䄰杉硁䑁䅧杉⭁䑁䅑杍㉁䑁䅙兏畁䑁䅙李ㅁ䑁䅁杍硁䑁䅷睌兂䝁䅅杣桂䝁䄰材䅁䅁䅣䅁䵁䅁䅁䅖呂䙁䅧杏䵂䅁䅁䅃䅁䵁䉙䅁㡁䙁䅁兙祂䝁䅅兢杁䝁䅫䅚㥁䍁䅉兎楁䑁䄴免㡁䍁䄸䅕桂䡁䅉兙瑂䑁䄴䅐兂䝁䅅杣桂䝁䄰䅉灂䝁䅑児楁䑁䅅杉⭁䍁䄰免㑁䑁䅫免穁䑁䅫李㑁䑁䅕䅎㡁䍁䄸䅕桂䡁䅉兙瑂䑁䄴䅐兂䝁䅅杣桂䝁䄰䅉灂䝁䅑児楁䑁䅍杉⭁䑁䅉睎㡁䍁䄸䅕桂䡁䅉兙瑂䑁䄴䅐兂䝁䅅杣桂䝁䄰䅉灂䝁䅑児楁䑁䅉杉⭁䑁䅅䅍睁䑁䅁李睁䑁䅷睌兂䝁䅅杣桂䝁䄰材㡁䙁䅁兙祂䝁䅅兢杁䝁䅫䅚㥁䍁䅉䅎楁䑁䄴䅍㡁䍁䄸䅕桂䡁䅉兙瑂䑁䄴䅐兂䝁䅅杣桂䝁䄰䅉灂䝁䅑児楁䑁䅣杉⭁䑁䅙睌祁䑁䅉睌祁䑁䅁杍㉁䑁䅷睌兂䝁䅅杣桂䝁䄰材㡁䙁䅁兙祂䝁䅅兢杁䝁䅫䅚㥁䍁䅉免㍁䍁䅉材㑁䑁䅣睍㑁䑁䅁免㡁䍁䄸䅕桂䡁䅉兙瑂䑁䄴䅐兂䝁䅅杣桂䝁䄰䅉灂䝁䅑児楁䑁䅅䅏楁䑁䄴䅏㕁䑁䅑睍ㅁ䍁䄴李祁䑁䅕䅍ㅁ䑁䅅䅐癁䙁䅁兙祂䝁䅅兢⭁䅁䅁元䅁䅁䅷䅁啂䙁䅍䅗㙁䙁䅉䅁䭁䅁䅁杺䅅䑁䅷䅕桂䡁䅉兙瑂䍁䅁兡歂䑁䄰杉ㅁ䍁䅉材硁䑁䅷睌兂䝁䅅杣桂䝁䄰材㡁䙁䅁兙祂䝁䅅兢杁䝁䅫䅚㥁䍁䅉免楁䑁䄴兌硁䑁䅧兏祁䑁䅉䅎ぁ䑁䅧䅏穁䑁䅷睌兂䝁䅅杣桂䝁䄰材㡁䙁䅁兙祂䝁䅅兢杁䝁䅫䅚㥁䍁䅉睍楁䑁䄴杍㍁䑁䅷睌兂䝁䅅杣桂䝁䄰材㡁䙁䅁兙祂䝁䅅兢杁䝁䅫䅚㥁䍁䅉杍楁䑁䄴免睁䑁䅁䅍ㅁ䑁䅑䅐癁䙁䅁兙祂䝁䅅兢⭁䑁䅷䅕桂䡁䅉兙瑂䍁䅁兡歂䑁䄰杉ぁ䍁䅉材睁䑁䅷睌兂䝁䅅杣桂䝁䄰材㡁䙁䅁兙祂䝁䅅兢杁䝁䅫䅚㥁䍁䅉睎楁䑁䄴李癁䑁䅉杍癁䑁䅉䅍祁䑁䅙䅐癁䙁䅁兙祂䝁䅅兢⭁䑁䅷䅕桂䡁䅉兙瑂䍁䅁兡歂䑁䄰杉硁䑁䅣杉⭁䑁䅅䅍㉁䑁䅍睍ㅁ䑁䅷睌兂䝁䅅杣桂䝁䄰材㡁䙁䅁兙祂䝁䅅兢杁䝁䅫䅚㥁䍁䅉免㑁䍁䅉材㍁䑁䅫李祁䑁䅙杌硁䑁䅍睍㕁䑁䅑睍㍁䑁䅍李硁䑁䅷睌兂䝁䅅杣桂䝁䄰材䅁䍁䅫䅁䵁䅁䅁䅖呂䙁䅧杏䍂䅁䅁睃䅁䅁䅷䅁啂䙁䅍䅗㙁䙁䅁䅁䵁䅁䅁䅄䅁䙁䅑睕奂䑁䅯兓䅁䅁䄰䅁䝄允䅁䅐兂䝁䅅杣桂䝁䄰䅉灂䝁䅑児楁䑁䅕杉⭁䑁䅅䅐癁䙁䅁兙祂䝁䅅兢⭁䑁䅷䅕桂䡁䅉兙瑂䍁䅁兡歂䑁䄰杉硁䍁䅉材瑁䑁䅅䅏㑁䑁䅫睍ㅁ䑁䅉䅍ㅁ䑁䅣䅐癁䙁䅁兙祂䝁䅅兢⭁䑁䅷䅕桂䡁䅉兙瑂䍁䅁兡歂䑁䄰杉穁䍁䅉材祁䑁䅣䅐癁䙁䅁兙祂䝁䅅兢⭁䑁䅷䅕桂䡁䅉兙瑂䍁䅁兡歂䑁䄰杉祁䍁䅉材硁䑁䅁䅍睁䑁䅙䅍㡁䍁䄸䅕桂䡁䅉兙瑂䑁䄴䅐兂䝁䅅杣桂䝁䄰䅉灂䝁䅑児楁䑁䅑杉⭁䑁䅁䅐癁䙁䅁兙祂䝁䅅兢⭁䑁䅷䅕桂䡁䅉兙瑂䍁䅁兡歂䑁䄰杉㍁䍁䅉材㉁䍁䄸杍祁䍁䄸杍睁䑁䅉李㡁䍁䄸䅕桂䡁䅉兙瑂䑁䄴䅐兂䝁䅅杣桂䝁䄰䅉灂䝁䅑児楁䑁䅅睎楁䑁䄴杍穁䑁䅕免㑁䑁䅅李祁䑁䅷睌兂䝁䅅杣桂䝁䄰材㡁䙁䅁兙祂䝁䅅兢杁䝁䅫䅚㥁䍁䅉免㑁䍁䅉材硁䑁䅉䅏畁䑁䅙䅎ぁ䑁䅙免ㅁ䑁䅷睌兂䝁䅅杣桂䝁䄰材䅁䉁䅫䅁䍁䅁䅁䅁偁䅁䅁杸䅅䑁䅷䅕桂䡁䅉兙瑂䍁䅁兡歂䑁䄰杉ㅁ䍁䅉材硁䑁䅷睌兂䝁䅅杣桂䝁䄰材㡁䙁䅁兙祂䝁䅅兢杁䝁䅫䅚㥁䍁䅉免楁䑁䄴兌硁䑁䅧兏穁䑁䅁兎㉁䑁䅁䅏硁䑁䅷睌兂䝁䅅杣桂䝁䄰材㡁䙁䅁兙祂䝁䅅兢杁䝁䅫䅚㥁䍁䅉睍楁䑁䄴杍㍁䑁䅷睌兂䝁䅅杣桂䝁䄰材㡁䙁䅁兙祂䝁䅅兢杁䝁䅫䅚㥁䍁䅉杍楁䑁䄴免睁䑁䅁䅍ㅁ䑁䅑䅐癁䙁䅁兙祂䝁䅅兢⭁䑁䅷䅕桂䡁䅉兙瑂䍁䅁兡歂䑁䄰杉ぁ䍁䅉材睁䑁䅷睌兂䝁䅅杣桂䝁䄰材㡁䙁䅁兙祂䝁䅅兢杁䝁䅫䅚㥁䍁䅉睎楁䑁䄴李癁䑁䅉杍癁䑁䅉䅍祁䑁䅙䅐癁䙁䅁兙祂䝁䅅兢⭁䑁䅷䅕桂䡁䅉兙瑂䍁䅁兡歂䑁䄰杉硁䑁䅣杉⭁䑁䅉兏㍁䑁䅅睎㕁䑁䅷睌兂䝁䅅杣桂䝁䄰材㡁䙁䅁兙祂䝁䅅兢杁䝁䅫䅚㥁䍁䅉免㑁䍁䅉材ぁ䑁䅑䅎㕁䑁䅉杌ㅁ䑁䅅䅏ㅁ䑁䅫免㡁䍁䄸䅕桂䡁䅉兙瑂䑁䄴䅁允䅁䅁䅄䅁䙁䅑睕奂䑁䅯睒䅁䉁䅅䅁䵁䅁䅁䅖呂䙁䅧杏啂䅁䅁杅䅁䱁䈴䅁㡁䙁䅁兙祂䝁䅅兢杁䝁䅫䅚㥁䍁䅉兎楁䑁䄴免㡁䍁䄸䅕桂䡁䅉兙瑂䑁䄴䅐兂䝁䅅杣桂䝁䄰䅉灂䝁䅑児楁䑁䅅杉⭁䍁䄰免㑁䑁䅫䅍㍁䑁䅧杍㑁䑁䅑䅍㡁䍁䄸䅕桂䡁䅉兙瑂䑁䄴䅐兂䝁䅅杣桂䝁䄰䅉灂䝁䅑児楁䑁䅍杉⭁䑁䅉睎㡁䍁䄸䅕桂䡁䅉兙瑂䑁䄴䅐兂䝁䅅杣桂䝁䄰䅉灂䝁䅑児楁䑁䅉杉⭁䑁䅅䅍睁䑁䅁兎ぁ䑁䅷睌兂䝁䅅杣桂䝁䄰材㡁䙁䅁兙祂䝁䅅兢杁䝁䅫䅚㥁䍁䅉䅎楁䑁䄴䅍㡁䍁䄸䅕桂䡁䅉兙瑂䑁䄴䅐兂䝁䅅杣桂䝁䄰䅉灂䝁䅑児楁䑁䅣杉⭁䑁䅙睌祁䑁䅉睌祁䑁䅁杍㉁䑁䅷睌兂䝁䅅杣桂䝁䄰材㡁䙁䅁兙祂䝁䅅兢杁䝁䅫䅚㥁䍁䅉免㍁䍁䅉材ㅁ䑁䅫䅏㉁䑁䅧兏㡁䍁䄸䅕桂䡁䅉兙瑂䑁䄴䅐兂䝁䅅杣桂䝁䄰䅉灂䝁䅑児楁䑁䅅䅏楁䑁䄴杍ㅁ䑁䅉兏ぁ䍁䄴免㑁䑁䅷睌兂䝁䅅杣桂䝁䄰材䅁䉁䅍䅁佁䅁䅁䅖呂䙁䅧杏卂䙁䅫䅁啁䅁䅁䅹䅅䑁䅷䅕桂䡁䅉兙瑂䍁䅁兡歂䑁䄰杉ㅁ䍁䅉材硁䑁䅷睌兂䝁䅅杣桂䝁䄰材㡁䙁䅁兙祂䝁䅅兢杁䝁䅫䅚㥁䍁䅉免楁䑁䄴兌硁䑁䅧䅏㉁䑁䅉兎㉁䑁䅑李㕁䑁䅷睌兂䝁䅅杣桂䝁䄰材㡁䙁䅁兙祂䝁䅅兢杁䝁䅫䅚㥁䍁䅉睍楁䑁䄴杍㍁䑁䅷睌兂䝁䅅杣桂䝁䄰材㡁䙁䅁兙祂䝁䅅兢杁䝁䅫䅚㥁䍁䅉杍楁䑁䄴免睁䑁䅁䅍ㅁ䑁䅑䅐癁䙁䅁兙祂䝁䅅兢⭁䑁䅷䅕桂䡁䅉兙瑂䍁䅁兡歂䑁䄰杉ぁ䍁䅉材睁䑁䅷睌兂䝁䅅杣桂䝁䄰材㡁䙁䅁兙祂䝁䅅兢杁䝁䅫䅚㥁䍁䅉睎楁䑁䄴李癁䑁䅉杍癁䑁䅉䅍祁䑁䅙䅐癁䙁䅁兙祂䝁䅅兢⭁䑁䅷䅕桂䡁䅉兙瑂䍁䅁兡歂䑁䄰杉硁䑁䅣杉⭁䑁䅅䅍㕁䑁䅧䅍㕁䑁䅷睌兂䝁䅅杣桂䝁䄰材㡁䙁䅁兙祂䝁䅅兢杁䝁䅫䅚㥁䍁䅉免㑁䍁䅉材穁䑁䅫䅏ㅁ䑁䅣睎畁䑁䅅䅍㍁䑁䅫免㉁䑁䅷睌兂䝁䅅杣桂䝁䄰材䅁䉁䅕䅁䵁䅁䅁䅖呂䙁䅧杏偂䅁䅁杆䅁䱁䈴䅁㡁䙁䅁兙祂䝁䅅兢杁䝁䅫䅚㥁䍁䅉兎楁䑁䄴免㡁䍁䄸䅕桂䡁䅉兙瑂䑁䄴䅐兂䝁䅅杣桂䝁䄰䅉灂䝁䅑児楁䑁䅅杉⭁䍁䄰免㑁䑁䅫䅍㍁䑁䅧杍㑁䑁䅑䅍㡁䍁䄸䅕桂䡁䅉兙瑂䑁䄴䅐兂䝁䅅杣桂䝁䄰䅉灂䝁䅑児楁䑁䅍杉⭁䑁䅉睎㡁䍁䄸䅕桂䡁䅉兙瑂䑁䄴䅐兂䝁䅅杣桂䝁䄰䅉灂䝁䅑児楁䑁䅉杉⭁䑁䅅䅍睁䑁䅁李睁䑁䅷睌兂䝁䅅杣桂䝁䄰材㡁䙁䅁兙祂䝁䅅兢杁䝁䅫䅚㥁䍁䅉䅎楁䑁䄴䅍㡁䍁䄸䅕桂䡁䅉兙瑂䑁䄴䅐兂䝁䅅杣桂䝁䄰䅉灂䝁䅑児楁䑁䅣杉⭁䑁䅙睌祁䑁䅉睌祁䑁䅁杍㉁䑁䅷睌兂䝁䅅杣桂䝁䄰材㡁䙁䅁兙祂䝁䅅兢杁䝁䅫䅚㥁䍁䅉免㍁䍁䅉材ㅁ䑁䅫䅏㉁䑁䅧兏㡁䍁䄸䅕桂䡁䅉兙瑂䑁䄴䅐兂䝁䅅杣桂䝁䄰䅉灂䝁䅑児楁䑁䅅䅏楁䑁䄴兎ㅁ䑁䅫免㕁䍁䄴免㑁䑁䅷睌兂䝁䅅杣桂䝁䄰材䅁䉁䅣䅁䵁䅁䅁䅖呂䙁䅧杏䙂䅁䅁䅇䅁䅁䅷䅁啂䙁䅍䅗㙁䕁䄴䅁慁䅁䅁䅄䅁䙁䅑睕奂䑁䅯兔䅁䉁䅷䅁䵁䅁䅁䅖呂䙁䅧杏呂䅁䅁先䅁䵁䉁䅁㡁䙁䅁兙祂䝁䅅兢杁䝁䅫䅚㥁䍁䅉兎楁䑁䄴免㡁䍁䄸䅕桂䡁䅉兙瑂䑁䄴䅐兂䝁䅅杣桂䝁䄰䅉灂䝁䅑児楁䑁䅅杉⭁䍁䄰免㕁䑁䅁睎穁䑁䅅䅏硁䑁䅙杍㡁䍁䄸䅕桂䡁䅉兙瑂䑁䄴䅐兂䝁䅅杣桂䝁䄰䅉灂䝁䅑児楁䑁䅍杉⭁䑁䅉睎㡁䍁䄸䅕桂䡁䅉兙瑂䑁䄴䅐兂䝁䅅杣桂䝁䄰䅉灂䝁䅑児楁䑁䅉杉⭁䑁䅅䅍睁䑁䅁兎ぁ䑁䅷睌兂䝁䅅杣桂䝁䄰材㡁䙁䅁兙祂䝁䅅兢杁䝁䅫䅚㥁䍁䅉䅎楁䑁䄴䅍㡁䍁䄸䅕桂䡁䅉兙瑂䑁䄴䅐兂䝁䅅杣桂䝁䄰䅉灂䝁䅑児楁䑁䅣杉⭁䑁䅕睌硁䑁䅫睌祁䑁䅁杍㉁䑁䅷睌兂䝁䅅杣桂䝁䄰材㡁䙁䅁兙祂䝁䅅兢杁䝁䅫䅚㥁䍁䅉免㍁䍁䅉材㑁䑁䅧䅍穁䑁䅫睍㡁䍁䄸䅕桂䡁䅉兙瑂䑁䄴䅐兂䝁䅅杣桂䝁䄰䅉灂䝁䅑児楁䑁䅅䅏楁䑁䄴䅏ぁ䍁䄴䅎㍁䑁䅙䅍㕁䑁䅅䅐癁䙁䅁兙祂䝁䅅兢⭁䅁䅁杈䅁䵁䉁䅁㡁䙁䅁兙祂䝁䅅兢杁䝁䅫䅚㥁䍁䅉兎楁䑁䄴免㡁䍁䄸䅕桂䡁䅉兙瑂䑁䄴䅐兂䝁䅅杣桂䝁䄰䅉灂䝁䅑児楁䑁䅅杉⭁䍁䄰免㕁䑁䅁睎穁䑁䅅䅏硁䑁䅙杍㡁䍁䄸䅕桂䡁䅉兙瑂䑁䄴䅐兂䝁䅅杣桂䝁䄰䅉灂䝁䅑児楁䑁䅍杉⭁䑁䅉睎㡁䍁䄸䅕桂䡁䅉兙瑂䑁䄴䅐兂䝁䅅杣桂䝁䄰䅉灂䝁䅑児楁䑁䅉杉⭁䑁䅅䅍睁䑁䅁李睁䑁䅷睌兂䝁䅅杣桂䝁䄰材㡁䙁䅁兙祂䝁䅅兢杁䝁䅫䅚㥁䍁䅉䅎楁䑁䄴䅍㡁䍁䄸䅕桂䡁䅉兙瑂䑁䄴䅐兂䝁䅅杣桂䝁䄰䅉灂䝁䅑児楁䑁䅣杉⭁䑁䅕睌硁䑁䅫睌祁䑁䅁杍㉁䑁䅷睌兂䝁䅅杣桂䝁䄰材㡁䙁䅁兙祂䝁䅅兢杁䝁䅫䅚㥁䍁䅉免㍁䍁䅉材㑁䑁䅧䅍穁䑁䅫睍㡁䍁䄸䅕桂䡁䅉兙瑂䑁䄴䅐兂䝁䅅杣桂䝁䄰䅉灂䝁䅑児楁䑁䅅䅏楁䑁䄴杍㑁䑁䅑杌穁䑁䅣李睁䑁䅫䅐癁䙁䅁兙祂䝁䅅兢⭁䅁䅁䅉䅁䅁䅷䅁啂䙁䅍䅗㙁䕁䅧䅁桁䅁䅁䅹䅅䑁䅷䅕桂䡁䅉兙瑂䍁䅁兡歂䑁䄰杉ㅁ䍁䅉材硁䑁䅷睌兂䝁䅅杣桂䝁䄰材㡁䙁䅁兙祂䝁䅅兢杁䝁䅫䅚㥁䍁䅉免楁䑁䄴兌硁䑁䅧䅏㕁䑁䅧䅍睁䑁䅉睎穁䑁䅷睌兂䝁䅅杣桂䝁䄰材㡁䙁䅁兙祂䝁䅅兢杁䝁䅫䅚㥁䍁䅉睍楁䑁䄴杍㍁䑁䅷睌兂䝁䅅杣桂䝁䄰材㡁䙁䅁兙祂䝁䅅兢杁䝁䅫䅚㥁䍁䅉杍楁䑁䄴免睁䑁䅁䅍ㅁ䑁䅑䅐癁䙁䅁兙祂䝁䅅兢⭁䑁䅷䅕桂䡁䅉兙瑂䍁䅁兡歂䑁䄰杉ぁ䍁䅉材睁䑁䅷睌兂䝁䅅杣桂䝁䄰材㡁䙁䅁兙祂䝁䅅兢杁䝁䅫䅚㥁䍁䅉睎楁䑁䄴李癁䑁䅉杍癁䑁䅉䅍祁䑁䅙䅐癁䙁䅁兙祂䝁䅅兢⭁䑁䅷䅕桂䡁䅉兙瑂䍁䅁兡歂䑁䄰杉硁䑁䅣杉⭁䑁䅉䅎睁䑁䅕䅎㑁䑁䅫䅐癁䙁䅁兙祂䝁䅅兢⭁䑁䅷䅕桂䡁䅉兙瑂䍁䅁兡歂䑁䄰杉硁䑁䅧杉⭁䑁䅍睍㕁䑁䅫兎畁䑁䅑睍㕁䑁䅕睍穁䑁䅷睌兂䝁䅅杣桂䝁䄰材䅁䍁䅉䅁䥄允䅁䅐兂䝁䅅杣桂䝁䄰䅉灂䝁䅑児楁䑁䅕杉⭁䑁䅅䅐癁䙁䅁兙祂䝁䅅兢⭁䑁䅷䅕桂䡁䅉兙瑂䍁䅁兡歂䑁䄰杉硁䍁䅉材瑁䑁䅅䅏㑁䑁䅫䅏睁䑁䅁杍㍁䑁䅍䅐癁䙁䅁兙祂䝁䅅兢⭁䑁䅷䅕桂䡁䅉兙瑂䍁䅁兡歂䑁䄰杉穁䍁䅉材祁䑁䅣䅐癁䙁䅁兙祂䝁䅅兢⭁䑁䅷䅕桂䡁䅉兙瑂䍁䅁兡歂䑁䄰杉祁䍁䅉材硁䑁䅁䅍睁䑁䅙䅍㡁䍁䄸䅕桂䡁䅉兙瑂䑁䄴䅐兂䝁䅅杣桂䝁䄰䅉灂䝁䅑児楁䑁䅑杉⭁䑁䅁䅐癁䙁䅁兙祂䝁䅅兢⭁䑁䅷䅕桂䡁䅉兙瑂䍁䅁兡歂䑁䄰杉㍁䍁䅉材㉁䍁䄸杍祁䍁䄸杍睁䑁䅉李㡁䍁䄸䅕桂䡁䅉兙瑂䑁䄴䅐兂䝁䅅杣桂䝁䄰䅉灂䝁䅑児楁䑁䅅睎楁䑁䄴杍ぁ䑁䅁兎ぁ䑁䅧兏㡁䍁䄸䅕桂䡁䅉兙瑂䑁䄴䅐兂䝁䅅杣桂䝁䄰䅉灂䝁䅑児楁䑁䅅䅏楁䑁䄴兎穁䑁䅉䅎睁䍁䄴䅎穁䑁䅫兎穁䑁䅍䅐癁䙁䅁兙祂䝁䅅兢⭁䅁䅁睉䅁䵁䉙䅁㡁䙁䅁兙祂䝁䅅兢杁䝁䅫䅚㥁䍁䅉兎楁䑁䄴免㡁䍁䄸䅕桂䡁䅉兙瑂䑁䄴䅐兂䝁䅅杣桂䝁䄰䅉灂䝁䅑児楁䑁䅅杉⭁䍁䄰免㑁䑁䅧兏穁䑁䅕杍睁䑁䅕睎㡁䍁䄸䅕桂䡁䅉兙瑂䑁䄴䅐兂䝁䅅杣桂䝁䄰䅉灂䝁䅑児楁䑁䅍杉⭁䑁䅉睎㡁䍁䄸䅕桂䡁䅉兙瑂䑁䄴䅐兂䝁䅅杣桂䝁䄰䅉灂䝁䅑児楁䑁䅉杉⭁䑁䅅䅍睁䑁䅁兎ぁ䑁䅷睌兂䝁䅅杣桂䝁䄰材㡁䙁䅁兙祂䝁䅅兢杁䝁䅫䅚㥁䍁䅉䅎楁䑁䄴䅍㡁䍁䄸䅕桂䡁䅉兙瑂䑁䄴䅐兂䝁䅅杣桂䝁䄰䅉灂䝁䅑児楁䑁䅣杉⭁䑁䅙睌祁䑁䅉睌祁䑁䅁杍㉁䑁䅷睌兂䝁䅅杣桂䝁䄰材㡁䙁䅁兙祂䝁䅅兢杁䝁䅫䅚㥁䍁䅉免㍁䍁䅉材祁䑁䅍兎硁䑁䅧免㉁䑁䅉䅐癁䙁䅁兙祂䝁䅅兢⭁䑁䅷䅕桂䡁䅉兙瑂䍁䅁兡歂䑁䄰杉硁䑁䅧杉⭁䑁䅅免ぁ䍁䄴兎睁䑁䅧睎ぁ䑁䅕䅐癁䙁䅁兙祂䝁䅅兢⭁䅁䅁䅊䅁䅁䅷䅁啂䙁䅍䅗㙁䙁䅅䅁汁䅁䅁䅄䅁䙁䅑睕奂䑁䅯杒䅁䍁䅙䅁佄允䅁䅐兂䝁䅅杣桂䝁䄰䅉灂䝁䅑児楁䑁䅕杉⭁䑁䅅䅐癁䙁䅁兙祂䝁䅅兢⭁䑁䅷䅕桂䡁䅉兙瑂䍁䅁兡歂䑁䄰杉硁䍁䅉材瑁䑁䅅䅏㕁䑁䅉杍ぁ䑁䅑䅏㑁䑁䅍䅐癁䙁䅁兙祂䝁䅅兢⭁䑁䅷䅕桂䡁䅉兙瑂䍁䅁兡歂䑁䄰杉穁䍁䅉材祁䑁䅣䅐癁䙁䅁兙祂䝁䅅兢⭁䑁䅷䅕桂䡁䅉兙瑂䍁䅁兡歂䑁䄰杉祁䍁䅉材硁䑁䅁䅍睁䑁䅙䅍㡁䍁䄸䅕桂䡁䅉兙瑂䑁䄴䅐兂䝁䅅杣桂䝁䄰䅉灂䝁䅑児楁䑁䅑杉⭁䑁䅁䅐癁䙁䅁兙祂䝁䅅兢⭁䑁䅷䅕桂䡁䅉兙瑂䍁䅁兡歂䑁䄰杉㍁䍁䅉材㉁䍁䄸杍祁䍁䄸杍睁䑁䅉李㡁䍁䄸䅕桂䡁䅉兙瑂䑁䄴䅐兂䝁䅅杣桂䝁䄰䅉灂䝁䅑児楁䑁䅅睎楁䑁䄴免睁䑁䅙睍穁䑁䅕䅐癁䙁䅁兙祂䝁䅅兢⭁䑁䅷䅕桂䡁䅉兙瑂䍁䅁兡歂䑁䄰杉硁䑁䅧杉⭁䑁䅉睎ぁ䑁䅣睍睁䍁䄴杍祁䑁䅣䅎穁䑁䅍睎穁䑁䅙䅐癁䙁䅁兙祂䝁䅅兢⭁䅁䅁睊䅁䅁䅷䅁啂䙁䅍䅗㙁䕁䅑䅁潁䅁䅁䅁䅁䅁㴽

Sheet Instructions
A1: Executive Compensation Benchmarking Methodology
A3: Effective Date | B3: 44992 | D3: Remember: | E3: • NEO order
A4: Last Revised | B4: 44992 | E4: • Currency
E5: • Incumbents serving for partial years
E6: • Date of fiscal year end
B9: Purpose
B10: Establish guidelines for executive compensation benchmarking in order to maintain consistency across client projects and teams, improve ease of training, and increase the efficiency of the benchmarking exercise
B12: Policy
B13: Roles
B14: · Record each person’s entire name and role as disclosed in the proxy
B15: o Ignore “director” roles (i.e. assume that the CEO is on the Board of directors)
B16: · Capture Executive Chairman role if it is one of the top 5 NEOs, but do not use as a comparison to any of the NEOs, unless indicated by client team
B17: o Footnote and confirm with client team
B19: Base Salary
B20: · Record the base salary in the Summary Compensation Table
B21: · If the incumbent has partial years of service, annualize the base salary
B22: · If the upcoming year’s salary is disclosed, record it in column O; it will be used in lieu of data aging
... B132: · Assume that the peer reviewer has made all of the necessary changes to the raw data sheet

Sheet Import 2024 Data
B3: x | C3: Lookup | D3: Role match | E3: Company | F3: Title | G3: Incumbent | H3: Actual TDC | I3: Target TDC
C4: TSX:HBM_2024_CEO | D4: CEO | E4: Hudbay Minerals Inc. | F4: President & CEO | G4: Peter Kukielski | H4: 5600057 | I4: 5457572.2
C5: TSX:HBM_2024_COO | D5: COO | E5: Hudbay Minerals Inc. | F5: COO | G5: Andre Lauzon | H5: 2604993 | I5: 2503127
C6: TSX:HBM_2024_CFO | D6: CFO | E6: Hudbay Minerals Inc. | F6: CFO | G6: Eugene Lei | H6: 2350784 | I6: 2300974.6
C7: TSX:HBM_2024_Legal | D7: Legal | E7: Hudbay Minerals Inc. | F7: SVP, Legal and Organizational Effectiveness | G7: Patrick Donnelly | H7: 1919023 | I7: 1837927.8
C8: TSX:HBM_2024_Region2 | D8: Region2 | E8: Hudbay Minerals Inc. | F8: SVP, US Business Unit | G8: Javier Del Rio | H8: 2212298.2 | I8: 1818959.7
C9: TSX:HBM_2024_Tech | D9: Tech | E9: Hudbay Minerals Inc. | F9: SVP, Exploration and Technical Services | G9: Olivier Tavchandjian | H9: 465850 | I9: 1304380
C10: TSX:HBM_2024_Region | D10: Region | E10: Hudbay Minerals Inc. | F10: SVP, Canada | G10: Rob Carter | H10: 453500 | I10: 1269800
C14: TSX:K_2024_CEO | D14: CEO | E14: Kinross Gold Corporation | F14: CEO | G14: J. Paul Rollinson | H14: 9344.8458 | I14: 8698.6526
C15: TSX:LUN_2024_CEO | D15: CEO | E15: Lundin Mining Corporation | F15: President & CEO | G15: Jack Lundin | H15: 5366.5489 | I15: 4420
C16: TSX:AGI_2024_CEO | D16: CEO | E16: Alamos Gold Inc. | F16: CEO | G16: John A. McCluskey | H16: 6013.0529 | I16: 5375
C17: TSX:PAAS_2024_CEO | D17: CEO | E17: Pan American Silver Corp. | F17: CEO | G17: Michael Steinmann | H17: 7737.93 | I17: 7690.8
C18: TSX:CS_2024_CEO | D18: CEO | E18: Capstone Copper Corp. | F18: CEO | G18: John MacKenzie | H18: 4278.72 | I18: 4416
... C61: TSX:CG_2024_COO | D61: COO | E61: Centerra Gold Inc. | F61: EVP, COO | G61: Paul Chawrun | H61: 1944.8 | I61: 1980

Sheet Raw Data
D2: INPUTS
AP3: Check with client team 1) whether this benchmarking is necessary and 2) how to treat pension & other in the output tables (i.e., actual, 3-year average)
D4: Peer Ticker(s) | G4: Date | H4: 45852
D5: 1 | E5: TSX:K | G5: Currency | H5: CAD
D6: 2 | E6: TSX:LUN | G6: Client Ticker | H6: TSX:HBM
D7: 3 | E7: TSX:PAAS
D8: 4 | E8: TSX:BTO | G8: CAD/USD
D9: 5 | E9: TSX:IMG | G9: 2025 | H9: =_xll.ciqfunctions.udf.CIQAVG("$CADUSD", "IQ_LASTSALEPRICE", "1/1/"&$G9, "31/12/"&$G9) -> 1.39745
D10: 6 | E10: TSX:CS | G10: =G9-1 -> 2024 | H10: =_xll.ciqfunctions.udf.CIQAVG("$CADUSD", "IQ_LASTSALEPRICE", "1/1/"&$G10, "31/12/"&$G10) -> 1.37017
D11: 7 | E11: TSX:SSRM | G11: =G10-1 -> 2023 | H11: =_xll.ciqfunctions.udf.CIQAVG("$CADUSD", "IQ_LASTSALEPRICE", "1/1/"&$G11, "31/12/"&$G11) -> 1.34954
D12: 8 | E12: TSX:OGC
D13: 9 | E13: TSX:ELD | G13: Data Aging: | H13: 0.03
D14: 10 | E14: TSX:AGI
D15: 11 | E15: NYSE:HL
D16: 12 | E16: TSX:CG
D17: 13 | E17: TSX:FM
D18: 14 | E18: TSX:CDE
D19: 15 | E19: TSX:EQX
D20: 16
D21: 17
D22: 18
D23: 19
D24: 20
D25: 21
D26: 22
D27: 23
D28: 24
Q30: Base Salary | U30: STIP | AA30: Total Cash Compensation | AC30: Long-Term Incentives | AN30: Total Direct Compensation | AP30: Pension & Other | AW30: Total Compensation
A31: Look-Up2 | B31: Look-Up | C31: Look-Up3 | D31: Ticker | E31: Company | F31: Year | G31: Incumbent Start Month | H31: End Month (Typically FYE) | I31: Months | J31: Currency of Disclosure | K31: FX Rate | L31: Role Match | M31: Role Match 2 | N31: Position Match | O31: Position Title | P31: Incumbent | Q31: Actual Paid | R31: Annualized / Converted | S31: Latest (if disclosed) | T31: Latest (if disclosed) - Annualized / Converted | U31: Actual $ | V31: Annualized/ Converted | W31: Actual STI % | X31: 3 Year Average STIP % | Y31: Target STI % | Z31: Target STI $ | AA31: Actual TCC | AB31: Target TCC | AC31: RSUs | AD31: PSUs | AE31: Stock Options | AF31: DSUs | AG31: LT Cash | AH31: Total LTI $ | AI31: Total LTI % | AJ31: 3 Year Average LTIP % | AK31: Target LTI % | AL31: Target LTI $ | AM31: Total LTI (Converted) | AN31: Actual (base + actual bonus + actual LTIP) | AO31: Target (base + target bonus + Target LTIP) | AP31: Pension | AQ31: DB or DC Pension? | AR31: Pension Converted | AS31: Pension 3 Year Average | AT31: Other | AU31: Other Converted | AV31: Other 3 Year Average | AW31: Actual (Actual TDC + Pension + Other) | AX31: Target (Target TDC + Pension + Other) | AY31: Incumbent Specific Notes: | AZ31: Data Recorder | BA31: Peer Reviewer | BB31: Flags
A32: =$D32&"_"&$F32&"_"&$L32 -> TSX:HBM_2025_ | B32: =$D32&"_"&$F32&"_"&$N32 -> TSX:HBM_2025_CEO | C32: =$D32&"_"&$F32&"_"&$M32 -> TSX:HBM_2025_ | D32: =H6 -> TSX:HBM | E32: =_xll.ciqfunctions.udf.CIQ(D32,"IQ_Company_Name") -> Hudbay Minerals Inc. | F32: 2025 | G32: =F32&"-01-01" -> 2025-01-01 | H32: =F32&"-12-31" -> 2025-12-31 | I32: =_xlfn.DAYS(H32,G32)/_xlfn.DAYS(F32&"-12-31",F32&"-01-01")*12 -> 12 | J32: CAD | K32: =IF($J32="CAD",1,IF($J32="USD",VLOOKUP($F32,$G$9:$H$11,2,FALSE),"N/A")) -> 1 | N32: CEO | O32: President & CEO | P32: Peter Kukielski | Q32: 1047525 | R32: 1099901 | S32: 1099901 | T32: =IFERROR(IF((S32*$K32)=0,"-",(S32*$K32)),"-") -> 1099901 | U32: 1615284 | V32: =IFERROR(U32*(12/$I32)*$K32,"-") -> 1615284 | W32: =IFERROR($V32/$R32,"-") -> 1.4685722 | X32: =IFERROR(AVERAGE(W32:W34),"N/A") -> 1.5031237 | Y32: 1.2 | Z32: =IFERROR(IF(ISNUMBER($Y32)=TRUE, $Y32*$R32,$X32*$R32),"-") -> 1319881.2 | AA32: =IFERROR(IF(SUM(R32,V32)=0,"-",SUM(R32,V32)),"-") -> 2715185 | AB32: =IFERROR(IF(SUM(R32,Z32)=0,"-",SUM(R32,Z32)),"-") -> 2419782.2 | AC32: =1/3*2081956 -> 693985.33 | AD32: =2/3*2081956 -> 1387970.7 | AE32: 693985 | AF32: - | AG32: - | AH32: =IFERROR(IF(SUM(AC32:AG32)=0,IF(COUNTIF($AA32:$AE32,"=0")>0,"$0","-"),SUM(AC32:AG32)),"-") -> 2775941 | AI32: =IFERROR($AK32/$P32,"-") -> - | AJ32: =IFERROR(AVERAGE(AI32:AI34),"N/A") -> N/A | AK32: 2.65 | AL32: =IFERROR(IF(ISNUMBER($AK32)=TRUE, $AK32*$R32, $AJ32*$R32), "-") -> 2914737.6 | AM32: =IFERROR($AH32*$K32,"-") -> 2775941 | AN32: =IFERROR(IF(SUM(AA32,AM32)=0,"-",SUM(AA32,AM32)),"-") -> 5491126 | AO32: =IFERROR(IF(SUM($AB32,$AL32)=0,"-",SUM($AB32,$AL32)),"-") -> 5334519.8 | AP32: 91893 | AQ32: DC | AR32: =IFERROR(AP32*(12/$I32)*$K32,"-") -> 91893 | AS32: =IFERROR(AVERAGE(AR32:AR34),"N/A") -> 110427.67 | AT32: 204272 | AU32: =IFERROR(AT32*(12/$H32)*$J32,"-") -> - | AV32: =IFERROR(AVERAGE(AU32:AU34),"N/A") -> N/A | AW32: =IFERROR(IF(SUM(AN32,AR32,AU32)=0,"-",SUM(AN32,AR32,AU32)),"-") -> 5583019 | AX32: =IFERROR(IF(SUM(AO32,AR32,AU32)=0,"-",SUM(AO32,AR32,AU32)),"-") -> 5426412.8 | AY32: - | AZ32: KP | BA32: sc
A33: =$D33&"_"&$F33&"_"&$L33 -> TSX:HBM_2024_ | B33: =$D33&"_"&$F33&"_"&$N33 -> TSX:HBM_2024_CEO | C33: =$D33&"_"&$F33&"_"&$M33 -> TSX:HBM_2024_ | D33: =D32 -> TSX:HBM | E33: =_xll.ciqfunctions.udf.CIQ(D33,"IQ_Company_Name") -> Hudbay Minerals Inc. | F33: 2024 | G33: =F33&"-01-01" -> 2024-01-01 | H33: =F33&"-12-31" -> 2024-12-31 | I33: =_xlfn.DAYS(H33,G33)/_xlfn.DAYS(F33&"-12-31",F33&"-01-01")*12 -> 12 | J33: CAD | K33: =IF($J33="CAD",1,IF($J33="USD",VLOOKUP($F33,$G$9:$H$11,2,FALSE),"N/A")) -> 1 | N33: =N32 -> CEO | O33: =O32 -> President & CEO | P33: =P32 -> Peter Kukielski | Q33: 1017015 | R33: =IFERROR(Q33*(12/$I33)*$K33,"-") -> 1017015 | S33: - | T33: =IFERROR(IF((S33*$K33)=0,"-",(S33*$K33)),"-") -> - | U33: 1632919 | V33: =IFERROR(U33*(12/$I33)*$K33,"-") -> 1632919 | W33: =IFERROR($V33/$R33,"-") -> 1.6055997 | Y33: - | Z33: =IFERROR(IF(ISNUMBER($Y33)=TRUE, $Y33*$R33,$X33*$R33),"-") -> 0 | AA33: =IFERROR(IF(SUM(R33,V33)=0,"-",SUM(R33,V33)),"-") -> 2649934 | AB33: =IFERROR(IF(SUM(R33,Z33)=0,"-",SUM(R33,Z33)),"-") -> 1017015 | AC33: =1/3*1906903 -> 635634.33 | AD33: =2/3*1906903 -> 1271268.7 | AE33: 635634 | AF33: - | AG33: - | AH33: =IFERROR(IF(SUM(AC33:AG33)=0,IF(COUNTIF($AA33:$AE33,"=0")>0,"$0","-"),SUM(AC33:AG33)),"-") -> 2542537 | AI33: =IFERROR($AK33/$P33,"-") -> - | AK33: - | AL33: =IFERROR(IF(ISNUMBER($AK33)=TRUE, $AK33*$R33, $AJ33*$R33), "-") -> 0 | AM33: =IFERROR($AH33*$K33,"-") -> 2542537 | AN33: =IFERROR(IF(SUM(AA33,AM33)=0,"-",SUM(AA33,AM33)),"-") -> 5192471 | AO33: =IFERROR(IF(SUM($AB33,$AL33)=0,"-",SUM($AB33,$AL33)),"-") -> 1017015 | AP33: 122042 | AQ33: DC | AR33: =IFERROR(AP33*(12/$I33)*$K33,"-") -> 122042 | AT33: 255034 | AU33: =IFERROR(AT33*(12/$H33)*$J33,"-") -> - | AW33: =IFERROR(IF(SUM(AN33,AR33,AU33)=0,"-",SUM(AN33,AR33,AU33)),"-") -> 5314513 | AX33: =IFERROR(IF(SUM(AO33,AR33,AU33)=0,"-",SUM(AO33,AR33,AU33)),"-") -> 1139057 | AY33: - | AZ33: KP | BA33: sc
A34: =$D34&"_"&$F34&"_"&$L34 -> TSX:HBM_2023_ | B34: =$D34&"_"&$F34&"_"&$N34 -> TSX:HBM_2023_CEO | C34: =$D34&"_"&$F34&"_"&$M34 -> TSX:HBM_2023_ | D34: =D33 -> TSX:HBM | E34: =_xll.ciqfunctions.udf.CIQ(D34,"IQ_Company_Name") -> Hudbay Minerals Inc. | F34: 2023 | G34: =F34&"-01-01" -> 2023-01-01 | H34: =F34&"-12-31" -> 2023-12-31 | I34: =_xlfn.DAYS(H34,G34)/_xlfn.DAYS(F34&"-12-31",F34&"-01-01")*12 -> 12 | J34: CAD | K34: =IF($J34="CAD",1,IF($J34="USD",VLOOKUP($F34,$G$9:$H$11,2,FALSE),"N/A")) -> 1 | N34: =N33 -> CEO | O34: =O33 -> President & CEO | P34: =P33 -> Peter Kukielski | Q34: 977899 | R34: =IFERROR(Q34*(12/$I34)*$K34,"-") -> 977899 | S34: - | T34: =IFERROR(IF((S34*$K34)=0,"-",(S34*$K34)),"-") -> - | U34: 1403480 | V34: =IFERROR(U34*(12/$I34)*$K34,"-") -> 1403480 | W34: =IFERROR($V34/$R34,"-") -> 1.4351993 | Y34: - | Z34: =IFERROR(IF(ISNUMBER($Y34)=TRUE, $Y34*$R34,$X34*$R34),"-") -> 0 | AA34: =IFERROR(IF(SUM(R34,V34)=0,"-",SUM(R34,V34)),"-") -> 2381379 | AB34: =IFERROR(IF(SUM(R34,Z34)=0,"-",SUM(R34,Z34)),"-") -> 977899 | AC34: =1/3*1833560 -> 611186.67 | AD34: =2/3*1833560 -> 1222373.3 | AE34: 611187 | AF34: - | AG34: - | AH34: =IFERROR(IF(SUM(AC34:AG34)=0,IF(COUNTIF($AA34:$AE34,"=0")>0,"$0","-"),SUM(AC34:AG34)),"-") -> 2444747 | AI34: =IFERROR($AK34/$P34,"-") -> - | AK34: - | AL34: =IFERROR(IF(ISNUMBER($AK34)=TRUE, $AK34*$R34, $AJ34*$R34), "-") -> 0 | AM34: =IFERROR($AH34*$K34,"-") -> 2444747 | AN34: =IFERROR(IF(SUM(AA34,AM34)=0,"-",SUM(AA34,AM34)),"-") -> 4826126 | AO34: =IFERROR(IF(SUM($AB34,$AL34)=0,"-",SUM($AB34,$AL34)),"-") -> 977899 | AP34: 117348 | AQ34: DC | AR34: =IFERROR(AP34*(12/$I34)*$K34,"-") -> 117348 | AT34: 275237 | AU34: =IFERROR(AT34*(12/$H34)*$J34,"-") -> - | AW34: =IFERROR(IF(SUM(AN34,AR34,AU34)=0,"-",SUM(AN34,AR34,AU34)),"-") -> 4943474 | AX34: =IFERROR(IF(SUM(AO34,AR34,AU34)=0,"-",SUM(AO34,AR34,AU34)),"-") -> 1095247 | AY34: - | AZ34: KP | BA34: sc
A35: =$D35&"_"&$F35&"_"&$L35 -> TSX:HBM_2025_COO | B35: =$D35&"_"&$F35&"_"&$N35 -> TSX:HBM_2025_NEO1 | C35: =$D35&"_"&$F35&"_"&$M35 -> TSX:HBM_2025_2nd Highest | D35: =D34 -> TSX:HBM | E35: =_xll.ciqfunctions.udf.CIQ(D35,"IQ_Company_Name") -> Hudbay Minerals Inc. | F35: =F32 -> 2025 | G35: =F35&"-01-01" -> 2025-01-01 | H35: =F35&"-12-31" -> 2025-12-31 | I35: =_xlfn.DAYS(H35,G35)/_xlfn.DAYS(F35&"-12-31",F35&"-01-01")*12 -> 12 | J35: CAD | K35: =IF($J35="CAD",1,IF($J35="USD",VLOOKUP($F35,$G$9:$H$11,2,FALSE),"N/A")) -> 1 | L35: COO | M35: 2nd Highest | N35: NEO1 | O35: COO | P35: Andre Lauzon | Q35: 651000 | R35: 696570 | S35: 696570 | T35: =IFERROR(IF((S35*$K35)=0,"-",(S35*$K35)),"-") -> 696570 | U35: 749952 | V35: =IFERROR(U35*(12/$I35)*$K35,"-") -> 749952 | W35: =IFERROR($V35/$R35,"-") -> 1.0766355 | X35: =IFERROR(AVERAGE(W35:W37),"N/A") -> 1.1211787 | Y35: 0.9 | Z35: =IFERROR(IF(ISNUMBER($Y35)=TRUE, $Y35*$R35,$X35*$R35),"-") -> 626913 | AA35: =IFERROR(IF(SUM(R35,V35)=0,"-",SUM(R35,V35)),"-") -> 1446522 | AB35: =IFERROR(IF(SUM(R35,Z35)=0,"-",SUM(R35,Z35)),"-") -> 1323483 | AC35: =1/3*830025 -> 276675 | AD35: =2/3*830025 -> 553350 | AE35: 276675 | AF35: - | AG35: - | AH35: =IFERROR(IF(SUM(AC35:AG35)=0,IF(COUNTIF($AA35:$AE35,"=0")>0,"$0","-"),SUM(AC35:AG35)),"-") -> 1106700 | AI35: =IFERROR($AK35/$P35,"-") -> - | AJ35: =IFERROR(AVERAGE(AI35:AI37),"N/A") -> N/A | AK35: 1.8 | AL35: =IFERROR(IF(ISNUMBER($AK35)=TRUE, $AK35*$R35, $AJ35*$R35), "-") -> 1253826 | AM35: =IFERROR($AH35*$K35,"-") -> 1106700 | AN35: =IFERROR(IF(SUM(AA35,AM35)=0,"-",SUM(AA35,AM35)),"-") -> 2553222 | AO35: =IFERROR(IF(SUM($AB35,$AL35)=0,"-",SUM($AB35,$AL35)),"-") -> 2577309 | AP35: 44310 | AQ35: DC | AR35: =IFERROR(AP35*(12/$I35)*$K35,"-") -> 44310 | AS35: =IFERROR(AVERAGE(AR35:AR37),"N/A") -> 61826 | AT35: 97046 | AU35: =IFERROR(AT35*(12/$H35)*$J35,"-") -> - | AV35: =IFERROR(AVERAGE(AU35:AU37),"N/A") -> N/A | AW35: =IFERROR(IF(SUM(AN35,AR35,AU35)=0,"-",SUM(AN35,AR35,AU35)),"-") -> 2597532 | AX35: =IFERROR(IF(SUM(AO35,AR35,AU35)=0,"-",SUM(AO35,AR35,AU35)),"-") -> 2621619 | AY35: - | AZ35: KP | BA35: sc
A36: =$D36&"_"&$F36&"_"&$L36 -> TSX:HBM_2024_COO | B36: =$D36&"_"&$F36&"_"&$N36 -> TSX:HBM_2024_NEO1 | C36: =$D36&"_"&$F36&"_"&$M36 -> TSX:HBM_2024_ | D36: =D35 -> TSX:HBM | E36: =_xll.ciqfunctions.udf.CIQ(D36,"IQ_Company_Name") -> Hudbay Minerals Inc. | F36: =F33 -> 2024 | G36: =F36&"-01-01" -> 2024-01-01 | H36: =F36&"-12-31" -> 2024-12-31 | I36: =_xlfn.DAYS(H36,G36)/_xlfn.DAYS(F36&"-12-31",F36&"-01-01")*12 -> 12 | J36: CAD | K36: =IF($J36="CAD",1,IF($J36="USD",VLOOKUP($F36,$G$9:$H$11,2,FALSE),"N/A")) -> 1 | L36: COO | N36: =N35 -> NEO1 | O36: =O35 -> COO | P36: =P35 -> Andre Lauzon | Q36: 620000 | R36: =IFERROR(Q36*(12/$I36)*$K36,"-") -> 620000 | S36: - | T36: =IFERROR(IF((S36*$K36)=0,"-",(S36*$K36)),"-") -> - | U36: 740466 | V36: =IFERROR(U36*(12/$I36)*$K36,"-") -> 740466 | W36: =IFERROR($V36/$R36,"-") -> 1.1943 | Y36: - | Z36: =IFERROR(IF(ISNUMBER($Y36)=TRUE, $Y36*$R36,$X36*$R36),"-") -> 0 | AA36: =IFERROR(IF(SUM(R36,V36)=0,"-",SUM(R36,V36)),"-") -> 1360466 | AB36: =IFERROR(IF(SUM(R36,Z36)=0,"-",SUM(R36,Z36)),"-") -> 620000 | AC36: =1/3*790500 -> 263500 | AD36: =2/3*790500 -> 527000 | AE36: 263500 | AF36: - | AG36: - | AH36: =IFERROR(IF(SUM(AC36:AG36)=0,IF(COUNTIF($AA36:$AE36,"=0")>0,"$0","-"),SUM(AC36:AG36)),"-") -> 1054000 | AI36: =IFERROR($AK36/$P36,"-") -> - | AK36: - | AL36: =IFERROR(IF(ISNUMBER($AK36)=TRUE, $AK36*$R36, $AJ36*$R36), "-") -> 0 | AM36: =IFERROR($AH36*$K36,"-") -> 1054000 | AN36: =IFERROR(IF(SUM(AA36,AM36)=0,"-",SUM(AA36,AM36)),"-") -> 2414466 | AO36: =IFERROR(IF(SUM($AB36,$AL36)=0,"-",SUM($AB36,$AL36)),"-") -> 620000 | AP36: 74400 | AQ36: DC | AR36: =IFERROR(AP36*(12/$I36)*$K36,"-") -> 74400 | AT36: 85127 | AU36: =IFERROR(AT36*(12/$H36)*$J36,"-") -> - | AW36: =IFERROR(IF(SUM(AN36,AR36,AU36)=0,"-",SUM(AN36,AR36,AU36)),"-") -> 2488866 | AX36: =IFERROR(IF(SUM(AO36,AR36,AU36)=0,"-",SUM(AO36,AR36,AU36)),"-") -> 694400 | AY36: - | AZ36: KP | BA36: sc
A37: =$D37&"_"&$F37&"_"&$L37 -> TSX:HBM_2023_COO | B37: =$D37&"_"&$F37&"_"&$N37 -> TSX:HBM_2023_NEO1 | C37: =$D37&"_"&$F37&"_"&$M37 -> TSX:HBM_2023_ | D37: =D36 -> TSX:HBM | E37: =_xll.ciqfunctions.udf.CIQ(D37,"IQ_Company_Name") -> Hudbay Minerals Inc. | F37: =F34 -> 2023 | G37: =F37&"-01-01" -> 2023-01-01 | H37: =F37&"-12-31" -> 2023-12-31 | I37: =_xlfn.DAYS(H37,G37)/_xlfn.DAYS(F37&"-12-31",F37&"-01-01")*12 -> 12 | J37: CAD | K37: =IF($J37="CAD",1,IF($J37="USD",VLOOKUP($F37,$G$9:$H$11,2,FALSE),"N/A")) -> 1 | L37: COO | N37: =N36 -> NEO1 | O37: =O36 -> COO | P37: =P36 -> Andre Lauzon | Q37: 556400 | R37: =IFERROR(Q37*(12/$I37)*$K37,"-") -> 556400 | S37: - | T37: =IFERROR(IF((S37*$K37)=0,"-",(S37*$K37)),"-") -> - | U37: 607923 | V37: =IFERROR(U37*(12/$I37)*$K37,"-") -> 607923 | W37: =IFERROR($V37/$R37,"-") -> 1.0926006 | Y37: - | Z37: =IFERROR(IF(ISNUMBER($Y37)=TRUE, $Y37*$R37,$X37*$R37),"-") -> 0 | AA37: =IFERROR(IF(SUM(R37,V37)=0,"-",SUM(R37,V37)),"-") -> 1164323 | AB37: =IFERROR(IF(SUM(R37,Z37)=0,"-",SUM(R37,Z37)),"-") -> 556400 | AC37: =1/3*709410 -> 236470 | AD37: =2/3*709410 -> 472940 | AE37: 236470 | AF37: - | AG37: - | AH37: =IFERROR(IF(SUM(AC37:AG37)=0,IF(COUNTIF($AA37:$AE37,"=0")>0,"$0","-"),SUM(AC37:AG37)),"-") -> 945880 | AI37: =IFERROR($AK37/$P37,"-") -> - | AK37: - | AL37: =IFERROR(IF(ISNUMBER($AK37)=TRUE, $AK37*$R37, $AJ37*$R37), "-") -> 0 | AM37: =IFERROR($AH37*$K37,"-") -> 945880 | AN37: =IFERROR(IF(SUM(AA37,AM37)=0,"-",SUM(AA37,AM37)),"-") -> 2110203 | AO37: =IFERROR(IF(SUM($AB37,$AL37)=0,"-",SUM($AB37,$AL37)),"-") -> 556400 | AP37: 66768 | AQ37: DC | AR37: =IFERROR(AP37*(12/$I37)*$K37,"-") -> 66768 | AT37: 179092 | AU37: =IFERROR(AT37*(12/$H37)*$J37,"-") -> - | AW37: =IFERROR(IF(SUM(AN37,AR37,AU37)=0,"-",SUM(AN37,AR37,AU37)),"-") -> 2176971 | AX37: =IFERROR(IF(SUM(AO37,AR37,AU37)=0,"-",SUM(AO37,AR37,AU37)),"-") -> 623168 | AY37: - | AZ37: KP | BA37: sc
A38: =$D38&"_"&$F38&"_"&$L38 -> TSX:HBM_2025_ | B38: =$D38&"_"&$F38&"_"&$N38 -> TSX:HBM_2025_CFO | C38: =$D38&"_"&$F38&"_"&$M38 -> TSX:HBM_2025_ | D38: =D37 -> TSX:HBM | E38: =_xll.ciqfunctions.udf.CIQ(D38,"IQ_Company_Name") -> Hudbay Minerals Inc. | F38: =F35 -> 2025 | G38: =F38&"-01-01" -> 2025-01-01 | H38: =F38&"-12-31" -> 2025-12-31 | I38: =_xlfn.DAYS(H38,G38)/_xlfn.DAYS(F38&"-12-31",F38&"-01-01")*12 -> 12 | J38: CAD | K38: =IF($J38="CAD",1,IF($J38="USD",VLOOKUP($F38,$G$9:$H$11,2,FALSE),"N/A")) -> 1 | N38: CFO | O38: CFO | P38: Eugene Lei | Q38: 573681 | R38: 625312 | S38: 625312 | T38: =IFERROR(IF((S38*$K38)=0,"-",(S38*$K38)),"-") -> 625312 | U38: 664494 | V38: =IFERROR(U38*(12/$I38)*$K38,"-") -> 664494 | W38: =IFERROR($V38/$R38,"-") -> 1.0626599 | X38: =IFERROR(AVERAGE(W38:W40),"N/A") -> 1.1210197 | Y38: 0.9 | Z38: =IFERROR(IF(ISNUMBER($Y38)=TRUE, $Y38*$R38,$X38*$R38),"-") -> 562780.8 | AA38: =IFERROR(IF(SUM(R38,V38)=0,"-",SUM(R38,V38)),"-") -> 1289806 | AB38: =IFERROR(IF(SUM(R38,Z38)=0,"-",SUM(R38,Z38)),"-") -> 1188092.8 | AC38: =1/3*731443 -> 243814.33 | AD38: =2/3*731443 -> 487628.67 | AE38: 243814 | AF38: - | AG38: - | AH38: =IFERROR(IF(SUM(AC38:AG38)=0,IF(COUNTIF($AA38:$AE38,"=0")>0,"$0","-"),SUM(AC38:AG38)),"-") -> 975257 | AI38: =IFERROR($AK38/$P38,"-") -> - | AJ38: =IFERROR(AVERAGE(AI38:AI40),"N/A") -> N/A | AK38: 1.8 | AL38: =IFERROR(IF(ISNUMBER($AK38)=TRUE, $AK38*$R38, $AJ38*$R38), "-") -> 1125561.6 | AM38: =IFERROR($AH38*$K38,"-") -> 975257 | AN38: =IFERROR(IF(SUM(AA38,AM38)=0,"-",SUM(AA38,AM38)),"-") -> 2265063 | AO38: =IFERROR(IF(SUM($AB38,$AL38)=0,"-",SUM($AB38,$AL38)),"-") -> 2313654.4 | AP38: 138981 | AQ38: DC & DB | AR38: =IFERROR(AP38*(12/$I38)*$K38,"-") -> 138981 | AS38: =IFERROR(AVERAGE(AR38:AR40),"N/A") -> 126721.33 | AT38: 118675 | AU38: =IFERROR(AT38*(12/$H38)*$J38,"-") -> - | AV38: =IFERROR(AVERAGE(AU38:AU40),"N/A") -> N/A | AW38: =IFERROR(IF(SUM(AN38,AR38,AU38)=0,"-",SUM(AN38,AR38,AU38)),"-") -> 2404044 | AX38: =IFERROR(IF(SUM(AO38,AR38,AU38)=0,"-",SUM(AO38,AR38,AU38)),"-") -> 2452635.4 | AY38: - | AZ38: KP | BA38: sc
A39: =$D39&"_"&$F39&"_"&$L39 -> TSX:HBM_2024_ | B39: =$D39&"_"&$F39&"_"&$N39 -> TSX:HBM_2024_CFO | C39: =$D39&"_"&$F39&"_"&$M39 -> TSX:HBM_2024_ | D39: =D38 -> TSX:HBM | E39: =_xll.ciqfunctions.udf.CIQ(D39,"IQ_Company_Name") -> Hudbay Minerals Inc. | F39: =F36 -> 2024 | G39: =F39&"-01-01" -> 2024-01-01 | H39: =F39&"-12-31" -> 2024-12-31 | I39: =_xlfn.DAYS(H39,G39)/_xlfn.DAYS(F39&"-12-31",F39&"-01-01")*12 -> 12 | J39: CAD | K39: =IF($J39="CAD",1,IF($J39="USD",VLOOKUP($F39,$G$9:$H$11,2,FALSE),"N/A")) -> 1 | N39: =N38 -> CFO | O39: =O38 -> CFO | P39: =P38 -> Eugene Lei | Q39: 551616 | R39: =IFERROR(Q39*(12/$I39)*$K39,"-") -> 551616 | S39: - | T39: =IFERROR(IF((S39*$K39)=0,"-",(S39*$K39)),"-") -> - | U39: 658795 | V39: =IFERROR(U39*(12/$I39)*$K39,"-") -> 658795 | W39: =IFERROR($V39/$R39,"-") -> 1.1943 | Y39: - | Z39: =IFERROR(IF(ISNUMBER($Y39)=TRUE, $Y39*$R39,$X39*$R39),"-") -> 0 | AA39: =IFERROR(IF(SUM(R39,V39)=0,"-",SUM(R39,V39)),"-") -> 1210411 | AB39: =IFERROR(IF(SUM(R39,Z39)=0,"-",SUM(R39,Z39)),"-") -> 551616 | AC39: =1/3*661939 -> 220646.33 | AD39: =2/3*661939 -> 441292.67 | AE39: 220646 | AF39: - | AG39: - | AH39: =IFERROR(IF(SUM(AC39:AG39)=0,IF(COUNTIF($AA39:$AE39,"=0")>0,"$0","-"),SUM(AC39:AG39)),"-") -> 882585 | AI39: =IFERROR($AK39/$P39,"-") -> - | AK39: - | AL39: =IFERROR(IF(ISNUMBER($AK39)=TRUE, $AK39*$R39, $AJ39*$R39), "-") -> 0 | AM39: =IFERROR($AH39*$K39,"-") -> 882585 | AN39: =IFERROR(IF(SUM(AA39,AM39)=0,"-",SUM(AA39,AM39)),"-") -> 2092996 | AO39: =IFERROR(IF(SUM($AB39,$AL39)=0,"-",SUM($AB39,$AL39)),"-") -> 551616 | AP39: 132222 | AQ39: DC & DB | AR39: =IFERROR(AP39*(12/$I39)*$K39,"-") -> 132222 | AT39: 103501 | AU39: =IFERROR(AT39*(12/$H39)*$J39,"-") -> - | AW39: =IFERROR(IF(SUM(AN39,AR39,AU39)=0,"-",SUM(AN39,AR39,AU39)),"-") -> 2225218 | AX39: =IFERROR(IF(SUM(AO39,AR39,AU39)=0,"-",SUM(AO39,AR39,AU39)),"-") -> 683838 | AY39: - | AZ39: KP | BA39: sc
A40: =$D40&"_"&$F40&"_"&$L40 -> TSX:HBM_2023_ | B40: =$D40&"_"&$F40&"_"&$N40 -> TSX:HBM_2023_CFO | C40: =$D40&"_"&$F40&"_"&$M40 -> TSX:HBM_2023_ | D40: =D39 -> TSX:HBM | E40: =_xll.ciqfunctions.udf.CIQ(D40,"IQ_Company_Name") -> Hudbay Minerals Inc. | F40: =F37 -> 2023 | G40: =F40&"-01-01" -> 2023-01-01 | H40: =F40&"-12-31" -> 2023-12-31 | I40: =_xlfn.DAYS(H40,G40)/_xlfn.DAYS(F40&"-12-31",F40&"-01-01")*12 -> 12 | J40: CAD | K40: =IF($J40="CAD",1,IF($J40="USD",VLOOKUP($F40,$G$9:$H$11,2,FALSE),"N/A")) -> 1 | N40: =N39 -> CFO | O40: =O39 -> CFO | P40: =P39 -> Eugene Lei | Q40: 530400 | R40: =IFERROR(Q40*(12/$I40)*$K40,"-") -> 530400 | S40: - | T40: =IFERROR(IF((S40*$K40)=0,"-",(S40*$K40)),"-") -> - | U40: 586675 | V40: =IFERROR(U40*(12/$I40)*$K40,"-") -> 586675 | W40: =IFERROR($V40/$R40,"-") -> 1.1060992 | Y40: - | Z40: =IFERROR(IF(ISNUMBER($Y40)=TRUE, $Y40*$R40,$X40*$R40),"-") -> 0 | AA40: =IFERROR(IF(SUM(R40,V40)=0,"-",SUM(R40,V40)),"-") -> 1117075 | AB40: =IFERROR(IF(SUM(R40,Z40)=0,"-",SUM(R40,Z40)),"-") -> 530400 | AC40: =1/3*636480 -> 212160 | AD40: =2/3*636480 -> 424320 | AE40: 212160 | AF40: - | AG40: - | AH40: =IFERROR(IF(SUM(AC40:AG40)=0,IF(COUNTIF($AA40:$AE40,"=0")>0,"$0","-"),SUM(AC40:AG40)),"-") -> 848640 | AI40: =IFERROR($AK40/$P40,"-") -> - | AK40: - | AL40: =IFERROR(IF(ISNUMBER($AK40)=TRUE, $AK40*$R40, $AJ40*$R40), "-") -> 0 | AM40: =IFERROR($AH40*$K40,"-") -> 848640 | AN40: =IFERROR(IF(SUM(AA40,AM40)=0,"-",SUM(AA40,AM40)),"-") -> 1965715 | AO40: =IFERROR(IF(SUM($AB40,$AL40)=0,"-",SUM($AB40,$AL40)),"-") -> 530400 | AP40: 108961 | AQ40: DC & DB | AR40: =IFERROR(AP40*(12/$I40)*$K40,"-") -> 108961 | AT40: 141406 | AU40: =IFERROR(AT40*(12/$H40)*$J40,"-") -> - | AW40: =IFERROR(IF(SUM(AN40,AR40,AU40)=0,"-",SUM(AN40,AR40,AU40)),"-") -> 2074676 | AX40: =IFERROR(IF(SUM(AO40,AR40,AU40)=0,"-",SUM(AO40,AR40,AU40)),"-") -> 639361 | AY40: - | AZ40: KP | BA40: sc
A41: =$D41&"_"&$F41&"_"&$L41 -> TSX:HBM_2025_Legal | B41: =$D41&"_"&$F41&"_"&$N41 -> TSX:HBM_2025_NEO3 | C41: =$D41&"_"&$F41&"_"&$M41 -> TSX:HBM_2025_ | D41: =D40 -> TSX:HBM | E41: =_xll.ciqfunctions.udf.CIQ(D41,"IQ_Company_Name") -> Hudbay Minerals Inc. | F41: =F38 -> 2025 | G41: =F41&"-01-01" -> 2025-01-01 | H41: =F41&"-12-31" -> 2025-12-31 | I41: =_xlfn.DAYS(H41,G41)/_xlfn.DAYS(F41&"-12-31",F41&"-01-01")*12 -> 12 | J41: CAD | K41: =IF($J41="CAD",1,IF($J41="USD",VLOOKUP($F41,$G$9:$H$11,2,FALSE),"N/A")) -> 1 | L41: Legal | N41: NEO3 | O41: SVP, Legal and Organizational Effectiveness | P41: Patrick Donnelly | Q41: 501660 | R41: 526743 | S41: 526743 | T41: =IFERROR(IF((S41*$K41)=0,"-",(S41*$K41)),"-") -> 526743 | U41: 478583 | V41: =IFERROR(U41*(12/$I41)*$K41,"-") -> 478583 | W41: =IFERROR($V41/$R41,"-") -> 0.90857021 | X41: =IFERROR(AVERAGE(W41:W43),"N/A") -> 0.91062429 | Y41: 0.75 | Z41: =IFERROR(IF(ISNUMBER($Y41)=TRUE, $Y41*$R41,$X41*$R41),"-") -> 395057.25 | AA41: =IFERROR(IF(SUM(R41,V41)=0,"-",SUM(R41,V41)),"-") -> 1005326 | AB41: =IFERROR(IF(SUM(R41,Z41)=0,"-",SUM(R41,Z41)),"-") -> 921800.25 | AC41: =1/3*564367 -> 188122.33 | AD41: =2/3*564367 -> 376244.67 | AE41: 188122 | AF41: - | AG41: - | AH41: =IFERROR(IF(SUM(AC41:AG41)=0,IF(COUNTIF($AA41:$AE41,"=0")>0,"$0","-"),SUM(AC41:AG41)),"-") -> 752489 | AI41: =IFERROR($AK41/$P41,"-") -> - | AJ41: =IFERROR(AVERAGE(AI41:AI43),"N/A") -> N/A | AK41: 1.5 | AL41: =IFERROR(IF(ISNUMBER($AK41)=TRUE, $AK41*$R41, $AJ41*$R41), "-") -> 790114.5 | AM41: =IFERROR($AH41*$K41,"-") -> 752489 | AN41: =IFERROR(IF(SUM(AA41,AM41)=0,"-",SUM(AA41,AM41)),"-") -> 1757815 | AO41: =IFERROR(IF(SUM($AB41,$AL41)=0,"-",SUM($AB41,$AL41)),"-") -> 1711914.8 | AP41: 91935 | AQ41: DB | AR41: =IFERROR(AP41*(12/$I41)*$K41,"-") -> 91935 | AS41: =IFERROR(AVERAGE(AR41:AR43),"N/A") -> 89596 | AT41: 92458 | AU41: =IFERROR(AT41*(12/$H41)*$J41,"-") -> - | AV41: =IFERROR(AVERAGE(AU41:AU43),"N/A") -> N/A | AW41: =IFERROR(IF(SUM(AN41,AR41,AU41)=0,"-",SUM(AN41,AR41,AU41)),"-") -> 1849750 | AX41: =IFERROR(IF(SUM(AO41,AR41,AU41)=0,"-",SUM(AO41,AR41,AU41)),"-") -> 1803849.8 | AY41: - | AZ41: KP | BA41: sc
A42: =$D42&"_"&$F42&"_"&$L42 -> TSX:HBM_2024_Legal | B42: =$D42&"_"&$F42&"_"&$N42 -> TSX:HBM_2024_NEO3 | C42: =$D42&"_"&$F42&"_"&$M42 -> TSX:HBM_2024_ | D42: =D41 -> TSX:HBM | E42: =_xll.ciqfunctions.udf.CIQ(D42,"IQ_Company_Name") -> Hudbay Minerals Inc. | F42: =F39 -> 2024 | G42: =F42&"-01-01" -> 2024-01-01 | H42: =F42&"-12-31" -> 2024-12-31 | I42: =_xlfn.DAYS(H42,G42)/_xlfn.DAYS(F42&"-12-31",F42&"-01-01")*12 -> 12 | J42: CAD | K42: =IF($J42="CAD",1,IF($J42="USD",VLOOKUP($F42,$G$9:$H$11,2,FALSE),"N/A")) -> 1 | L42: Legal | N42: =N41 -> NEO3 | O42: =O41 -> SVP, Legal and Organizational Effectiveness | P42: =P41 -> Patrick Donnelly | Q42: 487048 | R42: =IFERROR(Q42*(12/$I42)*$K42,"-") -> 487048 | S42: - | T42: =IFERROR(IF((S42*$K42)=0,"-",(S42*$K42)),"-") -> - | U42: 479256 | V42: =IFERROR(U42*(12/$I42)*$K42,"-") -> 479256 | W42: =IFERROR($V42/$R42,"-") -> 0.98400158 | Y42: - | Z42: =IFERROR(IF(ISNUMBER($Y42)=TRUE, $Y42*$R42,$X42*$R42),"-") -> 0 | AA42: =IFERROR(IF(SUM(R42,V42)=0,"-",SUM(R42,V42)),"-") -> 966304 | AB42: =IFERROR(IF(SUM(R42,Z42)=0,"-",SUM(R42,Z42)),"-") -> 487048 | AC42: =1/3*547929 -> 182643 | AD42: =2/3*547929 -> 365286 | AE42: 182643 | AF42: - | AG42: - | AH42: =IFERROR(IF(SUM(AC42:AG42)=0,IF(COUNTIF($AA42:$AE42,"=0")>0,"$0","-"),SUM(AC42:AG42)),"-") -> 730572 | AI42: =IFERROR($AK42/$P42,"-") -> - | AK42: - | AL42: =IFERROR(IF(ISNUMBER($AK42)=TRUE, $AK42*$R42, $AJ42*$R42), "-") -> 0 | AM42: =IFERROR($AH42*$K42,"-") -> 730572 | AN42: =IFERROR(IF(SUM(AA42,AM42)=0,"-",SUM(AA42,AM42)),"-") -> 1696876 | AO42: =IFERROR(IF(SUM($AB42,$AL42)=0,"-",SUM($AB42,$AL42)),"-") -> 487048 | AP42: 122673 | AQ42: DB | AR42: =IFERROR(AP42*(12/$I42)*$K42,"-") -> 122673 | AT42: 84863 | AU42: =IFERROR(AT42*(12/$H42)*$J42,"-") -> - | AW42: =IFERROR(IF(SUM(AN42,AR42,AU42)=0,"-",SUM(AN42,AR42,AU42)),"-") -> 1819549 | AX42: =IFERROR(IF(SUM(AO42,AR42,AU42)=0,"-",SUM(AO42,AR42,AU42)),"-") -> 609721 | AY42: - | AZ42: KP | BA42: sc
...

Sheet Master - Summary
A1: =TODAY() -> 46204
A2: CAD | B2: Position
B3: Year | C3: 2018
C4: Company | D4: Market Cap | E4: TEV | F4: Incumbent | G4: Position Title | H4: Annualized / Converted | I4: Annualized/ Converted | J4: Actual STI % | K4: 3 Year Average STIP % | L4: Target STI $ | M4: Target STI % | N4: Actual TCC | O4: Target TCC | P4: Total LTI (Converted) | Q4: Total LTI % | R4: 3 Year Average LTIP % | S4: Target LTI $ | T4: Target LTI % | U4: Actual (base + actual bonus + actual LTIP) | V4: Target (base + target bonus + Target LTIP) | X4: Cash | Y4: Equity
C5: =+C2& " Benchmarking - "&'Raw Data'!H5&" $000s" -> Benchmarking - CAD $000s
C6: Company | D6: Market Cap | E6: TEV | F6: Incumbent | G6: Title | H6: Base Salary | I6: STIP | L6: STIP | N6: Total Cash Compensation | P6: LTIP | S6: LTIP | U6: Total Direct Compensation | X6: Pay Mix
A7: Look-up | B7: Ticker | D7: Market Cap | E7: TEV | F7: Incumbent | G7: Title | H7: Base Salary | I7: Actual $ | J7: Actual % | K7: 3 Year Average STIP % | L7: Target $ | M7: Target % | N7: Actual $ | O7: Target $ | P7: Actual $ | Q7: Actual% | R7: 3 Year Average LTIP % | S7: Target $ | T7: Target % | U7: Actual $ | V7: Target $ | X7: Cash | Y7: Equity
A8: =$B8&"_"&$C$3&"_"&$C$2 -> TSX:T_2018_ | B8: TSX:T | C8: =IFERROR(INDEX(Raw_Data,MATCH($A8,Look_Up,0),MATCH(C$4,Component,0)),"-") -> - | D8: =_xll.ciqfunctions.udf.CIQ(B8, "IQ_MARKETCAP", $A$1,$A$2) -> #PEND | E8: =_xll.ciqfunctions.udf.CIQ($B8, "IQ_TEV", $A$1,$A$2) -> #PEND | F8: =IFERROR(INDEX(Raw_Data,MATCH($A8,Look_Up,0),MATCH(F$4,Component,0)),"-") -> - | G8: =IFERROR(INDEX(Raw_Data,MATCH($A8,Look_Up,0),MATCH(G$4,Component,0)),"-") -> - | H8: =IFERROR(INDEX(Raw_Data,MATCH($A8,Look_Up,0),MATCH(H$4,Component,0))/1000,"-") -> - | I8: =IFERROR(INDEX(Raw_Data,MATCH($A8,Look_Up,0),MATCH(I$4,Component,0))/1000,"-") -> - | J8: =IFERROR(INDEX(Raw_Data,MATCH($A8,Look_Up,0),MATCH(J$4,Component,0)),"-") -> - | K8: =IFERROR(INDEX(Raw_Data,MATCH($A8,Look_Up,0),MATCH(K$4,Component,0)),"-") -> - | L8: =IFERROR(INDEX(Raw_Data,MATCH($A8,Look_Up,0),MATCH(L$4,Component,0))/1000,"-") -> - | M8: =IFERROR(INDEX(Raw_Data,MATCH($A8,Look_Up,0),MATCH(M$4,Component,0)),"-") -> - | N8: =IFERROR(INDEX(Raw_Data,MATCH($A8,Look_Up,0),MATCH(N$4,Component,0))/1000,"-") -> - | O8: =IFERROR(INDEX(Raw_Data,MATCH($A8,Look_Up,0),MATCH(O$4,Component,0))/1000,"-") -> - | P8: =IFERROR(INDEX(Raw_Data,MATCH($A8,Look_Up,0),MATCH(P$4,Component,0))/1000,"-") -> - | Q8: =IFERROR(INDEX(Raw_Data,MATCH($A8,Look_Up,0),MATCH(Q$4,Component,0)),"-") -> - | R8: =IFERROR(INDEX(Raw_Data,MATCH($A8,Look_Up,0),MATCH(R$4,Component,0)),"-") -> - | S8: =IFERROR(INDEX(Raw_Data,MATCH($A8,Look_Up,0),MATCH(S$4,Component,0))/1000,"-") -> - | T8: =IFERROR(INDEX(Raw_Data,MATCH($A8,Look_Up,0),MATCH(T$4,Component,0)),"-") -> - | U8: =IFERROR(INDEX(Raw_Data,MATCH($A8,Look_Up,0),MATCH(U$4,Component,0))/1000,"-") -> - | V8: =IFERROR(INDEX(Raw_Data,MATCH($A8,Look_Up,0),MATCH(V$4,Component,0))/1000,"-") -> - | X8: =IFERROR(N8/U8,"-") -> - | Y8: =IFERROR(P8/U8,"-") -> -
A9: =$B9&"_"&$C$3&"_"&$C$2 -> TSX:S_2018_ | B9: TSX:S | C9: =IFERROR(INDEX(Raw_Data,MATCH($A9,Look_Up,0),MATCH(C$4,Component,0)),"-") -> - | D9: =_xll.ciqfunctions.udf.CIQ(B9, "IQ_MARKETCAP", $A$1,$A$2) -> #PEND | E9: =_xll.ciqfunctions.udf.CIQ($B9, "IQ_TEV", $A$1,$A$2) -> #PEND | F9: =IFERROR(INDEX(Raw_Data,MATCH($A9,Look_Up,0),MATCH(F$4,Component,0)),"-") -> - | G9: =IFERROR(INDEX(Raw_Data,MATCH($A9,Look_Up,0),MATCH(G$4,Component,0)),"-") -> - | H9: =IFERROR(INDEX(Raw_Data,MATCH($A9,Look_Up,0),MATCH(H$4,Component,0))/1000,"-") -> - | I9: =IFERROR(INDEX(Raw_Data,MATCH($A9,Look_Up,0),MATCH(I$4,Component,0))/1000,"-") -> - | J9: =IFERROR(INDEX(Raw_Data,MATCH($A9,Look_Up,0),MATCH(J$4,Component,0)),"-") -> - | K9: =IFERROR(INDEX(Raw_Data,MATCH($A9,Look_Up,0),MATCH(K$4,Component,0)),"-") -> - | L9: =IFERROR(INDEX(Raw_Data,MATCH($A9,Look_Up,0),MATCH(L$4,Component,0))/1000,"-") -> - | M9: =IFERROR(INDEX(Raw_Data,MATCH($A9,Look_Up,0),MATCH(M$4,Component,0)),"-") -> - | N9: =IFERROR(INDEX(Raw_Data,MATCH($A9,Look_Up,0),MATCH(N$4,Component,0))/1000,"-") -> - | O9: =IFERROR(INDEX(Raw_Data,MATCH($A9,Look_Up,0),MATCH(O$4,Component,0))/1000,"-") -> - | P9: =IFERROR(INDEX(Raw_Data,MATCH($A9,Look_Up,0),MATCH(P$4,Component,0))/1000,"-") -> - | Q9: =IFERROR(INDEX(Raw_Data,MATCH($A9,Look_Up,0),MATCH(Q$4,Component,0)),"-") -> - | R9: =IFERROR(INDEX(Raw_Data,MATCH($A9,Look_Up,0),MATCH(R$4,Component,0)),"-") -> - | S9: =IFERROR(INDEX(Raw_Data,MATCH($A9,Look_Up,0),MATCH(S$4,Component,0))/1000,"-") -> - | T9: =IFERROR(INDEX(Raw_Data,MATCH($A9,Look_Up,0),MATCH(T$4,Component,0)),"-") -> - | U9: =IFERROR(INDEX(Raw_Data,MATCH($A9,Look_Up,0),MATCH(U$4,Component,0))/1000,"-") -> - | V9: =IFERROR(INDEX(Raw_Data,MATCH($A9,Look_Up,0),MATCH(V$4,Component,0))/1000,"-") -> - | X9: =IFERROR(N9/U9,"-") -> - | Y9: =IFERROR(P9/U9,"-") -> -
A10: =$B10&"_"&$C$3&"_"&$C$2 -> TSX:R_2018_ | B10: TSX:R | C10: =IFERROR(INDEX(Raw_Data,MATCH($A10,Look_Up,0),MATCH(C$4,Component,0)),"-") -> - | D10: =_xll.ciqfunctions.udf.CIQ(B10, "IQ_MARKETCAP", $A$1,$A$2) -> #PEND | E10: =_xll.ciqfunctions.udf.CIQ($B10, "IQ_TEV", $A$1,$A$2) -> #PEND | F10: =IFERROR(INDEX(Raw_Data,MATCH($A10,Look_Up,0),MATCH(F$4,Component,0)),"-") -> - | G10: =IFERROR(INDEX(Raw_Data,MATCH($A10,Look_Up,0),MATCH(G$4,Component,0)),"-") -> - | H10: =IFERROR(INDEX(Raw_Data,MATCH($A10,Look_Up,0),MATCH(H$4,Component,0))/1000,"-") -> - | I10: =IFERROR(INDEX(Raw_Data,MATCH($A10,Look_Up,0),MATCH(I$4,Component,0))/1000,"-") -> - | J10: =IFERROR(INDEX(Raw_Data,MATCH($A10,Look_Up,0),MATCH(J$4,Component,0)),"-") -> - | K10: =IFERROR(INDEX(Raw_Data,MATCH($A10,Look_Up,0),MATCH(K$4,Component,0)),"-") -> - | L10: =IFERROR(INDEX(Raw_Data,MATCH($A10,Look_Up,0),MATCH(L$4,Component,0))/1000,"-") -> - | M10: =IFERROR(INDEX(Raw_Data,MATCH($A10,Look_Up,0),MATCH(M$4,Component,0)),"-") -> - | N10: =IFERROR(INDEX(Raw_Data,MATCH($A10,Look_Up,0),MATCH(N$4,Component,0))/1000,"-") -> - | O10: =IFERROR(INDEX(Raw_Data,MATCH($A10,Look_Up,0),MATCH(O$4,Component,0))/1000,"-") -> - | P10: =IFERROR(INDEX(Raw_Data,MATCH($A10,Look_Up,0),MATCH(P$4,Component,0))/1000,"-") -> - | Q10: =IFERROR(INDEX(Raw_Data,MATCH($A10,Look_Up,0),MATCH(Q$4,Component,0)),"-") -> - | R10: =IFERROR(INDEX(Raw_Data,MATCH($A10,Look_Up,0),MATCH(R$4,Component,0)),"-") -> - | S10: =IFERROR(INDEX(Raw_Data,MATCH($A10,Look_Up,0),MATCH(S$4,Component,0))/1000,"-") -> - | T10: =IFERROR(INDEX(Raw_Data,MATCH($A10,Look_Up,0),MATCH(T$4,Component,0)),"-") -> - | U10: =IFERROR(INDEX(Raw_Data,MATCH($A10,Look_Up,0),MATCH(U$4,Component,0))/1000,"-") -> - | V10: =IFERROR(INDEX(Raw_Data,MATCH($A10,Look_Up,0),MATCH(V$4,Component,0))/1000,"-") -> - | X10: =IFERROR(N10/U10,"-") -> - | Y10: =IFERROR(P10/U10,"-") -> -
A11: =$B11&"_"&$C$3&"_"&$C$2 -> TSX:Q_2018_ | B11: TSX:Q | C11: =IFERROR(INDEX(Raw_Data,MATCH($A11,Look_Up,0),MATCH(C$4,Component,0)),"-") -> - | D11: =_xll.ciqfunctions.udf.CIQ(B11, "IQ_MARKETCAP", $A$1,$A$2) -> #PEND | E11: =_xll.ciqfunctions.udf.CIQ($B11, "IQ_TEV", $A$1,$A$2) -> #PEND | F11: =IFERROR(INDEX(Raw_Data,MATCH($A11,Look_Up,0),MATCH(F$4,Component,0)),"-") -> - | G11: =IFERROR(INDEX(Raw_Data,MATCH($A11,Look_Up,0),MATCH(G$4,Component,0)),"-") -> - | H11: =IFERROR(INDEX(Raw_Data,MATCH($A11,Look_Up,0),MATCH(H$4,Component,0))/1000,"-") -> - | I11: =IFERROR(INDEX(Raw_Data,MATCH($A11,Look_Up,0),MATCH(I$4,Component,0))/1000,"-") -> - | J11: =IFERROR(INDEX(Raw_Data,MATCH($A11,Look_Up,0),MATCH(J$4,Component,0)),"-") -> - | K11: =IFERROR(INDEX(Raw_Data,MATCH($A11,Look_Up,0),MATCH(K$4,Component,0)),"-") -> - | L11: =IFERROR(INDEX(Raw_Data,MATCH($A11,Look_Up,0),MATCH(L$4,Component,0))/1000,"-") -> - | M11: =IFERROR(INDEX(Raw_Data,MATCH($A11,Look_Up,0),MATCH(M$4,Component,0)),"-") -> - | N11: =IFERROR(INDEX(Raw_Data,MATCH($A11,Look_Up,0),MATCH(N$4,Component,0))/1000,"-") -> - | O11: =IFERROR(INDEX(Raw_Data,MATCH($A11,Look_Up,0),MATCH(O$4,Component,0))/1000,"-") -> - | P11: =IFERROR(INDEX(Raw_Data,MATCH($A11,Look_Up,0),MATCH(P$4,Component,0))/1000,"-") -> - | Q11: =IFERROR(INDEX(Raw_Data,MATCH($A11,Look_Up,0),MATCH(Q$4,Component,0)),"-") -> - | R11: =IFERROR(INDEX(Raw_Data,MATCH($A11,Look_Up,0),MATCH(R$4,Component,0)),"-") -> - | S11: =IFERROR(INDEX(Raw_Data,MATCH($A11,Look_Up,0),MATCH(S$4,Component,0))/1000,"-") -> - | T11: =IFERROR(INDEX(Raw_Data,MATCH($A11,Look_Up,0),MATCH(T$4,Component,0)),"-") -> - | U11: =IFERROR(INDEX(Raw_Data,MATCH($A11,Look_Up,0),MATCH(U$4,Component,0))/1000,"-") -> - | V11: =IFERROR(INDEX(Raw_Data,MATCH($A11,Look_Up,0),MATCH(V$4,Component,0))/1000,"-") -> - | X11: =IFERROR(N11/U11,"-") -> - | Y11: =IFERROR(P11/U11,"-") -> -
A12: =$B12&"_"&$C$3&"_"&$C$2 -> TSX:P_2018_ | B12: TSX:P | C12: =IFERROR(INDEX(Raw_Data,MATCH($A12,Look_Up,0),MATCH(C$4,Component,0)),"-") -> - | D12: =_xll.ciqfunctions.udf.CIQ(B12, "IQ_MARKETCAP", $A$1,$A$2) -> #PEND | E12: =_xll.ciqfunctions.udf.CIQ($B12, "IQ_TEV", $A$1,$A$2) -> #PEND | F12: =IFERROR(INDEX(Raw_Data,MATCH($A12,Look_Up,0),MATCH(F$4,Component,0)),"-") -> - | G12: =IFERROR(INDEX(Raw_Data,MATCH($A12,Look_Up,0),MATCH(G$4,Component,0)),"-") -> - | H12: =IFERROR(INDEX(Raw_Data,MATCH($A12,Look_Up,0),MATCH(H$4,Component,0))/1000,"-") -> - | I12: =IFERROR(INDEX(Raw_Data,MATCH($A12,Look_Up,0),MATCH(I$4,Component,0))/1000,"-") -> - | J12: =IFERROR(INDEX(Raw_Data,MATCH($A12,Look_Up,0),MATCH(J$4,Component,0)),"-") -> - | K12: =IFERROR(INDEX(Raw_Data,MATCH($A12,Look_Up,0),MATCH(K$4,Component,0)),"-") -> - | L12: =IFERROR(INDEX(Raw_Data,MATCH($A12,Look_Up,0),MATCH(L$4,Component,0))/1000,"-") -> - | M12: =IFERROR(INDEX(Raw_Data,MATCH($A12,Look_Up,0),MATCH(M$4,Component,0)),"-") -> - | N12: =IFERROR(INDEX(Raw_Data,MATCH($A12,Look_Up,0),MATCH(N$4,Component,0))/1000,"-") -> - | O12: =IFERROR(INDEX(Raw_Data,MATCH($A12,Look_Up,0),MATCH(O$4,Component,0))/1000,"-") -> - | P12: =IFERROR(INDEX(Raw_Data,MATCH($A12,Look_Up,0),MATCH(P$4,Component,0))/1000,"-") -> - | Q12: =IFERROR(INDEX(Raw_Data,MATCH($A12,Look_Up,0),MATCH(Q$4,Component,0)),"-") -> - | R12: =IFERROR(INDEX(Raw_Data,MATCH($A12,Look_Up,0),MATCH(R$4,Component,0)),"-") -> - | S12: =IFERROR(INDEX(Raw_Data,MATCH($A12,Look_Up,0),MATCH(S$4,Component,0))/1000,"-") -> - | T12: =IFERROR(INDEX(Raw_Data,MATCH($A12,Look_Up,0),MATCH(T$4,Component,0)),"-") -> - | U12: =IFERROR(INDEX(Raw_Data,MATCH($A12,Look_Up,0),MATCH(U$4,Component,0))/1000,"-") -> - | V12: =IFERROR(INDEX(Raw_Data,MATCH($A12,Look_Up,0),MATCH(V$4,Component,0))/1000,"-") -> - | X12: =IFERROR(N12/U12,"-") -> - | Y12: =IFERROR(P12/U12,"-") -> -
A13: =$B13&"_"&$C$3&"_"&$C$2 -> TSX:O_2018_ | B13: TSX:O | C13: =IFERROR(INDEX(Raw_Data,MATCH($A13,Look_Up,0),MATCH(C$4,Component,0)),"-") -> - | D13: =_xll.ciqfunctions.udf.CIQ(B13, "IQ_MARKETCAP", $A$1,$A$2) -> #PEND | E13: =_xll.ciqfunctions.udf.CIQ($B13, "IQ_TEV", $A$1,$A$2) -> #PEND | F13: =IFERROR(INDEX(Raw_Data,MATCH($A13,Look_Up,0),MATCH(F$4,Component,0)),"-") -> - | G13: =IFERROR(INDEX(Raw_Data,MATCH($A13,Look_Up,0),MATCH(G$4,Component,0)),"-") -> - | H13: =IFERROR(INDEX(Raw_Data,MATCH($A13,Look_Up,0),MATCH(H$4,Component,0))/1000,"-") -> - | I13: =IFERROR(INDEX(Raw_Data,MATCH($A13,Look_Up,0),MATCH(I$4,Component,0))/1000,"-") -> - | J13: =IFERROR(INDEX(Raw_Data,MATCH($A13,Look_Up,0),MATCH(J$4,Component,0)),"-") -> - | K13: =IFERROR(INDEX(Raw_Data,MATCH($A13,Look_Up,0),MATCH(K$4,Component,0)),"-") -> - | L13: =IFERROR(INDEX(Raw_Data,MATCH($A13,Look_Up,0),MATCH(L$4,Component,0))/1000,"-") -> - | M13: =IFERROR(INDEX(Raw_Data,MATCH($A13,Look_Up,0),MATCH(M$4,Component,0)),"-") -> - | N13: =IFERROR(INDEX(Raw_Data,MATCH($A13,Look_Up,0),MATCH(N$4,Component,0))/1000,"-") -> - | O13: =IFERROR(INDEX(Raw_Data,MATCH($A13,Look_Up,0),MATCH(O$4,Component,0))/1000,"-") -> - | P13: =IFERROR(INDEX(Raw_Data,MATCH($A13,Look_Up,0),MATCH(P$4,Component,0))/1000,"-") -> - | Q13: =IFERROR(INDEX(Raw_Data,MATCH($A13,Look_Up,0),MATCH(Q$4,Component,0)),"-") -> - | R13: =IFERROR(INDEX(Raw_Data,MATCH($A13,Look_Up,0),MATCH(R$4,Component,0)),"-") -> - | S13: =IFERROR(INDEX(Raw_Data,MATCH($A13,Look_Up,0),MATCH(S$4,Component,0))/1000,"-") -> - | T13: =IFERROR(INDEX(Raw_Data,MATCH($A13,Look_Up,0),MATCH(T$4,Component,0)),"-") -> - | U13: =IFERROR(INDEX(Raw_Data,MATCH($A13,Look_Up,0),MATCH(U$4,Component,0))/1000,"-") -> - | V13: =IFERROR(INDEX(Raw_Data,MATCH($A13,Look_Up,0),MATCH(V$4,Component,0))/1000,"-") -> - | X13: =IFERROR(N13/U13,"-") -> - | Y13: =IFERROR(P13/U13,"-") -> -
A14: =$B14&"_"&$C$3&"_"&$C$2 -> TSX:N_2018_ | B14: TSX:N | C14: =IFERROR(INDEX(Raw_Data,MATCH($A14,Look_Up,0),MATCH(C$4,Component,0)),"-") -> - | D14: =_xll.ciqfunctions.udf.CIQ(B14, "IQ_MARKETCAP", $A$1,$A$2) -> #PEND | E14: =_xll.ciqfunctions.udf.CIQ($B14, "IQ_TEV", $A$1,$A$2) -> #PEND | F14: =IFERROR(INDEX(Raw_Data,MATCH($A14,Look_Up,0),MATCH(F$4,Component,0)),"-") -> - | G14: =IFERROR(INDEX(Raw_Data,MATCH($A14,Look_Up,0),MATCH(G$4,Component,0)),"-") -> - | H14: =IFERROR(INDEX(Raw_Data,MATCH($A14,Look_Up,0),MATCH(H$4,Component,0))/1000,"-") -> - | I14: =IFERROR(INDEX(Raw_Data,MATCH($A14,Look_Up,0),MATCH(I$4,Component,0))/1000,"-") -> - | J14: =IFERROR(INDEX(Raw_Data,MATCH($A14,Look_Up,0),MATCH(J$4,Component,0)),"-") -> - | K14: =IFERROR(INDEX(Raw_Data,MATCH($A14,Look_Up,0),MATCH(K$4,Component,0)),"-") -> - | L14: =IFERROR(INDEX(Raw_Data,MATCH($A14,Look_Up,0),MATCH(L$4,Component,0))/1000,"-") -> - | M14: =IFERROR(INDEX(Raw_Data,MATCH($A14,Look_Up,0),MATCH(M$4,Component,0)),"-") -> - | N14: =IFERROR(INDEX(Raw_Data,MATCH($A14,Look_Up,0),MATCH(N$4,Component,0))/1000,"-") -> - | O14: =IFERROR(INDEX(Raw_Data,MATCH($A14,Look_Up,0),MATCH(O$4,Component,0))/1000,"-") -> - | P14: =IFERROR(INDEX(Raw_Data,MATCH($A14,Look_Up,0),MATCH(P$4,Component,0))/1000,"-") -> - | Q14: =IFERROR(INDEX(Raw_Data,MATCH($A14,Look_Up,0),MATCH(Q$4,Component,0)),"-") -> - | R14: =IFERROR(INDEX(Raw_Data,MATCH($A14,Look_Up,0),MATCH(R$4,Component,0)),"-") -> - | S14: =IFERROR(INDEX(Raw_Data,MATCH($A14,Look_Up,0),MATCH(S$4,Component,0))/1000,"-") -> - | T14: =IFERROR(INDEX(Raw_Data,MATCH($A14,Look_Up,0),MATCH(T$4,Component,0)),"-") -> - | U14: =IFERROR(INDEX(Raw_Data,MATCH($A14,Look_Up,0),MATCH(U$4,Component,0))/1000,"-") -> - | V14: =IFERROR(INDEX(Raw_Data,MATCH($A14,Look_Up,0),MATCH(V$4,Component,0))/1000,"-") -> - | X14: =IFERROR(N14/U14,"-") -> - | Y14: =IFERROR(P14/U14,"-") -> -
A15: =$B15&"_"&$C$3&"_"&$C$2 -> TSX:M_2018_ | B15: TSX:M | C15: =IFERROR(INDEX(Raw_Data,MATCH($A15,Look_Up,0),MATCH(C$4,Component,0)),"-") -> - | D15: =_xll.ciqfunctions.udf.CIQ(B15, "IQ_MARKETCAP", $A$1,$A$2) -> #PEND | E15: =_xll.ciqfunctions.udf.CIQ($B15, "IQ_TEV", $A$1,$A$2) -> #PEND | F15: =IFERROR(INDEX(Raw_Data,MATCH($A15,Look_Up,0),MATCH(F$4,Component,0)),"-") -> - | G15: =IFERROR(INDEX(Raw_Data,MATCH($A15,Look_Up,0),MATCH(G$4,Component,0)),"-") -> - | H15: =IFERROR(INDEX(Raw_Data,MATCH($A15,Look_Up,0),MATCH(H$4,Component,0))/1000,"-") -> - | I15: =IFERROR(INDEX(Raw_Data,MATCH($A15,Look_Up,0),MATCH(I$4,Component,0))/1000,"-") -> - | J15: =IFERROR(INDEX(Raw_Data,MATCH($A15,Look_Up,0),MATCH(J$4,Component,0)),"-") -> - | K15: =IFERROR(INDEX(Raw_Data,MATCH($A15,Look_Up,0),MATCH(K$4,Component,0)),"-") -> - | L15: =IFERROR(INDEX(Raw_Data,MATCH($A15,Look_Up,0),MATCH(L$4,Component,0))/1000,"-") -> - | M15: =IFERROR(INDEX(Raw_Data,MATCH($A15,Look_Up,0),MATCH(M$4,Component,0)),"-") -> - | N15: =IFERROR(INDEX(Raw_Data,MATCH($A15,Look_Up,0),MATCH(N$4,Component,0))/1000,"-") -> - | O15: =IFERROR(INDEX(Raw_Data,MATCH($A15,Look_Up,0),MATCH(O$4,Component,0))/1000,"-") -> - | P15: =IFERROR(INDEX(Raw_Data,MATCH($A15,Look_Up,0),MATCH(P$4,Component,0))/1000,"-") -> - | Q15: =IFERROR(INDEX(Raw_Data,MATCH($A15,Look_Up,0),MATCH(Q$4,Component,0)),"-") -> - | R15: =IFERROR(INDEX(Raw_Data,MATCH($A15,Look_Up,0),MATCH(R$4,Component,0)),"-") -> - | S15: =IFERROR(INDEX(Raw_Data,MATCH($A15,Look_Up,0),MATCH(S$4,Component,0))/1000,"-") -> - | T15: =IFERROR(INDEX(Raw_Data,MATCH($A15,Look_Up,0),MATCH(T$4,Component,0)),"-") -> - | U15: =IFERROR(INDEX(Raw_Data,MATCH($A15,Look_Up,0),MATCH(U$4,Component,0))/1000,"-") -> - | V15: =IFERROR(INDEX(Raw_Data,MATCH($A15,Look_Up,0),MATCH(V$4,Component,0))/1000,"-") -> - | X15: =IFERROR(N15/U15,"-") -> - | Y15: =IFERROR(P15/U15,"-") -> -
A16: =$B16&"_"&$C$3&"_"&$C$2 -> TSX:L_2018_ | B16: TSX:L | C16: =IFERROR(INDEX(Raw_Data,MATCH($A16,Look_Up,0),MATCH(C$4,Component,0)),"-") -> - | D16: =_xll.ciqfunctions.udf.CIQ(B16, "IQ_MARKETCAP", $A$1,$A$2) -> #PEND | E16: =_xll.ciqfunctions.udf.CIQ($B16, "IQ_TEV", $A$1,$A$2) -> #PEND | F16: =IFERROR(INDEX(Raw_Data,MATCH($A16,Look_Up,0),MATCH(F$4,Component,0)),"-") -> - | G16: =IFERROR(INDEX(Raw_Data,MATCH($A16,Look_Up,0),MATCH(G$4,Component,0)),"-") -> - | H16: =IFERROR(INDEX(Raw_Data,MATCH($A16,Look_Up,0),MATCH(H$4,Component,0))/1000,"-") -> - | I16: =IFERROR(INDEX(Raw_Data,MATCH($A16,Look_Up,0),MATCH(I$4,Component,0))/1000,"-") -> - | J16: =IFERROR(INDEX(Raw_Data,MATCH($A16,Look_Up,0),MATCH(J$4,Component,0)),"-") -> - | K16: =IFERROR(INDEX(Raw_Data,MATCH($A16,Look_Up,0),MATCH(K$4,Component,0)),"-") -> - | L16: =IFERROR(INDEX(Raw_Data,MATCH($A16,Look_Up,0),MATCH(L$4,Component,0))/1000,"-") -> - | M16: =IFERROR(INDEX(Raw_Data,MATCH($A16,Look_Up,0),MATCH(M$4,Component,0)),"-") -> - | N16: =IFERROR(INDEX(Raw_Data,MATCH($A16,Look_Up,0),MATCH(N$4,Component,0))/1000,"-") -> - | O16: =IFERROR(INDEX(Raw_Data,MATCH($A16,Look_Up,0),MATCH(O$4,Component,0))/1000,"-") -> - | P16: =IFERROR(INDEX(Raw_Data,MATCH($A16,Look_Up,0),MATCH(P$4,Component,0))/1000,"-") -> - | Q16: =IFERROR(INDEX(Raw_Data,MATCH($A16,Look_Up,0),MATCH(Q$4,Component,0)),"-") -> - | R16: =IFERROR(INDEX(Raw_Data,MATCH($A16,Look_Up,0),MATCH(R$4,Component,0)),"-") -> - | S16: =IFERROR(INDEX(Raw_Data,MATCH($A16,Look_Up,0),MATCH(S$4,Component,0))/1000,"-") -> - | T16: =IFERROR(INDEX(Raw_Data,MATCH($A16,Look_Up,0),MATCH(T$4,Component,0)),"-") -> - | U16: =IFERROR(INDEX(Raw_Data,MATCH($A16,Look_Up,0),MATCH(U$4,Component,0))/1000,"-") -> - | V16: =IFERROR(INDEX(Raw_Data,MATCH($A16,Look_Up,0),MATCH(V$4,Component,0))/1000,"-") -> - | X16: =IFERROR(N16/U16,"-") -> - | Y16: =IFERROR(P16/U16,"-") -> -
A17: =$B17&"_"&$C$3&"_"&$C$2 -> TSX:K_2018_ | B17: TSX:K | C17: =IFERROR(INDEX(Raw_Data,MATCH($A17,Look_Up,0),MATCH(C$4,Component,0)),"-") -> - | D17: =_xll.ciqfunctions.udf.CIQ(B17, "IQ_MARKETCAP", $A$1,$A$2) -> #PEND | E17: =_xll.ciqfunctions.udf.CIQ($B17, "IQ_TEV", $A$1,$A$2) -> #PEND | F17: =IFERROR(INDEX(Raw_Data,MATCH($A17,Look_Up,0),MATCH(F$4,Component,0)),"-") -> - | G17: =IFERROR(INDEX(Raw_Data,MATCH($A17,Look_Up,0),MATCH(G$4,Component,0)),"-") -> - | H17: =IFERROR(INDEX(Raw_Data,MATCH($A17,Look_Up,0),MATCH(H$4,Component,0))/1000,"-") -> - | I17: =IFERROR(INDEX(Raw_Data,MATCH($A17,Look_Up,0),MATCH(I$4,Component,0))/1000,"-") -> - | J17: =IFERROR(INDEX(Raw_Data,MATCH($A17,Look_Up,0),MATCH(J$4,Component,0)),"-") -> - | K17: =IFERROR(INDEX(Raw_Data,MATCH($A17,Look_Up,0),MATCH(K$4,Component,0)),"-") -> - | L17: =IFERROR(INDEX(Raw_Data,MATCH($A17,Look_Up,0),MATCH(L$4,Component,0))/1000,"-") -> - | M17: =IFERROR(INDEX(Raw_Data,MATCH($A17,Look_Up,0),MATCH(M$4,Component,0)),"-") -> - | N17: =IFERROR(INDEX(Raw_Data,MATCH($A17,Look_Up,0),MATCH(N$4,Component,0))/1000,"-") -> - | O17: =IFERROR(INDEX(Raw_Data,MATCH($A17,Look_Up,0),MATCH(O$4,Component,0))/1000,"-") -> - | P17: =IFERROR(INDEX(Raw_Data,MATCH($A17,Look_Up,0),MATCH(P$4,Component,0))/1000,"-") -> - | Q17: =IFERROR(INDEX(Raw_Data,MATCH($A17,Look_Up,0),MATCH(Q$4,Component,0)),"-") -> - | R17: =IFERROR(INDEX(Raw_Data,MATCH($A17,Look_Up,0),MATCH(R$4,Component,0)),"-") -> - | S17: =IFERROR(INDEX(Raw_Data,MATCH($A17,Look_Up,0),MATCH(S$4,Component,0))/1000,"-") -> - | T17: =IFERROR(INDEX(Raw_Data,MATCH($A17,Look_Up,0),MATCH(T$4,Component,0)),"-") -> - | U17: =IFERROR(INDEX(Raw_Data,MATCH($A17,Look_Up,0),MATCH(U$4,Component,0))/1000,"-") -> - | V17: =IFERROR(INDEX(Raw_Data,MATCH($A17,Look_Up,0),MATCH(V$4,Component,0))/1000,"-") -> - | X17: =IFERROR(N17/U17,"-") -> - | Y17: =IFERROR(P17/U17,"-") -> -
A18: =$B18&"_"&$C$3&"_"&$C$2 -> TSX:J_2018_ | B18: TSX:J | C18: =IFERROR(INDEX(Raw_Data,MATCH($A18,Look_Up,0),MATCH(C$4,Component,0)),"-") -> - | D18: =_xll.ciqfunctions.udf.CIQ(B18, "IQ_MARKETCAP", $A$1,$A$2) -> #PEND | E18: =_xll.ciqfunctions.udf.CIQ($B18, "IQ_TEV", $A$1,$A$2) -> #PEND | F18: =IFERROR(INDEX(Raw_Data,MATCH($A18,Look_Up,0),MATCH(F$4,Component,0)),"-") -> - | G18: =IFERROR(INDEX(Raw_Data,MATCH($A18,Look_Up,0),MATCH(G$4,Component,0)),"-") -> - | H18: =IFERROR(INDEX(Raw_Data,MATCH($A18,Look_Up,0),MATCH(H$4,Component,0))/1000,"-") -> - | I18: =IFERROR(INDEX(Raw_Data,MATCH($A18,Look_Up,0),MATCH(I$4,Component,0))/1000,"-") -> - | J18: =IFERROR(INDEX(Raw_Data,MATCH($A18,Look_Up,0),MATCH(J$4,Component,0)),"-") -> - | K18: =IFERROR(INDEX(Raw_Data,MATCH($A18,Look_Up,0),MATCH(K$4,Component,0)),"-") -> - | L18: =IFERROR(INDEX(Raw_Data,MATCH($A18,Look_Up,0),MATCH(L$4,Component,0))/1000,"-") -> - | M18: =IFERROR(INDEX(Raw_Data,MATCH($A18,Look_Up,0),MATCH(M$4,Component,0)),"-") -> - | N18: =IFERROR(INDEX(Raw_Data,MATCH($A18,Look_Up,0),MATCH(N$4,Component,0))/1000,"-") -> - | O18: =IFERROR(INDEX(Raw_Data,MATCH($A18,Look_Up,0),MATCH(O$4,Component,0))/1000,"-") -> - | P18: =IFERROR(INDEX(Raw_Data,MATCH($A18,Look_Up,0),MATCH(P$4,Component,0))/1000,"-") -> - | Q18: =IFERROR(INDEX(Raw_Data,MATCH($A18,Look_Up,0),MATCH(Q$4,Component,0)),"-") -> - | R18: =IFERROR(INDEX(Raw_Data,MATCH($A18,Look_Up,0),MATCH(R$4,Component,0)),"-") -> - | S18: =IFERROR(INDEX(Raw_Data,MATCH($A18,Look_Up,0),MATCH(S$4,Component,0))/1000,"-") -> - | T18: =IFERROR(INDEX(Raw_Data,MATCH($A18,Look_Up,0),MATCH(T$4,Component,0)),"-") -> - | U18: =IFERROR(INDEX(Raw_Data,MATCH($A18,Look_Up,0),MATCH(U$4,Component,0))/1000,"-") -> - | V18: =IFERROR(INDEX(Raw_Data,MATCH($A18,Look_Up,0),MATCH(V$4,Component,0))/1000,"-") -> - | X18: =IFERROR(N18/U18,"-") -> - | Y18: =IFERROR(P18/U18,"-") -> -
A19: =$B19&"_"&$C$3&"_"&$C$2 -> TSX:I_2018_ | B19: TSX:I | C19: =IFERROR(INDEX(Raw_Data,MATCH($A19,Look_Up,0),MATCH(C$4,Component,0)),"-") -> - | D19: =_xll.ciqfunctions.udf.CIQ(B19, "IQ_MARKETCAP", $A$1,$A$2) -> #PEND | E19: =_xll.ciqfunctions.udf.CIQ($B19, "IQ_TEV", $A$1,$A$2) -> #PEND | F19: =IFERROR(INDEX(Raw_Data,MATCH($A19,Look_Up,0),MATCH(F$4,Component,0)),"-") -> - | G19: =IFERROR(INDEX(Raw_Data,MATCH($A19,Look_Up,0),MATCH(G$4,Component,0)),"-") -> - | H19: =IFERROR(INDEX(Raw_Data,MATCH($A19,Look_Up,0),MATCH(H$4,Component,0))/1000,"-") -> - | I19: =IFERROR(INDEX(Raw_Data,MATCH($A19,Look_Up,0),MATCH(I$4,Component,0))/1000,"-") -> - | J19: =IFERROR(INDEX(Raw_Data,MATCH($A19,Look_Up,0),MATCH(J$4,Component,0)),"-") -> - | K19: =IFERROR(INDEX(Raw_Data,MATCH($A19,Look_Up,0),MATCH(K$4,Component,0)),"-") -> - | L19: =IFERROR(INDEX(Raw_Data,MATCH($A19,Look_Up,0),MATCH(L$4,Component,0))/1000,"-") -> - | M19: =IFERROR(INDEX(Raw_Data,MATCH($A19,Look_Up,0),MATCH(M$4,Component,0)),"-") -> - | N19: =IFERROR(INDEX(Raw_Data,MATCH($A19,Look_Up,0),MATCH(N$4,Component,0))/1000,"-") -> - | O19: =IFERROR(INDEX(Raw_Data,MATCH($A19,Look_Up,0),MATCH(O$4,Component,0))/1000,"-") -> - | P19: =IFERROR(INDEX(Raw_Data,MATCH($A19,Look_Up,0),MATCH(P$4,Component,0))/1000,"-") -> - | Q19: =IFERROR(INDEX(Raw_Data,MATCH($A19,Look_Up,0),MATCH(Q$4,Component,0)),"-") -> - | R19: =IFERROR(INDEX(Raw_Data,MATCH($A19,Look_Up,0),MATCH(R$4,Component,0)),"-") -> - | S19: =IFERROR(INDEX(Raw_Data,MATCH($A19,Look_Up,0),MATCH(S$4,Component,0))/1000,"-") -> - | T19: =IFERROR(INDEX(Raw_Data,MATCH($A19,Look_Up,0),MATCH(T$4,Component,0)),"-") -> - | U19: =IFERROR(INDEX(Raw_Data,MATCH($A19,Look_Up,0),MATCH(U$4,Component,0))/1000,"-") -> - | V19: =IFERROR(INDEX(Raw_Data,MATCH($A19,Look_Up,0),MATCH(V$4,Component,0))/1000,"-") -> - | X19: =IFERROR(N19/U19,"-") -> - | Y19: =IFERROR(P19/U19,"-") -> -
... A27: =$B27&"_"&$C$3&"_"&$C$2 -> TSX:A_2018_ | B27: TSX:A | C27: =IFERROR(INDEX(Raw_Data,MATCH($A27,Look_Up,0),MATCH(C$4,Component,0)),"-") -> - | D27: =_xll.ciqfunctions.udf.CIQ(B27, "IQ_MARKETCAP", $A$1,$A$2) -> #PEND | E27: =_xll.ciqfunctions.udf.CIQ($B27, "IQ_TEV", $A$1,$A$2) -> #PEND | F27: =IFERROR(INDEX(Raw_Data,MATCH($A27,Look_Up,0),MATCH(F$4,Component,0)),"-") -> - | G27: =IFERROR(INDEX(Raw_Data,MATCH($A27,Look_Up,0),MATCH(G$4,Component,0)),"-") -> - | H27: =IFERROR(INDEX(Raw_Data,MATCH($A27,Look_Up,0),MATCH(H$4,Component,0))/1000,"-") -> - | I27: =IFERROR(INDEX(Raw_Data,MATCH($A27,Look_Up,0),MATCH(I$4,Component,0))/1000,"-") -> - | J27: =IFERROR(INDEX(Raw_Data,MATCH($A27,Look_Up,0),MATCH(J$4,Component,0)),"-") -> - | K27: =IFERROR(INDEX(Raw_Data,MATCH($A27,Look_Up,0),MATCH(K$4,Component,0)),"-") -> - | L27: =IFERROR(INDEX(Raw_Data,MATCH($A27,Look_Up,0),MATCH(L$4,Component,0))/1000,"-") -> - | M27: =IFERROR(INDEX(Raw_Data,MATCH($A27,Look_Up,0),MATCH(M$4,Component,0)),"-") -> - | N27: =IFERROR(INDEX(Raw_Data,MATCH($A27,Look_Up,0),MATCH(N$4,Component,0))/1000,"-") -> - | O27: =IFERROR(INDEX(Raw_Data,MATCH($A27,Look_Up,0),MATCH(O$4,Component,0))/1000,"-") -> - | P27: =IFERROR(INDEX(Raw_Data,MATCH($A27,Look_Up,0),MATCH(P$4,Component,0))/1000,"-") -> - | Q27: =IFERROR(INDEX(Raw_Data,MATCH($A27,Look_Up,0),MATCH(Q$4,Component,0)),"-") -> - | R27: =IFERROR(INDEX(Raw_Data,MATCH($A27,Look_Up,0),MATCH(R$4,Component,0)),"-") -> - | S27: =IFERROR(INDEX(Raw_Data,MATCH($A27,Look_Up,0),MATCH(S$4,Component,0))/1000,"-") -> - | T27: =IFERROR(INDEX(Raw_Data,MATCH($A27,Look_Up,0),MATCH(T$4,Component,0)),"-") -> - | U27: =IFERROR(INDEX(Raw_Data,MATCH($A27,Look_Up,0),MATCH(U$4,Component,0))/1000,"-") -> - | V27: =IFERROR(INDEX(Raw_Data,MATCH($A27,Look_Up,0),MATCH(V$4,Component,0))/1000,"-") -> - | X27: =IFERROR(N27/U27,"-") -> - | Y27: =IFERROR(P27/U27,"-") -> -
C28: Summary Statistics
